[2025-01-24T20:30:49.797+0000] {local_task_job_runner.py:123} INFO - ::group::Pre task execution logs
[2025-01-24T20:30:49.805+0000] {taskinstance.py:2613} INFO - Dependencies all met for dep_context=non-requeueable deps ti=<TaskInstance: coleta_dados_abertos_cnpj.extract manual__2025-01-24T20:30:48.934842+00:00 [queued]>
[2025-01-24T20:30:49.810+0000] {taskinstance.py:2613} INFO - Dependencies all met for dep_context=requeueable deps ti=<TaskInstance: coleta_dados_abertos_cnpj.extract manual__2025-01-24T20:30:48.934842+00:00 [queued]>
[2025-01-24T20:30:49.810+0000] {taskinstance.py:2866} INFO - Starting attempt 1 of 2
[2025-01-24T20:30:49.850+0000] {taskinstance.py:2889} INFO - Executing <Task(PythonOperator): extract> on 2025-01-24 20:30:48.934842+00:00
[2025-01-24T20:30:49.853+0000] {warnings.py:112} WARNING - /home/***/.local/lib/python3.12/site-packages/***/task/task_runner/standard_task_runner.py:70: DeprecationWarning: This process (pid=217) is multi-threaded, use of fork() may lead to deadlocks in the child.
  pid = os.fork()

[2025-01-24T20:30:49.854+0000] {standard_task_runner.py:72} INFO - Started process 218 to run task
[2025-01-24T20:30:49.854+0000] {standard_task_runner.py:104} INFO - Running: ['***', 'tasks', 'run', 'coleta_dados_abertos_cnpj', 'extract', 'manual__2025-01-24T20:30:48.934842+00:00', '--job-id', '761', '--raw', '--subdir', 'DAGS_FOLDER/coleta_dados_abertos_cnpj/dag.py', '--cfg-path', '/tmp/tmpe73er5np']
[2025-01-24T20:30:49.855+0000] {standard_task_runner.py:105} INFO - Job 761: Subtask extract
[2025-01-24T20:30:49.877+0000] {task_command.py:467} INFO - Running <TaskInstance: coleta_dados_abertos_cnpj.extract manual__2025-01-24T20:30:48.934842+00:00 [running]> on host ee70781c29c7
[2025-01-24T20:30:49.932+0000] {taskinstance.py:3132} INFO - Exporting env vars: AIRFLOW_CTX_DAG_OWNER='Corvaum' AIRFLOW_CTX_DAG_ID='coleta_dados_abertos_cnpj' AIRFLOW_CTX_TASK_ID='extract' AIRFLOW_CTX_EXECUTION_DATE='2025-01-24T20:30:48.934842+00:00' AIRFLOW_CTX_TRY_NUMBER='1' AIRFLOW_CTX_DAG_RUN_ID='manual__2025-01-24T20:30:48.934842+00:00'
[2025-01-24T20:30:49.934+0000] {taskinstance.py:731} INFO - ::endgroup::
[2025-01-24T20:30:49.948+0000] {logging_mixin.py:190} INFO - Data formatada: 2025-01
[2025-01-24T20:30:50.091+0000] {logging_mixin.py:190} INFO - Erro ao listar os arquivos: HTTPSConnectionPool(host='arquivos.receitafederal.gov.br', port=443): Max retries exceeded with url: /dados/cnpj/dados_abertos_cnpj/2025-01 (Caused by SSLError(SSLEOFError(8, '[SSL: UNEXPECTED_EOF_WHILE_READING] EOF occurred in violation of protocol (_ssl.c:1000)')))
[2025-01-24T20:30:50.091+0000] {logging_mixin.py:190} INFO - Arquivos encontrados: []
[2025-01-24T20:30:50.091+0000] {python.py:240} INFO - Done. Returned value was: None
[2025-01-24T20:30:50.096+0000] {taskinstance.py:340} INFO - ::group::Post task execution logs
[2025-01-24T20:30:50.096+0000] {taskinstance.py:352} INFO - Marking task as SUCCESS. dag_id=coleta_dados_abertos_cnpj, task_id=extract, run_id=manual__2025-01-24T20:30:48.934842+00:00, execution_date=20250124T203048, start_date=20250124T203049, end_date=20250124T203050
[2025-01-24T20:30:50.148+0000] {local_task_job_runner.py:266} INFO - Task exited with return code 0
[2025-01-24T20:30:50.162+0000] {taskinstance.py:3895} INFO - 10 downstream tasks scheduled from follow-on schedule check
[2025-01-24T20:30:50.167+0000] {local_task_job_runner.py:245} INFO - ::endgroup::
