[2025-01-24T19:04:38.964+0000] {local_task_job_runner.py:123} INFO - ::group::Pre task execution logs
[2025-01-24T19:04:38.971+0000] {taskinstance.py:2613} INFO - Dependencies all met for dep_context=non-requeueable deps ti=<TaskInstance: coleta_dados_abertos_cnpj.extract manual__2025-01-24T19:04:37.945220+00:00 [queued]>
[2025-01-24T19:04:38.975+0000] {taskinstance.py:2613} INFO - Dependencies all met for dep_context=requeueable deps ti=<TaskInstance: coleta_dados_abertos_cnpj.extract manual__2025-01-24T19:04:37.945220+00:00 [queued]>
[2025-01-24T19:04:38.975+0000] {taskinstance.py:2866} INFO - Starting attempt 1 of 2
[2025-01-24T19:04:39.002+0000] {taskinstance.py:2889} INFO - Executing <Task(PythonOperator): extract> on 2025-01-24 19:04:37.945220+00:00
[2025-01-24T19:04:39.023+0000] {warnings.py:112} WARNING - /home/***/.local/lib/python3.12/site-packages/***/task/task_runner/standard_task_runner.py:70: DeprecationWarning: This process (pid=1694) is multi-threaded, use of fork() may lead to deadlocks in the child.
  pid = os.fork()

[2025-01-24T19:04:39.025+0000] {standard_task_runner.py:72} INFO - Started process 1695 to run task
[2025-01-24T19:04:39.025+0000] {standard_task_runner.py:104} INFO - Running: ['***', 'tasks', 'run', 'coleta_dados_abertos_cnpj', 'extract', 'manual__2025-01-24T19:04:37.945220+00:00', '--job-id', '694', '--raw', '--subdir', 'DAGS_FOLDER/coleta_dados_abertos_cnpj/dag.py', '--cfg-path', '/tmp/tmpa00ae6by']
[2025-01-24T19:04:39.026+0000] {standard_task_runner.py:105} INFO - Job 694: Subtask extract
[2025-01-24T19:04:39.047+0000] {task_command.py:467} INFO - Running <TaskInstance: coleta_dados_abertos_cnpj.extract manual__2025-01-24T19:04:37.945220+00:00 [running]> on host ee70781c29c7
[2025-01-24T19:04:39.094+0000] {taskinstance.py:3132} INFO - Exporting env vars: AIRFLOW_CTX_DAG_OWNER='Corvaum' AIRFLOW_CTX_DAG_ID='coleta_dados_abertos_cnpj' AIRFLOW_CTX_TASK_ID='extract' AIRFLOW_CTX_EXECUTION_DATE='2025-01-24T19:04:37.945220+00:00' AIRFLOW_CTX_TRY_NUMBER='1' AIRFLOW_CTX_DAG_RUN_ID='manual__2025-01-24T19:04:37.945220+00:00'
[2025-01-24T19:04:39.095+0000] {taskinstance.py:731} INFO - ::endgroup::
[2025-01-24T19:04:39.113+0000] {logging_mixin.py:190} INFO - Data formatada: 2025-01
[2025-01-24T19:04:49.225+0000] {logging_mixin.py:190} INFO - Erro ao listar os arquivos: HTTPSConnectionPool(host='arquivos.receitafederal.gov.br', port=443): Max retries exceeded with url: /dados/cnpj/dados_abertos_cnpj/2025-01 (Caused by ConnectTimeoutError(<urllib3.connection.HTTPSConnection object at 0x7f565c379e20>, 'Connection to arquivos.receitafederal.gov.br timed out. (connect timeout=10)'))
[2025-01-24T19:04:49.226+0000] {logging_mixin.py:190} INFO - Arquivos encontrados: []
[2025-01-24T19:04:49.226+0000] {python.py:240} INFO - Done. Returned value was: None
[2025-01-24T19:04:49.231+0000] {taskinstance.py:340} INFO - ::group::Post task execution logs
[2025-01-24T19:04:49.232+0000] {taskinstance.py:352} INFO - Marking task as SUCCESS. dag_id=coleta_dados_abertos_cnpj, task_id=extract, run_id=manual__2025-01-24T19:04:37.945220+00:00, execution_date=20250124T190437, start_date=20250124T190438, end_date=20250124T190449
[2025-01-24T19:04:49.265+0000] {local_task_job_runner.py:266} INFO - Task exited with return code 0
[2025-01-24T19:04:49.279+0000] {taskinstance.py:3895} INFO - 10 downstream tasks scheduled from follow-on schedule check
[2025-01-24T19:04:49.281+0000] {local_task_job_runner.py:245} INFO - ::endgroup::
