[2025-01-23T01:26:11.455+0000] {local_task_job_runner.py:123} INFO - ::group::Pre task execution logs
[2025-01-23T01:26:11.464+0000] {taskinstance.py:2613} INFO - Dependencies all met for dep_context=non-requeueable deps ti=<TaskInstance: coleta_dados_abertos_cnpj.extract scheduled__2024-09-10T00:00:00+00:00 [queued]>
[2025-01-23T01:26:11.469+0000] {taskinstance.py:2613} INFO - Dependencies all met for dep_context=requeueable deps ti=<TaskInstance: coleta_dados_abertos_cnpj.extract scheduled__2024-09-10T00:00:00+00:00 [queued]>
[2025-01-23T01:26:11.470+0000] {taskinstance.py:2866} INFO - Starting attempt 2 of 2
[2025-01-23T01:26:11.555+0000] {taskinstance.py:2889} INFO - Executing <Task(PythonOperator): extract> on 2024-09-10 00:00:00+00:00
[2025-01-23T01:26:11.558+0000] {warnings.py:112} WARNING - /home/***/.local/lib/python3.12/site-packages/***/task/task_runner/standard_task_runner.py:70: DeprecationWarning: This process (pid=210) is multi-threaded, use of fork() may lead to deadlocks in the child.
  pid = os.fork()

[2025-01-23T01:26:11.559+0000] {standard_task_runner.py:72} INFO - Started process 215 to run task
[2025-01-23T01:26:11.559+0000] {standard_task_runner.py:104} INFO - Running: ['***', 'tasks', 'run', 'coleta_dados_abertos_cnpj', 'extract', 'scheduled__2024-09-10T00:00:00+00:00', '--job-id', '217', '--raw', '--subdir', 'DAGS_FOLDER/coleta_dados_abertos_cnpj/dag.py', '--cfg-path', '/tmp/tmpgy9ssi7p']
[2025-01-23T01:26:11.561+0000] {standard_task_runner.py:105} INFO - Job 217: Subtask extract
[2025-01-23T01:26:11.587+0000] {task_command.py:467} INFO - Running <TaskInstance: coleta_dados_abertos_cnpj.extract scheduled__2024-09-10T00:00:00+00:00 [running]> on host 659dab735c6e
[2025-01-23T01:26:11.629+0000] {taskinstance.py:3132} INFO - Exporting env vars: AIRFLOW_CTX_DAG_OWNER='Corvaum' AIRFLOW_CTX_DAG_ID='coleta_dados_abertos_cnpj' AIRFLOW_CTX_TASK_ID='extract' AIRFLOW_CTX_EXECUTION_DATE='2024-09-10T00:00:00+00:00' AIRFLOW_CTX_TRY_NUMBER='2' AIRFLOW_CTX_DAG_RUN_ID='scheduled__2024-09-10T00:00:00+00:00'
[2025-01-23T01:26:11.629+0000] {taskinstance.py:731} INFO - ::endgroup::
[2025-01-23T01:26:11.640+0000] {logging_mixin.py:190} INFO - 2024-09
[2025-01-23T01:26:11.856+0000] {logging_mixin.py:190} INFO - -----------------
[2025-01-23T01:26:11.857+0000] {logging_mixin.py:190} INFO - ['Cnaes.zip', 'Empresas0.zip', 'Empresas1.zip', 'Empresas2.zip', 'Empresas3.zip', 'Empresas4.zip', 'Empresas5.zip', 'Empresas6.zip', 'Empresas7.zip', 'Empresas8.zip', 'Empresas9.zip', 'Estabelecimentos0.zip', 'Estabelecimentos1.zip', 'Estabelecimentos2.zip', 'Estabelecimentos3.zip', 'Estabelecimentos4.zip', 'Estabelecimentos5.zip', 'Estabelecimentos6.zip', 'Estabelecimentos7.zip', 'Estabelecimentos8.zip', 'Estabelecimentos9.zip', 'Motivos.zip', 'Municipios.zip', 'Naturezas.zip', 'Paises.zip', 'Qualificacoes.zip', 'Simples.zip', 'Socios0.zip', 'Socios1.zip', 'Socios2.zip', 'Socios3.zip', 'Socios4.zip', 'Socios5.zip', 'Socios6.zip', 'Socios7.zip', 'Socios8.zip', 'Socios9.zip']
[2025-01-23T01:26:11.857+0000] {logging_mixin.py:190} INFO - ['Cnaes', 'Empresas', 'Estabelecimentos', 'Motivos', 'Municipios', 'Naturezas', 'Paises', 'Qualificacoes', 'Simples', 'Socios']
[2025-01-23T01:26:11.857+0000] {logging_mixin.py:190} INFO - Iniciando o download de: https://arquivos.receitafederal.gov.br/dados/cnpj/dados_abertos_cnpj/2024-09/Cnaes.zip
[2025-01-23T01:26:11.999+0000] {logging_mixin.py:190} INFO - Arquivo salvo em: G:/Airflow/volumes/dados_abertos_cnpj/2024-09/Cnaes/Cnaes.zip
[2025-01-23T01:26:12.000+0000] {logging_mixin.py:190} INFO - Iniciando o download de: https://arquivos.receitafederal.gov.br/dados/cnpj/dados_abertos_cnpj/2024-09/Empresas0.zip
[2025-01-23T01:29:04.493+0000] {taskinstance.py:3311} ERROR - Task failed with exception
Traceback (most recent call last):
  File "/home/airflow/.local/lib/python3.12/site-packages/urllib3/response.py", line 748, in _error_catcher
    yield
  File "/home/airflow/.local/lib/python3.12/site-packages/urllib3/response.py", line 894, in _raw_read
    raise IncompleteRead(self._fp_bytes_read, self.length_remaining)
urllib3.exceptions.IncompleteRead: IncompleteRead(25632673 bytes read, 345171581 more expected)

The above exception was the direct cause of the following exception:

Traceback (most recent call last):
  File "/home/airflow/.local/lib/python3.12/site-packages/requests/models.py", line 820, in generate
    yield from self.raw.stream(chunk_size, decode_content=True)
  File "/home/airflow/.local/lib/python3.12/site-packages/urllib3/response.py", line 1060, in stream
    data = self.read(amt=amt, decode_content=decode_content)
           ^^^^^^^^^^^^^^^^^^^^^^^^^^^^^^^^^^^^^^^^^^^^^^^^^
  File "/home/airflow/.local/lib/python3.12/site-packages/urllib3/response.py", line 977, in read
    data = self._raw_read(amt)
           ^^^^^^^^^^^^^^^^^^^
  File "/home/airflow/.local/lib/python3.12/site-packages/urllib3/response.py", line 872, in _raw_read
    with self._error_catcher():
         ^^^^^^^^^^^^^^^^^^^^^
  File "/usr/local/lib/python3.12/contextlib.py", line 158, in __exit__
    self.gen.throw(value)
  File "/home/airflow/.local/lib/python3.12/site-packages/urllib3/response.py", line 772, in _error_catcher
    raise ProtocolError(arg, e) from e
urllib3.exceptions.ProtocolError: ('Connection broken: IncompleteRead(25632673 bytes read, 345171581 more expected)', IncompleteRead(25632673 bytes read, 345171581 more expected))

During handling of the above exception, another exception occurred:

Traceback (most recent call last):
  File "/home/airflow/.local/lib/python3.12/site-packages/airflow/models/taskinstance.py", line 767, in _execute_task
    result = _execute_callable(context=context, **execute_callable_kwargs)
             ^^^^^^^^^^^^^^^^^^^^^^^^^^^^^^^^^^^^^^^^^^^^^^^^^^^^^^^^^^^^^
  File "/home/airflow/.local/lib/python3.12/site-packages/airflow/models/taskinstance.py", line 733, in _execute_callable
    return ExecutionCallableRunner(
           ^^^^^^^^^^^^^^^^^^^^^^^^
  File "/home/airflow/.local/lib/python3.12/site-packages/airflow/utils/operator_helpers.py", line 252, in run
    return self.func(*args, **kwargs)
           ^^^^^^^^^^^^^^^^^^^^^^^^^^
  File "/home/airflow/.local/lib/python3.12/site-packages/airflow/models/baseoperator.py", line 422, in wrapper
    return func(self, *args, **kwargs)
           ^^^^^^^^^^^^^^^^^^^^^^^^^^^
  File "/home/airflow/.local/lib/python3.12/site-packages/airflow/operators/python.py", line 238, in execute
    return_value = self.execute_callable()
                   ^^^^^^^^^^^^^^^^^^^^^^^
  File "/home/airflow/.local/lib/python3.12/site-packages/airflow/operators/python.py", line 256, in execute_callable
    return runner.run(*self.op_args, **self.op_kwargs)
           ^^^^^^^^^^^^^^^^^^^^^^^^^^^^^^^^^^^^^^^^^^^
  File "/home/airflow/.local/lib/python3.12/site-packages/airflow/utils/operator_helpers.py", line 252, in run
    return self.func(*args, **kwargs)
           ^^^^^^^^^^^^^^^^^^^^^^^^^^
  File "/opt/airflow/dags/coleta_dados_abertos_cnpj/jobs/extract.py", line 105, in extract
    file_path = download_with_requests(
                ^^^^^^^^^^^^^^^^^^^^^^^
  File "/opt/airflow/dags/coleta_dados_abertos_cnpj/jobs/extract.py", line 68, in download_with_requests
    for chunk in r.iter_content(chunk_size=8192):
                 ^^^^^^^^^^^^^^^^^^^^^^^^^^^^^^^
  File "/home/airflow/.local/lib/python3.12/site-packages/requests/models.py", line 822, in generate
    raise ChunkedEncodingError(e)
requests.exceptions.ChunkedEncodingError: ('Connection broken: IncompleteRead(25632673 bytes read, 345171581 more expected)', IncompleteRead(25632673 bytes read, 345171581 more expected))
[2025-01-23T01:29:04.510+0000] {taskinstance.py:1225} INFO - Marking task as FAILED. dag_id=coleta_dados_abertos_cnpj, task_id=extract, run_id=scheduled__2024-09-10T00:00:00+00:00, execution_date=20240910T000000, start_date=20250123T012611, end_date=20250123T012904
[2025-01-23T01:29:04.522+0000] {taskinstance.py:340} INFO - ::group::Post task execution logs
[2025-01-23T01:29:04.524+0000] {standard_task_runner.py:124} ERROR - Failed to execute job 217 for task extract (('Connection broken: IncompleteRead(25632673 bytes read, 345171581 more expected)', IncompleteRead(25632673 bytes read, 345171581 more expected)); 215)
Traceback (most recent call last):
  File "/home/airflow/.local/lib/python3.12/site-packages/urllib3/response.py", line 748, in _error_catcher
    yield
  File "/home/airflow/.local/lib/python3.12/site-packages/urllib3/response.py", line 894, in _raw_read
    raise IncompleteRead(self._fp_bytes_read, self.length_remaining)
urllib3.exceptions.IncompleteRead: IncompleteRead(25632673 bytes read, 345171581 more expected)

The above exception was the direct cause of the following exception:

Traceback (most recent call last):
  File "/home/airflow/.local/lib/python3.12/site-packages/requests/models.py", line 820, in generate
    yield from self.raw.stream(chunk_size, decode_content=True)
  File "/home/airflow/.local/lib/python3.12/site-packages/urllib3/response.py", line 1060, in stream
    data = self.read(amt=amt, decode_content=decode_content)
           ^^^^^^^^^^^^^^^^^^^^^^^^^^^^^^^^^^^^^^^^^^^^^^^^^
  File "/home/airflow/.local/lib/python3.12/site-packages/urllib3/response.py", line 977, in read
    data = self._raw_read(amt)
           ^^^^^^^^^^^^^^^^^^^
  File "/home/airflow/.local/lib/python3.12/site-packages/urllib3/response.py", line 872, in _raw_read
    with self._error_catcher():
         ^^^^^^^^^^^^^^^^^^^^^
  File "/usr/local/lib/python3.12/contextlib.py", line 158, in __exit__
    self.gen.throw(value)
  File "/home/airflow/.local/lib/python3.12/site-packages/urllib3/response.py", line 772, in _error_catcher
    raise ProtocolError(arg, e) from e
urllib3.exceptions.ProtocolError: ('Connection broken: IncompleteRead(25632673 bytes read, 345171581 more expected)', IncompleteRead(25632673 bytes read, 345171581 more expected))

During handling of the above exception, another exception occurred:

Traceback (most recent call last):
  File "/home/airflow/.local/lib/python3.12/site-packages/airflow/task/task_runner/standard_task_runner.py", line 117, in _start_by_fork
    ret = args.func(args, dag=self.dag)
          ^^^^^^^^^^^^^^^^^^^^^^^^^^^^^
  File "/home/airflow/.local/lib/python3.12/site-packages/airflow/cli/cli_config.py", line 49, in command
    return func(*args, **kwargs)
           ^^^^^^^^^^^^^^^^^^^^^
  File "/home/airflow/.local/lib/python3.12/site-packages/airflow/utils/cli.py", line 116, in wrapper
    return f(*args, **kwargs)
           ^^^^^^^^^^^^^^^^^^
  File "/home/airflow/.local/lib/python3.12/site-packages/airflow/cli/commands/task_command.py", line 483, in task_run
    task_return_code = _run_task_by_selected_method(args, _dag, ti)
                       ^^^^^^^^^^^^^^^^^^^^^^^^^^^^^^^^^^^^^^^^^^^^
  File "/home/airflow/.local/lib/python3.12/site-packages/airflow/cli/commands/task_command.py", line 256, in _run_task_by_selected_method
    return _run_raw_task(args, ti)
           ^^^^^^^^^^^^^^^^^^^^^^^
  File "/home/airflow/.local/lib/python3.12/site-packages/airflow/cli/commands/task_command.py", line 341, in _run_raw_task
    return ti._run_raw_task(
           ^^^^^^^^^^^^^^^^^
  File "/home/airflow/.local/lib/python3.12/site-packages/airflow/utils/session.py", line 97, in wrapper
    return func(*args, session=session, **kwargs)
           ^^^^^^^^^^^^^^^^^^^^^^^^^^^^^^^^^^^^^^
  File "/home/airflow/.local/lib/python3.12/site-packages/airflow/models/taskinstance.py", line 3005, in _run_raw_task
    return _run_raw_task(
           ^^^^^^^^^^^^^^
  File "/home/airflow/.local/lib/python3.12/site-packages/airflow/models/taskinstance.py", line 273, in _run_raw_task
    TaskInstance._execute_task_with_callbacks(
  File "/home/airflow/.local/lib/python3.12/site-packages/airflow/models/taskinstance.py", line 3159, in _execute_task_with_callbacks
    result = self._execute_task(context, task_orig)
             ^^^^^^^^^^^^^^^^^^^^^^^^^^^^^^^^^^^^^^
  File "/home/airflow/.local/lib/python3.12/site-packages/airflow/models/taskinstance.py", line 3183, in _execute_task
    return _execute_task(self, context, task_orig)
           ^^^^^^^^^^^^^^^^^^^^^^^^^^^^^^^^^^^^^^^
  File "/home/airflow/.local/lib/python3.12/site-packages/airflow/models/taskinstance.py", line 767, in _execute_task
    result = _execute_callable(context=context, **execute_callable_kwargs)
             ^^^^^^^^^^^^^^^^^^^^^^^^^^^^^^^^^^^^^^^^^^^^^^^^^^^^^^^^^^^^^
  File "/home/airflow/.local/lib/python3.12/site-packages/airflow/models/taskinstance.py", line 733, in _execute_callable
    return ExecutionCallableRunner(
           ^^^^^^^^^^^^^^^^^^^^^^^^
  File "/home/airflow/.local/lib/python3.12/site-packages/airflow/utils/operator_helpers.py", line 252, in run
    return self.func(*args, **kwargs)
           ^^^^^^^^^^^^^^^^^^^^^^^^^^
  File "/home/airflow/.local/lib/python3.12/site-packages/airflow/models/baseoperator.py", line 422, in wrapper
    return func(self, *args, **kwargs)
           ^^^^^^^^^^^^^^^^^^^^^^^^^^^
  File "/home/airflow/.local/lib/python3.12/site-packages/airflow/operators/python.py", line 238, in execute
    return_value = self.execute_callable()
                   ^^^^^^^^^^^^^^^^^^^^^^^
  File "/home/airflow/.local/lib/python3.12/site-packages/airflow/operators/python.py", line 256, in execute_callable
    return runner.run(*self.op_args, **self.op_kwargs)
           ^^^^^^^^^^^^^^^^^^^^^^^^^^^^^^^^^^^^^^^^^^^
  File "/home/airflow/.local/lib/python3.12/site-packages/airflow/utils/operator_helpers.py", line 252, in run
    return self.func(*args, **kwargs)
           ^^^^^^^^^^^^^^^^^^^^^^^^^^
  File "/opt/airflow/dags/coleta_dados_abertos_cnpj/jobs/extract.py", line 105, in extract
    file_path = download_with_requests(
                ^^^^^^^^^^^^^^^^^^^^^^^
  File "/opt/airflow/dags/coleta_dados_abertos_cnpj/jobs/extract.py", line 68, in download_with_requests
    for chunk in r.iter_content(chunk_size=8192):
                 ^^^^^^^^^^^^^^^^^^^^^^^^^^^^^^^
  File "/home/airflow/.local/lib/python3.12/site-packages/requests/models.py", line 822, in generate
    raise ChunkedEncodingError(e)
requests.exceptions.ChunkedEncodingError: ('Connection broken: IncompleteRead(25632673 bytes read, 345171581 more expected)', IncompleteRead(25632673 bytes read, 345171581 more expected))
[2025-01-23T01:29:04.565+0000] {local_task_job_runner.py:266} INFO - Task exited with return code 1
[2025-01-23T01:29:04.584+0000] {taskinstance.py:3895} INFO - 0 downstream tasks scheduled from follow-on schedule check
[2025-01-23T01:29:04.588+0000] {local_task_job_runner.py:245} INFO - ::endgroup::
[2025-01-24T19:02:08.019+0000] {local_task_job_runner.py:123} INFO - ::group::Pre task execution logs
[2025-01-24T19:02:08.027+0000] {taskinstance.py:2613} INFO - Dependencies all met for dep_context=non-requeueable deps ti=<TaskInstance: coleta_dados_abertos_cnpj.extract scheduled__2024-09-10T00:00:00+00:00 [queued]>
[2025-01-24T19:02:08.031+0000] {taskinstance.py:2613} INFO - Dependencies all met for dep_context=requeueable deps ti=<TaskInstance: coleta_dados_abertos_cnpj.extract scheduled__2024-09-10T00:00:00+00:00 [queued]>
[2025-01-24T19:02:08.031+0000] {taskinstance.py:2866} INFO - Starting attempt 2 of 2
[2025-01-24T19:02:08.040+0000] {taskinstance.py:2889} INFO - Executing <Task(PythonOperator): extract> on 2024-09-10 00:00:00+00:00
[2025-01-24T19:02:08.043+0000] {warnings.py:112} WARNING - /home/***/.local/lib/python3.12/site-packages/***/task/task_runner/standard_task_runner.py:70: DeprecationWarning: This process (pid=1404) is multi-threaded, use of fork() may lead to deadlocks in the child.
  pid = os.fork()

[2025-01-24T19:02:08.044+0000] {standard_task_runner.py:72} INFO - Started process 1409 to run task
[2025-01-24T19:02:08.044+0000] {standard_task_runner.py:104} INFO - Running: ['***', 'tasks', 'run', 'coleta_dados_abertos_cnpj', 'extract', 'scheduled__2024-09-10T00:00:00+00:00', '--job-id', '610', '--raw', '--subdir', 'DAGS_FOLDER/coleta_dados_abertos_cnpj/dag.py', '--cfg-path', '/tmp/tmp3so6tf9s']
[2025-01-24T19:02:08.046+0000] {standard_task_runner.py:105} INFO - Job 610: Subtask extract
[2025-01-24T19:02:08.069+0000] {task_command.py:467} INFO - Running <TaskInstance: coleta_dados_abertos_cnpj.extract scheduled__2024-09-10T00:00:00+00:00 [running]> on host ee70781c29c7
[2025-01-24T19:02:08.114+0000] {taskinstance.py:3132} INFO - Exporting env vars: AIRFLOW_CTX_DAG_OWNER='Corvaum' AIRFLOW_CTX_DAG_ID='coleta_dados_abertos_cnpj' AIRFLOW_CTX_TASK_ID='extract' AIRFLOW_CTX_EXECUTION_DATE='2024-09-10T00:00:00+00:00' AIRFLOW_CTX_TRY_NUMBER='2' AIRFLOW_CTX_DAG_RUN_ID='scheduled__2024-09-10T00:00:00+00:00'
[2025-01-24T19:02:08.115+0000] {taskinstance.py:731} INFO - ::endgroup::
[2025-01-24T19:02:08.126+0000] {logging_mixin.py:190} INFO - Data formatada: 2024-09
[2025-01-24T19:02:08.384+0000] {logging_mixin.py:190} INFO - Arquivos encontrados: ['Cnaes.zip', 'Empresas0.zip', 'Empresas1.zip', 'Empresas2.zip', 'Empresas3.zip', 'Empresas4.zip', 'Empresas5.zip', 'Empresas6.zip', 'Empresas7.zip', 'Empresas8.zip', 'Empresas9.zip', 'Estabelecimentos0.zip', 'Estabelecimentos1.zip', 'Estabelecimentos2.zip', 'Estabelecimentos3.zip', 'Estabelecimentos4.zip', 'Estabelecimentos5.zip', 'Estabelecimentos6.zip', 'Estabelecimentos7.zip', 'Estabelecimentos8.zip', 'Estabelecimentos9.zip', 'Motivos.zip', 'Municipios.zip', 'Naturezas.zip', 'Paises.zip', 'Qualificacoes.zip', 'Simples.zip', 'Socios0.zip', 'Socios1.zip', 'Socios2.zip', 'Socios3.zip', 'Socios4.zip', 'Socios5.zip', 'Socios6.zip', 'Socios7.zip', 'Socios8.zip', 'Socios9.zip']
[2025-01-24T19:02:08.384+0000] {logging_mixin.py:190} INFO - Baixando o arquivo: https://arquivos.receitafederal.gov.br/dados/cnpj/dados_abertos_cnpj/2024-09/Cnaes.zip
[2025-01-24T19:02:08.536+0000] {logging_mixin.py:190} INFO - Download concluído: https://arquivos.receitafederal.gov.br/dados/cnpj/dados_abertos_cnpj/2024-09/Cnaes.zip
[2025-01-24T19:02:08.539+0000] {logging_mixin.py:190} INFO - Arquivos descompactados: ['/tmp/5612addd86a942bbb8a73cf41ce91eed_extracted/F.K03200$Z.D40914.CNAECSV']
[2025-01-24T19:02:08.552+0000] {logging_mixin.py:190} INFO - Arquivo full_cpf/Cnaes/2024-09/Cnaes_049e19052f04431db422128d22a83748.csv carregado com sucesso no MinIO!
[2025-01-24T19:02:08.553+0000] {logging_mixin.py:190} INFO - Baixando o arquivo: https://arquivos.receitafederal.gov.br/dados/cnpj/dados_abertos_cnpj/2024-09/Empresas0.zip
[2025-01-24T19:03:43.666+0000] {local_task_job_runner.py:346} WARNING - State of this instance has been externally set to None. Terminating instance.
[2025-01-24T19:03:43.667+0000] {local_task_job_runner.py:245} INFO - ::endgroup::
[2025-01-24T19:03:43.668+0000] {process_utils.py:132} INFO - Sending 15 to group 1409. PIDs of all processes in the group: [1409]
[2025-01-24T19:03:43.668+0000] {process_utils.py:87} INFO - Sending the signal 15 to group 1409
[2025-01-24T19:03:43.668+0000] {taskinstance.py:3093} ERROR - Received SIGTERM. Terminating subprocesses.
[2025-01-24T19:03:43.674+0000] {taskinstance.py:3311} ERROR - Task failed with exception
Traceback (most recent call last):
  File "/home/airflow/.local/lib/python3.12/site-packages/airflow/models/taskinstance.py", line 767, in _execute_task
    result = _execute_callable(context=context, **execute_callable_kwargs)
             ^^^^^^^^^^^^^^^^^^^^^^^^^^^^^^^^^^^^^^^^^^^^^^^^^^^^^^^^^^^^^
  File "/home/airflow/.local/lib/python3.12/site-packages/airflow/models/taskinstance.py", line 733, in _execute_callable
    return ExecutionCallableRunner(
           ^^^^^^^^^^^^^^^^^^^^^^^^
  File "/home/airflow/.local/lib/python3.12/site-packages/airflow/utils/operator_helpers.py", line 252, in run
    return self.func(*args, **kwargs)
           ^^^^^^^^^^^^^^^^^^^^^^^^^^
  File "/home/airflow/.local/lib/python3.12/site-packages/airflow/models/baseoperator.py", line 422, in wrapper
    return func(self, *args, **kwargs)
           ^^^^^^^^^^^^^^^^^^^^^^^^^^^
  File "/home/airflow/.local/lib/python3.12/site-packages/airflow/operators/python.py", line 238, in execute
    return_value = self.execute_callable()
                   ^^^^^^^^^^^^^^^^^^^^^^^
  File "/home/airflow/.local/lib/python3.12/site-packages/airflow/operators/python.py", line 256, in execute_callable
    return runner.run(*self.op_args, **self.op_kwargs)
           ^^^^^^^^^^^^^^^^^^^^^^^^^^^^^^^^^^^^^^^^^^^
  File "/home/airflow/.local/lib/python3.12/site-packages/airflow/utils/operator_helpers.py", line 252, in run
    return self.func(*args, **kwargs)
           ^^^^^^^^^^^^^^^^^^^^^^^^^^
  File "/opt/airflow/dags/coleta_dados_abertos_cnpj/jobs/extract.py", line 123, in extract
    zip_file = download_with_requests(download_file_url)
               ^^^^^^^^^^^^^^^^^^^^^^^^^^^^^^^^^^^^^^^^^
  File "/opt/airflow/dags/coleta_dados_abertos_cnpj/jobs/extract.py", line 53, in download_with_requests
    for chunk in r.iter_content(chunk_size=8192):
                 ^^^^^^^^^^^^^^^^^^^^^^^^^^^^^^^
  File "/home/airflow/.local/lib/python3.12/site-packages/requests/models.py", line 820, in generate
    yield from self.raw.stream(chunk_size, decode_content=True)
  File "/home/airflow/.local/lib/python3.12/site-packages/urllib3/response.py", line 1060, in stream
    data = self.read(amt=amt, decode_content=decode_content)
           ^^^^^^^^^^^^^^^^^^^^^^^^^^^^^^^^^^^^^^^^^^^^^^^^^
  File "/home/airflow/.local/lib/python3.12/site-packages/urllib3/response.py", line 949, in read
    data = self._raw_read(amt)
           ^^^^^^^^^^^^^^^^^^^
  File "/home/airflow/.local/lib/python3.12/site-packages/urllib3/response.py", line 873, in _raw_read
    data = self._fp_read(amt, read1=read1) if not fp_closed else b""
           ^^^^^^^^^^^^^^^^^^^^^^^^^^^^^^^
  File "/home/airflow/.local/lib/python3.12/site-packages/urllib3/response.py", line 856, in _fp_read
    return self._fp.read(amt) if amt is not None else self._fp.read()
           ^^^^^^^^^^^^^^^^^^
  File "/usr/local/lib/python3.12/http/client.py", line 479, in read
    s = self.fp.read(amt)
        ^^^^^^^^^^^^^^^^^
  File "/usr/local/lib/python3.12/socket.py", line 720, in readinto
    return self._sock.recv_into(b)
           ^^^^^^^^^^^^^^^^^^^^^^^
  File "/usr/local/lib/python3.12/ssl.py", line 1251, in recv_into
    return self.read(nbytes, buffer)
           ^^^^^^^^^^^^^^^^^^^^^^^^^
  File "/usr/local/lib/python3.12/ssl.py", line 1103, in read
    return self._sslobj.read(len, buffer)
           ^^^^^^^^^^^^^^^^^^^^^^^^^^^^^^
  File "/home/airflow/.local/lib/python3.12/site-packages/airflow/models/taskinstance.py", line 3095, in signal_handler
    raise AirflowTaskTerminated("Task received SIGTERM signal")
airflow.exceptions.AirflowTaskTerminated: Task received SIGTERM signal
[2025-01-24T19:03:43.679+0000] {taskinstance.py:1225} INFO - Marking task as FAILED. dag_id=coleta_dados_abertos_cnpj, task_id=extract, run_id=scheduled__2024-09-10T00:00:00+00:00, execution_date=20240910T000000, start_date=20250124T190208, end_date=20250124T190343
[2025-01-24T19:03:43.686+0000] {taskinstance.py:340} INFO - ::group::Post task execution logs
[2025-01-24T19:03:43.686+0000] {standard_task_runner.py:124} ERROR - Failed to execute job 610 for task extract ((psycopg2.errors.ForeignKeyViolation) insert or update on table "task_fail" violates foreign key constraint "task_fail_ti_fkey"
DETAIL:  Key (dag_id, task_id, run_id, map_index)=(coleta_dados_abertos_cnpj, extract, scheduled__2024-09-10T00:00:00+00:00, -1) is not present in table "task_instance".

[SQL: INSERT INTO task_fail (task_id, dag_id, run_id, map_index, start_date, end_date, duration) VALUES (%(task_id)s, %(dag_id)s, %(run_id)s, %(map_index)s, %(start_date)s, %(end_date)s, %(duration)s) RETURNING task_fail.id]
[parameters: {'task_id': 'extract', 'dag_id': 'coleta_dados_abertos_cnpj', 'run_id': 'scheduled__2024-09-10T00:00:00+00:00', 'map_index': -1, 'start_date': datetime.datetime(2025, 1, 24, 19, 2, 8, 27532, tzinfo=Timezone('UTC')), 'end_date': datetime.datetime(2025, 1, 24, 19, 3, 43, 679194, tzinfo=Timezone('UTC')), 'duration': 95}]
(Background on this error at: https://sqlalche.me/e/14/gkpj); 1409)
Traceback (most recent call last):
  File "/home/airflow/.local/lib/python3.12/site-packages/airflow/models/taskinstance.py", line 273, in _run_raw_task
    TaskInstance._execute_task_with_callbacks(
  File "/home/airflow/.local/lib/python3.12/site-packages/airflow/models/taskinstance.py", line 3159, in _execute_task_with_callbacks
    result = self._execute_task(context, task_orig)
             ^^^^^^^^^^^^^^^^^^^^^^^^^^^^^^^^^^^^^^
  File "/home/airflow/.local/lib/python3.12/site-packages/airflow/models/taskinstance.py", line 3183, in _execute_task
    return _execute_task(self, context, task_orig)
           ^^^^^^^^^^^^^^^^^^^^^^^^^^^^^^^^^^^^^^^
  File "/home/airflow/.local/lib/python3.12/site-packages/airflow/models/taskinstance.py", line 767, in _execute_task
    result = _execute_callable(context=context, **execute_callable_kwargs)
             ^^^^^^^^^^^^^^^^^^^^^^^^^^^^^^^^^^^^^^^^^^^^^^^^^^^^^^^^^^^^^
  File "/home/airflow/.local/lib/python3.12/site-packages/airflow/models/taskinstance.py", line 733, in _execute_callable
    return ExecutionCallableRunner(
           ^^^^^^^^^^^^^^^^^^^^^^^^
  File "/home/airflow/.local/lib/python3.12/site-packages/airflow/utils/operator_helpers.py", line 252, in run
    return self.func(*args, **kwargs)
           ^^^^^^^^^^^^^^^^^^^^^^^^^^
  File "/home/airflow/.local/lib/python3.12/site-packages/airflow/models/baseoperator.py", line 422, in wrapper
    return func(self, *args, **kwargs)
           ^^^^^^^^^^^^^^^^^^^^^^^^^^^
  File "/home/airflow/.local/lib/python3.12/site-packages/airflow/operators/python.py", line 238, in execute
    return_value = self.execute_callable()
                   ^^^^^^^^^^^^^^^^^^^^^^^
  File "/home/airflow/.local/lib/python3.12/site-packages/airflow/operators/python.py", line 256, in execute_callable
    return runner.run(*self.op_args, **self.op_kwargs)
           ^^^^^^^^^^^^^^^^^^^^^^^^^^^^^^^^^^^^^^^^^^^
  File "/home/airflow/.local/lib/python3.12/site-packages/airflow/utils/operator_helpers.py", line 252, in run
    return self.func(*args, **kwargs)
           ^^^^^^^^^^^^^^^^^^^^^^^^^^
  File "/opt/airflow/dags/coleta_dados_abertos_cnpj/jobs/extract.py", line 123, in extract
    zip_file = download_with_requests(download_file_url)
               ^^^^^^^^^^^^^^^^^^^^^^^^^^^^^^^^^^^^^^^^^
  File "/opt/airflow/dags/coleta_dados_abertos_cnpj/jobs/extract.py", line 53, in download_with_requests
    for chunk in r.iter_content(chunk_size=8192):
                 ^^^^^^^^^^^^^^^^^^^^^^^^^^^^^^^
  File "/home/airflow/.local/lib/python3.12/site-packages/requests/models.py", line 820, in generate
    yield from self.raw.stream(chunk_size, decode_content=True)
  File "/home/airflow/.local/lib/python3.12/site-packages/urllib3/response.py", line 1060, in stream
    data = self.read(amt=amt, decode_content=decode_content)
           ^^^^^^^^^^^^^^^^^^^^^^^^^^^^^^^^^^^^^^^^^^^^^^^^^
  File "/home/airflow/.local/lib/python3.12/site-packages/urllib3/response.py", line 949, in read
    data = self._raw_read(amt)
           ^^^^^^^^^^^^^^^^^^^
  File "/home/airflow/.local/lib/python3.12/site-packages/urllib3/response.py", line 873, in _raw_read
    data = self._fp_read(amt, read1=read1) if not fp_closed else b""
           ^^^^^^^^^^^^^^^^^^^^^^^^^^^^^^^
  File "/home/airflow/.local/lib/python3.12/site-packages/urllib3/response.py", line 856, in _fp_read
    return self._fp.read(amt) if amt is not None else self._fp.read()
           ^^^^^^^^^^^^^^^^^^
  File "/usr/local/lib/python3.12/http/client.py", line 479, in read
    s = self.fp.read(amt)
        ^^^^^^^^^^^^^^^^^
  File "/usr/local/lib/python3.12/socket.py", line 720, in readinto
    return self._sock.recv_into(b)
           ^^^^^^^^^^^^^^^^^^^^^^^
  File "/usr/local/lib/python3.12/ssl.py", line 1251, in recv_into
    return self.read(nbytes, buffer)
           ^^^^^^^^^^^^^^^^^^^^^^^^^
  File "/usr/local/lib/python3.12/ssl.py", line 1103, in read
    return self._sslobj.read(len, buffer)
           ^^^^^^^^^^^^^^^^^^^^^^^^^^^^^^
  File "/home/airflow/.local/lib/python3.12/site-packages/airflow/models/taskinstance.py", line 3095, in signal_handler
    raise AirflowTaskTerminated("Task received SIGTERM signal")
airflow.exceptions.AirflowTaskTerminated: Task received SIGTERM signal

During handling of the above exception, another exception occurred:

Traceback (most recent call last):
  File "/home/airflow/.local/lib/python3.12/site-packages/sqlalchemy/engine/base.py", line 1910, in _execute_context
    self.dialect.do_execute(
  File "/home/airflow/.local/lib/python3.12/site-packages/sqlalchemy/engine/default.py", line 736, in do_execute
    cursor.execute(statement, parameters)
psycopg2.errors.ForeignKeyViolation: insert or update on table "task_fail" violates foreign key constraint "task_fail_ti_fkey"
DETAIL:  Key (dag_id, task_id, run_id, map_index)=(coleta_dados_abertos_cnpj, extract, scheduled__2024-09-10T00:00:00+00:00, -1) is not present in table "task_instance".


The above exception was the direct cause of the following exception:

Traceback (most recent call last):
  File "/home/airflow/.local/lib/python3.12/site-packages/airflow/task/task_runner/standard_task_runner.py", line 117, in _start_by_fork
    ret = args.func(args, dag=self.dag)
          ^^^^^^^^^^^^^^^^^^^^^^^^^^^^^
  File "/home/airflow/.local/lib/python3.12/site-packages/airflow/cli/cli_config.py", line 49, in command
    return func(*args, **kwargs)
           ^^^^^^^^^^^^^^^^^^^^^
  File "/home/airflow/.local/lib/python3.12/site-packages/airflow/utils/cli.py", line 116, in wrapper
    return f(*args, **kwargs)
           ^^^^^^^^^^^^^^^^^^
  File "/home/airflow/.local/lib/python3.12/site-packages/airflow/cli/commands/task_command.py", line 483, in task_run
    task_return_code = _run_task_by_selected_method(args, _dag, ti)
                       ^^^^^^^^^^^^^^^^^^^^^^^^^^^^^^^^^^^^^^^^^^^^
  File "/home/airflow/.local/lib/python3.12/site-packages/airflow/cli/commands/task_command.py", line 256, in _run_task_by_selected_method
    return _run_raw_task(args, ti)
           ^^^^^^^^^^^^^^^^^^^^^^^
  File "/home/airflow/.local/lib/python3.12/site-packages/airflow/cli/commands/task_command.py", line 341, in _run_raw_task
    return ti._run_raw_task(
           ^^^^^^^^^^^^^^^^^
  File "/home/airflow/.local/lib/python3.12/site-packages/airflow/utils/session.py", line 97, in wrapper
    return func(*args, session=session, **kwargs)
           ^^^^^^^^^^^^^^^^^^^^^^^^^^^^^^^^^^^^^^
  File "/home/airflow/.local/lib/python3.12/site-packages/airflow/models/taskinstance.py", line 3005, in _run_raw_task
    return _run_raw_task(
           ^^^^^^^^^^^^^^
  File "/home/airflow/.local/lib/python3.12/site-packages/airflow/models/taskinstance.py", line 327, in _run_raw_task
    ti.handle_failure(e, test_mode, context, session=session)
  File "/home/airflow/.local/lib/python3.12/site-packages/airflow/utils/session.py", line 94, in wrapper
    return func(*args, **kwargs)
           ^^^^^^^^^^^^^^^^^^^^^
  File "/home/airflow/.local/lib/python3.12/site-packages/airflow/models/taskinstance.py", line 3428, in handle_failure
    _handle_failure(
  File "/home/airflow/.local/lib/python3.12/site-packages/airflow/utils/session.py", line 94, in wrapper
    return func(*args, **kwargs)
           ^^^^^^^^^^^^^^^^^^^^^
  File "/home/airflow/.local/lib/python3.12/site-packages/airflow/api_internal/internal_api_call.py", line 166, in wrapper
    return func(*args, **kwargs)
           ^^^^^^^^^^^^^^^^^^^^^
  File "/home/airflow/.local/lib/python3.12/site-packages/airflow/models/taskinstance.py", line 1243, in _handle_failure
    TaskInstance.save_to_db(failure_context["ti"], session)
  File "/home/airflow/.local/lib/python3.12/site-packages/airflow/api_internal/internal_api_call.py", line 166, in wrapper
    return func(*args, **kwargs)
           ^^^^^^^^^^^^^^^^^^^^^
  File "/home/airflow/.local/lib/python3.12/site-packages/airflow/utils/session.py", line 94, in wrapper
    return func(*args, **kwargs)
           ^^^^^^^^^^^^^^^^^^^^^
  File "/home/airflow/.local/lib/python3.12/site-packages/airflow/models/taskinstance.py", line 3400, in save_to_db
    session.flush()
  File "/home/airflow/.local/lib/python3.12/site-packages/sqlalchemy/orm/session.py", line 3449, in flush
    self._flush(objects)
  File "/home/airflow/.local/lib/python3.12/site-packages/sqlalchemy/orm/session.py", line 3588, in _flush
    with util.safe_reraise():
         ^^^^^^^^^^^^^^^^^^^
  File "/home/airflow/.local/lib/python3.12/site-packages/sqlalchemy/util/langhelpers.py", line 70, in __exit__
    compat.raise_(
  File "/home/airflow/.local/lib/python3.12/site-packages/sqlalchemy/util/compat.py", line 211, in raise_
    raise exception
  File "/home/airflow/.local/lib/python3.12/site-packages/sqlalchemy/orm/session.py", line 3549, in _flush
    flush_context.execute()
  File "/home/airflow/.local/lib/python3.12/site-packages/sqlalchemy/orm/unitofwork.py", line 456, in execute
    rec.execute(self)
  File "/home/airflow/.local/lib/python3.12/site-packages/sqlalchemy/orm/unitofwork.py", line 630, in execute
    util.preloaded.orm_persistence.save_obj(
  File "/home/airflow/.local/lib/python3.12/site-packages/sqlalchemy/orm/persistence.py", line 245, in save_obj
    _emit_insert_statements(
  File "/home/airflow/.local/lib/python3.12/site-packages/sqlalchemy/orm/persistence.py", line 1238, in _emit_insert_statements
    result = connection._execute_20(
             ^^^^^^^^^^^^^^^^^^^^^^^
  File "/home/airflow/.local/lib/python3.12/site-packages/sqlalchemy/engine/base.py", line 1710, in _execute_20
    return meth(self, args_10style, kwargs_10style, execution_options)
           ^^^^^^^^^^^^^^^^^^^^^^^^^^^^^^^^^^^^^^^^^^^^^^^^^^^^^^^^^^^
  File "/home/airflow/.local/lib/python3.12/site-packages/sqlalchemy/sql/elements.py", line 334, in _execute_on_connection
    return connection._execute_clauseelement(
           ^^^^^^^^^^^^^^^^^^^^^^^^^^^^^^^^^^
  File "/home/airflow/.local/lib/python3.12/site-packages/sqlalchemy/engine/base.py", line 1577, in _execute_clauseelement
    ret = self._execute_context(
          ^^^^^^^^^^^^^^^^^^^^^^
  File "/home/airflow/.local/lib/python3.12/site-packages/sqlalchemy/engine/base.py", line 1953, in _execute_context
    self._handle_dbapi_exception(
  File "/home/airflow/.local/lib/python3.12/site-packages/sqlalchemy/engine/base.py", line 2134, in _handle_dbapi_exception
    util.raise_(
  File "/home/airflow/.local/lib/python3.12/site-packages/sqlalchemy/util/compat.py", line 211, in raise_
    raise exception
  File "/home/airflow/.local/lib/python3.12/site-packages/sqlalchemy/engine/base.py", line 1910, in _execute_context
    self.dialect.do_execute(
  File "/home/airflow/.local/lib/python3.12/site-packages/sqlalchemy/engine/default.py", line 736, in do_execute
    cursor.execute(statement, parameters)
sqlalchemy.exc.IntegrityError: (psycopg2.errors.ForeignKeyViolation) insert or update on table "task_fail" violates foreign key constraint "task_fail_ti_fkey"
DETAIL:  Key (dag_id, task_id, run_id, map_index)=(coleta_dados_abertos_cnpj, extract, scheduled__2024-09-10T00:00:00+00:00, -1) is not present in table "task_instance".

[SQL: INSERT INTO task_fail (task_id, dag_id, run_id, map_index, start_date, end_date, duration) VALUES (%(task_id)s, %(dag_id)s, %(run_id)s, %(map_index)s, %(start_date)s, %(end_date)s, %(duration)s) RETURNING task_fail.id]
[parameters: {'task_id': 'extract', 'dag_id': 'coleta_dados_abertos_cnpj', 'run_id': 'scheduled__2024-09-10T00:00:00+00:00', 'map_index': -1, 'start_date': datetime.datetime(2025, 1, 24, 19, 2, 8, 27532, tzinfo=Timezone('UTC')), 'end_date': datetime.datetime(2025, 1, 24, 19, 3, 43, 679194, tzinfo=Timezone('UTC')), 'duration': 95}]
(Background on this error at: https://sqlalche.me/e/14/gkpj)
[2025-01-24T19:03:43.721+0000] {process_utils.py:80} INFO - Process psutil.Process(pid=1409, status='terminated', exitcode=1, started='19:02:07') (1409) terminated with exit code 1
