[2025-01-19T19:54:27.517+0000] {local_task_job_runner.py:123} INFO - ::group::Pre task execution logs
[2025-01-19T19:54:27.627+0000] {taskinstance.py:2613} INFO - Dependencies all met for dep_context=non-requeueable deps ti=<TaskInstance: gerar_csv_dados_abertos_cnpj.gerar_csv manual__2025-01-19T19:49:13.414481+00:00 [queued]>
[2025-01-19T19:54:27.631+0000] {taskinstance.py:2613} INFO - Dependencies all met for dep_context=requeueable deps ti=<TaskInstance: gerar_csv_dados_abertos_cnpj.gerar_csv manual__2025-01-19T19:49:13.414481+00:00 [queued]>
[2025-01-19T19:54:27.632+0000] {taskinstance.py:2866} INFO - Starting attempt 4 of 4
[2025-01-19T19:54:27.664+0000] {taskinstance.py:2889} INFO - Executing <Task(PythonOperator): gerar_csv> on 2025-01-19 19:49:13.414481+00:00
[2025-01-19T19:54:27.669+0000] {warnings.py:112} WARNING - /home/***/.local/lib/python3.12/site-packages/***/task/task_runner/standard_task_runner.py:70: DeprecationWarning: This process (pid=320) is multi-threaded, use of fork() may lead to deadlocks in the child.
  pid = os.fork()

[2025-01-19T19:54:27.670+0000] {standard_task_runner.py:72} INFO - Started process 322 to run task
[2025-01-19T19:54:27.670+0000] {standard_task_runner.py:104} INFO - Running: ['***', 'tasks', 'run', 'gerar_csv_dados_abertos_cnpj', 'gerar_csv', 'manual__2025-01-19T19:49:13.414481+00:00', '--job-id', '215', '--raw', '--subdir', 'DAGS_FOLDER/saving_file.py', '--cfg-path', '/tmp/tmp2n0b3xfu']
[2025-01-19T19:54:27.672+0000] {standard_task_runner.py:105} INFO - Job 215: Subtask gerar_csv
[2025-01-19T19:54:27.701+0000] {task_command.py:467} INFO - Running <TaskInstance: gerar_csv_dados_abertos_cnpj.gerar_csv manual__2025-01-19T19:49:13.414481+00:00 [running]> on host f9324e49080a
[2025-01-19T19:54:27.753+0000] {taskinstance.py:3132} INFO - Exporting env vars: AIRFLOW_CTX_DAG_OWNER='***' AIRFLOW_CTX_DAG_ID='gerar_csv_dados_abertos_cnpj' AIRFLOW_CTX_TASK_ID='gerar_csv' AIRFLOW_CTX_EXECUTION_DATE='2025-01-19T19:49:13.414481+00:00' AIRFLOW_CTX_TRY_NUMBER='4' AIRFLOW_CTX_DAG_RUN_ID='manual__2025-01-19T19:49:13.414481+00:00'
[2025-01-19T19:54:27.754+0000] {taskinstance.py:731} INFO - ::endgroup::
[2025-01-19T19:54:27.762+0000] {logging_mixin.py:190} INFO - testanaado
[2025-01-19T19:54:27.763+0000] {logging_mixin.py:190} INFO - Erro ao gerar CSV: [Errno 17] File exists: 'G:/Airlfow/volumes/dados_abertos_cnpj/empresa_dados.csv'
[2025-01-19T19:54:27.766+0000] {logging_mixin.py:190} WARNING - Traceback (most recent call last):
[2025-01-19T19:54:27.766+0000] {logging_mixin.py:190} WARNING -   File "/opt/***/dags/saving_file.py", line 29, in gerar_csv
    os.makedirs(dir_name, exist_ok=True)
[2025-01-19T19:54:27.766+0000] {logging_mixin.py:190} WARNING -   File "<frozen os>", line 225, in makedirs
[2025-01-19T19:54:27.767+0000] {logging_mixin.py:190} WARNING - FileExistsError: [Errno 17] File exists: 'G:/Airlfow/volumes/dados_abertos_cnpj/empresa_dados.csv'
[2025-01-19T19:54:27.767+0000] {python.py:240} INFO - Done. Returned value was: None
[2025-01-19T19:54:27.773+0000] {taskinstance.py:340} INFO - ::group::Post task execution logs
[2025-01-19T19:54:27.773+0000] {taskinstance.py:352} INFO - Marking task as SUCCESS. dag_id=gerar_csv_dados_abertos_cnpj, task_id=gerar_csv, run_id=manual__2025-01-19T19:49:13.414481+00:00, execution_date=20250119T194913, start_date=20250119T195427, end_date=20250119T195427
[2025-01-19T19:54:27.803+0000] {local_task_job_runner.py:266} INFO - Task exited with return code 0
[2025-01-19T19:54:27.812+0000] {taskinstance.py:3895} INFO - 0 downstream tasks scheduled from follow-on schedule check
[2025-01-19T19:54:27.814+0000] {local_task_job_runner.py:245} INFO - ::endgroup::
