[2025-01-24T06:58:38.768+0000] {local_task_job_runner.py:123} INFO - ::group::Pre task execution logs
[2025-01-24T06:58:38.777+0000] {taskinstance.py:2613} INFO - Dependencies all met for dep_context=non-requeueable deps ti=<TaskInstance: coleta_dados_abertos_cnpj.extract manual__2025-01-24T06:56:26.109432+00:00 [queued]>
[2025-01-24T06:58:38.782+0000] {taskinstance.py:2613} INFO - Dependencies all met for dep_context=requeueable deps ti=<TaskInstance: coleta_dados_abertos_cnpj.extract manual__2025-01-24T06:56:26.109432+00:00 [queued]>
[2025-01-24T06:58:38.782+0000] {taskinstance.py:2866} INFO - Starting attempt 4 of 4
[2025-01-24T06:58:38.800+0000] {taskinstance.py:2889} INFO - Executing <Task(PythonOperator): extract> on 2025-01-24 06:56:26.109432+00:00
[2025-01-24T06:58:38.804+0000] {warnings.py:112} WARNING - /home/***/.local/lib/python3.12/site-packages/***/task/task_runner/standard_task_runner.py:70: DeprecationWarning: This process (pid=1461) is multi-threaded, use of fork() may lead to deadlocks in the child.
  pid = os.fork()

[2025-01-24T06:58:38.806+0000] {standard_task_runner.py:72} INFO - Started process 1462 to run task
[2025-01-24T06:58:38.805+0000] {standard_task_runner.py:104} INFO - Running: ['***', 'tasks', 'run', 'coleta_dados_abertos_cnpj', 'extract', 'manual__2025-01-24T06:56:26.109432+00:00', '--job-id', '296', '--raw', '--subdir', 'DAGS_FOLDER/coleta_dados_abertos_cnpj/dag.py', '--cfg-path', '/tmp/tmpdqsvjpw1']
[2025-01-24T06:58:38.806+0000] {standard_task_runner.py:105} INFO - Job 296: Subtask extract
[2025-01-24T06:58:38.831+0000] {task_command.py:467} INFO - Running <TaskInstance: coleta_dados_abertos_cnpj.extract manual__2025-01-24T06:56:26.109432+00:00 [running]> on host ee70781c29c7
[2025-01-24T06:58:38.875+0000] {taskinstance.py:3132} INFO - Exporting env vars: AIRFLOW_CTX_DAG_OWNER='Corvaum' AIRFLOW_CTX_DAG_ID='coleta_dados_abertos_cnpj' AIRFLOW_CTX_TASK_ID='extract' AIRFLOW_CTX_EXECUTION_DATE='2025-01-24T06:56:26.109432+00:00' AIRFLOW_CTX_TRY_NUMBER='4' AIRFLOW_CTX_DAG_RUN_ID='manual__2025-01-24T06:56:26.109432+00:00'
[2025-01-24T06:58:38.876+0000] {taskinstance.py:731} INFO - ::endgroup::
[2025-01-24T06:58:38.888+0000] {logging_mixin.py:190} INFO - 2025-01
[2025-01-24T06:58:39.259+0000] {logging_mixin.py:190} INFO - -----------------
[2025-01-24T06:58:39.260+0000] {logging_mixin.py:190} INFO - ['Cnaes.zip', 'Empresas0.zip', 'Empresas1.zip', 'Empresas2.zip', 'Empresas3.zip', 'Empresas4.zip', 'Empresas5.zip', 'Empresas6.zip', 'Empresas7.zip', 'Empresas8.zip', 'Empresas9.zip', 'Estabelecimentos0.zip', 'Estabelecimentos1.zip', 'Estabelecimentos2.zip', 'Estabelecimentos3.zip', 'Estabelecimentos4.zip', 'Estabelecimentos5.zip', 'Estabelecimentos6.zip', 'Estabelecimentos7.zip', 'Estabelecimentos8.zip', 'Estabelecimentos9.zip', 'Motivos.zip', 'Municipios.zip', 'Naturezas.zip', 'Paises.zip', 'Qualificacoes.zip', 'Simples.zip', 'Socios0.zip', 'Socios1.zip', 'Socios2.zip', 'Socios3.zip', 'Socios4.zip', 'Socios5.zip', 'Socios6.zip', 'Socios7.zip', 'Socios8.zip', 'Socios9.zip']
[2025-01-24T06:58:39.260+0000] {logging_mixin.py:190} INFO - ['Cnaes', 'Empresas', 'Estabelecimentos', 'Motivos', 'Municipios', 'Naturezas', 'Paises', 'Qualificacoes', 'Simples', 'Socios']
[2025-01-24T06:58:39.260+0000] {logging_mixin.py:190} INFO - Iniciando o download de: https://arquivos.receitafederal.gov.br/dados/cnpj/dados_abertos_cnpj/2025-01/Cnaes.zip
[2025-01-24T06:58:39.390+0000] {logging_mixin.py:190} INFO - Arquivo baixado e armazenado na mem√≥ria: Cnaes_4a8472bdab574ddfb3a5e93e72193095
[2025-01-24T06:58:39.391+0000] {taskinstance.py:3311} ERROR - Task failed with exception
Traceback (most recent call last):
  File "/home/airflow/.local/lib/python3.12/site-packages/airflow/models/taskinstance.py", line 767, in _execute_task
    result = _execute_callable(context=context, **execute_callable_kwargs)
             ^^^^^^^^^^^^^^^^^^^^^^^^^^^^^^^^^^^^^^^^^^^^^^^^^^^^^^^^^^^^^
  File "/home/airflow/.local/lib/python3.12/site-packages/airflow/models/taskinstance.py", line 733, in _execute_callable
    return ExecutionCallableRunner(
           ^^^^^^^^^^^^^^^^^^^^^^^^
  File "/home/airflow/.local/lib/python3.12/site-packages/airflow/utils/operator_helpers.py", line 252, in run
    return self.func(*args, **kwargs)
           ^^^^^^^^^^^^^^^^^^^^^^^^^^
  File "/home/airflow/.local/lib/python3.12/site-packages/airflow/models/baseoperator.py", line 422, in wrapper
    return func(self, *args, **kwargs)
           ^^^^^^^^^^^^^^^^^^^^^^^^^^^
  File "/home/airflow/.local/lib/python3.12/site-packages/airflow/operators/python.py", line 238, in execute
    return_value = self.execute_callable()
                   ^^^^^^^^^^^^^^^^^^^^^^^
  File "/home/airflow/.local/lib/python3.12/site-packages/airflow/operators/python.py", line 256, in execute_callable
    return runner.run(*self.op_args, **self.op_kwargs)
           ^^^^^^^^^^^^^^^^^^^^^^^^^^^^^^^^^^^^^^^^^^^
  File "/home/airflow/.local/lib/python3.12/site-packages/airflow/utils/operator_helpers.py", line 252, in run
    return self.func(*args, **kwargs)
           ^^^^^^^^^^^^^^^^^^^^^^^^^^
  File "/opt/airflow/dags/coleta_dados_abertos_cnpj/jobs/extract.py", line 180, in extract
    df = pd.read_csv(file_in_memory)
         ^^
NameError: name 'pd' is not defined
[2025-01-24T06:58:39.399+0000] {taskinstance.py:1225} INFO - Marking task as FAILED. dag_id=coleta_dados_abertos_cnpj, task_id=extract, run_id=manual__2025-01-24T06:56:26.109432+00:00, execution_date=20250124T065626, start_date=20250124T065838, end_date=20250124T065839
[2025-01-24T06:58:39.408+0000] {taskinstance.py:340} INFO - ::group::Post task execution logs
[2025-01-24T06:58:39.408+0000] {standard_task_runner.py:124} ERROR - Failed to execute job 296 for task extract (name 'pd' is not defined; 1462)
Traceback (most recent call last):
  File "/home/airflow/.local/lib/python3.12/site-packages/airflow/task/task_runner/standard_task_runner.py", line 117, in _start_by_fork
    ret = args.func(args, dag=self.dag)
          ^^^^^^^^^^^^^^^^^^^^^^^^^^^^^
  File "/home/airflow/.local/lib/python3.12/site-packages/airflow/cli/cli_config.py", line 49, in command
    return func(*args, **kwargs)
           ^^^^^^^^^^^^^^^^^^^^^
  File "/home/airflow/.local/lib/python3.12/site-packages/airflow/utils/cli.py", line 116, in wrapper
    return f(*args, **kwargs)
           ^^^^^^^^^^^^^^^^^^
  File "/home/airflow/.local/lib/python3.12/site-packages/airflow/cli/commands/task_command.py", line 483, in task_run
    task_return_code = _run_task_by_selected_method(args, _dag, ti)
                       ^^^^^^^^^^^^^^^^^^^^^^^^^^^^^^^^^^^^^^^^^^^^
  File "/home/airflow/.local/lib/python3.12/site-packages/airflow/cli/commands/task_command.py", line 256, in _run_task_by_selected_method
    return _run_raw_task(args, ti)
           ^^^^^^^^^^^^^^^^^^^^^^^
  File "/home/airflow/.local/lib/python3.12/site-packages/airflow/cli/commands/task_command.py", line 341, in _run_raw_task
    return ti._run_raw_task(
           ^^^^^^^^^^^^^^^^^
  File "/home/airflow/.local/lib/python3.12/site-packages/airflow/utils/session.py", line 97, in wrapper
    return func(*args, session=session, **kwargs)
           ^^^^^^^^^^^^^^^^^^^^^^^^^^^^^^^^^^^^^^
  File "/home/airflow/.local/lib/python3.12/site-packages/airflow/models/taskinstance.py", line 3005, in _run_raw_task
    return _run_raw_task(
           ^^^^^^^^^^^^^^
  File "/home/airflow/.local/lib/python3.12/site-packages/airflow/models/taskinstance.py", line 273, in _run_raw_task
    TaskInstance._execute_task_with_callbacks(
  File "/home/airflow/.local/lib/python3.12/site-packages/airflow/models/taskinstance.py", line 3159, in _execute_task_with_callbacks
    result = self._execute_task(context, task_orig)
             ^^^^^^^^^^^^^^^^^^^^^^^^^^^^^^^^^^^^^^
  File "/home/airflow/.local/lib/python3.12/site-packages/airflow/models/taskinstance.py", line 3183, in _execute_task
    return _execute_task(self, context, task_orig)
           ^^^^^^^^^^^^^^^^^^^^^^^^^^^^^^^^^^^^^^^
  File "/home/airflow/.local/lib/python3.12/site-packages/airflow/models/taskinstance.py", line 767, in _execute_task
    result = _execute_callable(context=context, **execute_callable_kwargs)
             ^^^^^^^^^^^^^^^^^^^^^^^^^^^^^^^^^^^^^^^^^^^^^^^^^^^^^^^^^^^^^
  File "/home/airflow/.local/lib/python3.12/site-packages/airflow/models/taskinstance.py", line 733, in _execute_callable
    return ExecutionCallableRunner(
           ^^^^^^^^^^^^^^^^^^^^^^^^
  File "/home/airflow/.local/lib/python3.12/site-packages/airflow/utils/operator_helpers.py", line 252, in run
    return self.func(*args, **kwargs)
           ^^^^^^^^^^^^^^^^^^^^^^^^^^
  File "/home/airflow/.local/lib/python3.12/site-packages/airflow/models/baseoperator.py", line 422, in wrapper
    return func(self, *args, **kwargs)
           ^^^^^^^^^^^^^^^^^^^^^^^^^^^
  File "/home/airflow/.local/lib/python3.12/site-packages/airflow/operators/python.py", line 238, in execute
    return_value = self.execute_callable()
                   ^^^^^^^^^^^^^^^^^^^^^^^
  File "/home/airflow/.local/lib/python3.12/site-packages/airflow/operators/python.py", line 256, in execute_callable
    return runner.run(*self.op_args, **self.op_kwargs)
           ^^^^^^^^^^^^^^^^^^^^^^^^^^^^^^^^^^^^^^^^^^^
  File "/home/airflow/.local/lib/python3.12/site-packages/airflow/utils/operator_helpers.py", line 252, in run
    return self.func(*args, **kwargs)
           ^^^^^^^^^^^^^^^^^^^^^^^^^^
  File "/opt/airflow/dags/coleta_dados_abertos_cnpj/jobs/extract.py", line 180, in extract
    df = pd.read_csv(file_in_memory)
         ^^
NameError: name 'pd' is not defined
[2025-01-24T06:58:39.421+0000] {local_task_job_runner.py:266} INFO - Task exited with return code 1
[2025-01-24T06:58:39.427+0000] {local_task_job_runner.py:245} INFO - ::endgroup::
