[2025-01-18T20:22:31.035+0000] {local_task_job_runner.py:123} INFO - ::group::Pre task execution logs
[2025-01-18T20:22:31.045+0000] {taskinstance.py:2613} INFO - Dependencies all met for dep_context=non-requeueable deps ti=<TaskInstance: coleta_dados_abertos_cnpj.extract manual__2025-01-18T18:00:06.806128+00:00 [queued]>
[2025-01-18T20:22:31.049+0000] {taskinstance.py:2613} INFO - Dependencies all met for dep_context=requeueable deps ti=<TaskInstance: coleta_dados_abertos_cnpj.extract manual__2025-01-18T18:00:06.806128+00:00 [queued]>
[2025-01-18T20:22:31.050+0000] {taskinstance.py:2866} INFO - Starting attempt 47 of 48
[2025-01-18T20:22:31.067+0000] {taskinstance.py:2889} INFO - Executing <Task(PythonOperator): extract> on 2025-01-18 18:00:06.806128+00:00
[2025-01-18T20:22:31.072+0000] {warnings.py:112} WARNING - /home/***/.local/lib/python3.12/site-packages/***/task/task_runner/standard_task_runner.py:70: DeprecationWarning: This process (pid=2467) is multi-threaded, use of fork() may lead to deadlocks in the child.
  pid = os.fork()

[2025-01-18T20:22:31.073+0000] {standard_task_runner.py:72} INFO - Started process 2468 to run task
[2025-01-18T20:22:31.074+0000] {standard_task_runner.py:104} INFO - Running: ['***', 'tasks', 'run', 'coleta_dados_abertos_cnpj', 'extract', 'manual__2025-01-18T18:00:06.806128+00:00', '--job-id', '79', '--raw', '--subdir', 'DAGS_FOLDER/coleta_dados_abertos_cnpj/dag.py', '--cfg-path', '/tmp/tmp1gg8_rda']
[2025-01-18T20:22:31.076+0000] {standard_task_runner.py:105} INFO - Job 79: Subtask extract
[2025-01-18T20:22:31.111+0000] {task_command.py:467} INFO - Running <TaskInstance: coleta_dados_abertos_cnpj.extract manual__2025-01-18T18:00:06.806128+00:00 [running]> on host e9a1739d3128
[2025-01-18T20:22:31.156+0000] {taskinstance.py:3132} INFO - Exporting env vars: AIRFLOW_CTX_DAG_OWNER='Corvaum' AIRFLOW_CTX_DAG_ID='coleta_dados_abertos_cnpj' AIRFLOW_CTX_TASK_ID='extract' AIRFLOW_CTX_EXECUTION_DATE='2025-01-18T18:00:06.806128+00:00' AIRFLOW_CTX_TRY_NUMBER='47' AIRFLOW_CTX_DAG_RUN_ID='manual__2025-01-18T18:00:06.806128+00:00'
[2025-01-18T20:22:31.157+0000] {taskinstance.py:731} INFO - ::endgroup::
[2025-01-18T20:22:31.172+0000] {logging_mixin.py:190} INFO - 2025-01
[2025-01-18T20:22:31.238+0000] {logging_mixin.py:190} INFO - Erro ao listar os arquivos: HTTPSConnectionPool(host='arquivos.receitafederal.gov.br', port=443): Max retries exceeded with url: /dados/cnpj/dados_abertos_cnpj/2025-01 (Caused by SSLError(SSLEOFError(8, '[SSL: UNEXPECTED_EOF_WHILE_READING] EOF occurred in violation of protocol (_ssl.c:1000)')))
[2025-01-18T20:22:31.239+0000] {logging_mixin.py:190} INFO - None
[2025-01-18T20:22:31.240+0000] {python.py:240} INFO - Done. Returned value was: None
[2025-01-18T20:22:31.246+0000] {taskinstance.py:340} INFO - ::group::Post task execution logs
[2025-01-18T20:22:31.246+0000] {taskinstance.py:352} INFO - Marking task as SUCCESS. dag_id=coleta_dados_abertos_cnpj, task_id=extract, run_id=manual__2025-01-18T18:00:06.806128+00:00, execution_date=20250118T180006, start_date=20250118T202231, end_date=20250118T202231
[2025-01-18T20:22:31.288+0000] {local_task_job_runner.py:266} INFO - Task exited with return code 0
[2025-01-18T20:22:31.303+0000] {taskinstance.py:3895} INFO - 0 downstream tasks scheduled from follow-on schedule check
[2025-01-18T20:22:31.306+0000] {local_task_job_runner.py:245} INFO - ::endgroup::
