[2025-01-18T20:57:20.252+0000] {local_task_job_runner.py:123} INFO - ::group::Pre task execution logs
[2025-01-18T20:57:20.260+0000] {taskinstance.py:2613} INFO - Dependencies all met for dep_context=non-requeueable deps ti=<TaskInstance: coleta_dados_abertos_cnpj.extract manual__2025-01-18T20:57:19.737899+00:00 [queued]>
[2025-01-18T20:57:20.264+0000] {taskinstance.py:2613} INFO - Dependencies all met for dep_context=requeueable deps ti=<TaskInstance: coleta_dados_abertos_cnpj.extract manual__2025-01-18T20:57:19.737899+00:00 [queued]>
[2025-01-18T20:57:20.264+0000] {taskinstance.py:2866} INFO - Starting attempt 1 of 2
[2025-01-18T20:57:20.293+0000] {taskinstance.py:2889} INFO - Executing <Task(PythonOperator): extract> on 2025-01-18 20:57:19.737899+00:00
[2025-01-18T20:57:20.298+0000] {warnings.py:112} WARNING - /home/***/.local/lib/python3.12/site-packages/***/task/task_runner/standard_task_runner.py:70: DeprecationWarning: This process (pid=2955) is multi-threaded, use of fork() may lead to deadlocks in the child.
  pid = os.fork()

[2025-01-18T20:57:20.299+0000] {standard_task_runner.py:104} INFO - Running: ['***', 'tasks', 'run', 'coleta_dados_abertos_cnpj', 'extract', 'manual__2025-01-18T20:57:19.737899+00:00', '--job-id', '87', '--raw', '--subdir', 'DAGS_FOLDER/coleta_dados_abertos_cnpj/dag.py', '--cfg-path', '/tmp/tmpasg4vipw']
[2025-01-18T20:57:20.300+0000] {standard_task_runner.py:72} INFO - Started process 2956 to run task
[2025-01-18T20:57:20.300+0000] {standard_task_runner.py:105} INFO - Job 87: Subtask extract
[2025-01-18T20:57:20.326+0000] {task_command.py:467} INFO - Running <TaskInstance: coleta_dados_abertos_cnpj.extract manual__2025-01-18T20:57:19.737899+00:00 [running]> on host e9a1739d3128
[2025-01-18T20:57:20.370+0000] {taskinstance.py:3132} INFO - Exporting env vars: AIRFLOW_CTX_DAG_OWNER='Corvaum' AIRFLOW_CTX_DAG_ID='coleta_dados_abertos_cnpj' AIRFLOW_CTX_TASK_ID='extract' AIRFLOW_CTX_EXECUTION_DATE='2025-01-18T20:57:19.737899+00:00' AIRFLOW_CTX_TRY_NUMBER='1' AIRFLOW_CTX_DAG_RUN_ID='manual__2025-01-18T20:57:19.737899+00:00'
[2025-01-18T20:57:20.371+0000] {taskinstance.py:731} INFO - ::endgroup::
[2025-01-18T20:57:20.386+0000] {logging_mixin.py:190} INFO - 2025-01
[2025-01-18T20:57:20.535+0000] {logging_mixin.py:190} INFO - Erro ao listar os arquivos: HTTPSConnectionPool(host='arquivos.receitafederal.gov.br', port=443): Max retries exceeded with url: /dados/cnpj/dados_abertos_cnpj/2025-01 (Caused by SSLError(SSLEOFError(8, '[SSL: UNEXPECTED_EOF_WHILE_READING] EOF occurred in violation of protocol (_ssl.c:1000)')))
[2025-01-18T20:57:20.536+0000] {logging_mixin.py:190} INFO - None
[2025-01-18T20:57:20.536+0000] {python.py:240} INFO - Done. Returned value was: None
[2025-01-18T20:57:20.542+0000] {taskinstance.py:340} INFO - ::group::Post task execution logs
[2025-01-18T20:57:20.542+0000] {taskinstance.py:352} INFO - Marking task as SUCCESS. dag_id=coleta_dados_abertos_cnpj, task_id=extract, run_id=manual__2025-01-18T20:57:19.737899+00:00, execution_date=20250118T205719, start_date=20250118T205720, end_date=20250118T205720
[2025-01-18T20:57:20.555+0000] {local_task_job_runner.py:266} INFO - Task exited with return code 0
[2025-01-18T20:57:20.563+0000] {taskinstance.py:3895} INFO - 0 downstream tasks scheduled from follow-on schedule check
[2025-01-18T20:57:20.565+0000] {local_task_job_runner.py:245} INFO - ::endgroup::
