[2025-01-24T22:42:00.812+0000] {local_task_job_runner.py:123} INFO - ::group::Pre task execution logs
[2025-01-24T22:42:00.822+0000] {taskinstance.py:2613} INFO - Dependencies all met for dep_context=non-requeueable deps ti=<TaskInstance: coleta_dados_abertos_cnpj.extract_estabelecimentos manual__2025-01-24T21:15:51.387766+00:00 [queued]>
[2025-01-24T22:42:00.829+0000] {taskinstance.py:2613} INFO - Dependencies all met for dep_context=requeueable deps ti=<TaskInstance: coleta_dados_abertos_cnpj.extract_estabelecimentos manual__2025-01-24T21:15:51.387766+00:00 [queued]>
[2025-01-24T22:42:00.829+0000] {taskinstance.py:2866} INFO - Starting attempt 7 of 8
[2025-01-24T22:42:00.858+0000] {taskinstance.py:2889} INFO - Executing <Task(PythonOperator): extract_estabelecimentos> on 2025-01-24 21:15:51.387766+00:00
[2025-01-24T22:42:00.862+0000] {warnings.py:112} WARNING - /home/***/.local/lib/python3.12/site-packages/***/task/task_runner/standard_task_runner.py:70: DeprecationWarning: This process (pid=2419) is multi-threaded, use of fork() may lead to deadlocks in the child.
  pid = os.fork()

[2025-01-24T22:42:00.863+0000] {standard_task_runner.py:72} INFO - Started process 2420 to run task
[2025-01-24T22:42:00.863+0000] {standard_task_runner.py:104} INFO - Running: ['***', 'tasks', 'run', 'coleta_dados_abertos_cnpj', 'extract_estabelecimentos', 'manual__2025-01-24T21:15:51.387766+00:00', '--job-id', '863', '--raw', '--subdir', 'DAGS_FOLDER/coleta_dados_abertos_cnpj/dag.py', '--cfg-path', '/tmp/tmpvxi5r1av']
[2025-01-24T22:42:00.864+0000] {standard_task_runner.py:105} INFO - Job 863: Subtask extract_estabelecimentos
[2025-01-24T22:42:00.894+0000] {task_command.py:467} INFO - Running <TaskInstance: coleta_dados_abertos_cnpj.extract_estabelecimentos manual__2025-01-24T21:15:51.387766+00:00 [running]> on host ee70781c29c7
[2025-01-24T22:42:00.946+0000] {taskinstance.py:3132} INFO - Exporting env vars: AIRFLOW_CTX_DAG_OWNER='Corvaum' AIRFLOW_CTX_DAG_ID='coleta_dados_abertos_cnpj' AIRFLOW_CTX_TASK_ID='extract_estabelecimentos' AIRFLOW_CTX_EXECUTION_DATE='2025-01-24T21:15:51.387766+00:00' AIRFLOW_CTX_TRY_NUMBER='7' AIRFLOW_CTX_DAG_RUN_ID='manual__2025-01-24T21:15:51.387766+00:00'
[2025-01-24T22:42:00.947+0000] {taskinstance.py:731} INFO - ::endgroup::
[2025-01-24T22:42:00.958+0000] {logging_mixin.py:190} INFO - Data formatada: 2025-01
[2025-01-24T22:42:01.221+0000] {logging_mixin.py:190} INFO - Arquivos encontrados: ['Estabelecimentos0.zip', 'Estabelecimentos1.zip', 'Estabelecimentos2.zip', 'Estabelecimentos3.zip', 'Estabelecimentos4.zip', 'Estabelecimentos5.zip', 'Estabelecimentos6.zip', 'Estabelecimentos7.zip', 'Estabelecimentos8.zip', 'Estabelecimentos9.zip']
[2025-01-24T22:42:01.221+0000] {logging_mixin.py:190} INFO - Baixando o arquivo: https://arquivos.receitafederal.gov.br/dados/cnpj/dados_abertos_cnpj/2025-01/Estabelecimentos0.zip
[2025-01-24T22:50:05.580+0000] {logging_mixin.py:190} INFO - Download conclu√≠do: https://arquivos.receitafederal.gov.br/dados/cnpj/dados_abertos_cnpj/2025-01/Estabelecimentos0.zip
[2025-01-24T22:50:21.394+0000] {logging_mixin.py:190} INFO - Arquivos descompactados: ['/tmp/23432bddc4374c1b8a243f3d83fed609_extracted/K3241.K03200Y0.D50111.ESTABELE']
[2025-01-24T22:57:09.604+0000] {connectionpool.py:870} WARNING - Retrying (Retry(total=4, connect=None, read=None, redirect=None, status=None)) after connection broken by 'ReadTimeoutError("HTTPConnectionPool(host='host.docker.internal', port=9000): Read timed out. (read timeout=300)")': /raw/full_cpf/Estabelecimentos/2025-01/Estabelecimentos_c4a8ae5149c147d9804f2c945c5196fd.csv?partNumber=757&uploadId=ZTA4ODNjYjYtMmE3OC00N2Q3LThkNmItYWQ5OTczYjg2YTNiLmJiNDhlZTA5LTE4ZmMtNGJlOC1hMjYwLTVmMDBjMGY4YmEwYngxNzM3NzU5MDIyNjYyMTU5NjEx
[2025-01-24T22:57:09.604+0000] {connectionpool.py:870} WARNING - Retrying (Retry(total=4, connect=None, read=None, redirect=None, status=None)) after connection broken by 'ReadTimeoutError("HTTPConnectionPool(host='host.docker.internal', port=9000): Read timed out. (read timeout=300)")': /raw/full_cpf/Estabelecimentos/2025-01/Estabelecimentos_c4a8ae5149c147d9804f2c945c5196fd.csv?partNumber=758&uploadId=ZTA4ODNjYjYtMmE3OC00N2Q3LThkNmItYWQ5OTczYjg2YTNiLmJiNDhlZTA5LTE4ZmMtNGJlOC1hMjYwLTVmMDBjMGY4YmEwYngxNzM3NzU5MDIyNjYyMTU5NjEx
[2025-01-24T22:57:09.658+0000] {connectionpool.py:870} WARNING - Retrying (Retry(total=4, connect=None, read=None, redirect=None, status=None)) after connection broken by 'ReadTimeoutError("HTTPConnectionPool(host='host.docker.internal', port=9000): Read timed out. (read timeout=300)")': /raw/full_cpf/Estabelecimentos/2025-01/Estabelecimentos_c4a8ae5149c147d9804f2c945c5196fd.csv?partNumber=759&uploadId=ZTA4ODNjYjYtMmE3OC00N2Q3LThkNmItYWQ5OTczYjg2YTNiLmJiNDhlZTA5LTE4ZmMtNGJlOC1hMjYwLTVmMDBjMGY4YmEwYngxNzM3NzU5MDIyNjYyMTU5NjEx
[2025-01-24T22:57:18.007+0000] {connectionpool.py:870} WARNING - Retrying (Retry(total=3, connect=None, read=None, redirect=None, status=None)) after connection broken by 'NameResolutionError("<urllib3.connection.HTTPConnection object at 0x7fe21cfb1070>: Failed to resolve 'host.docker.internal' ([Errno -3] Temporary failure in name resolution)")': /raw/full_cpf/Estabelecimentos/2025-01/Estabelecimentos_c4a8ae5149c147d9804f2c945c5196fd.csv?partNumber=758&uploadId=ZTA4ODNjYjYtMmE3OC00N2Q3LThkNmItYWQ5OTczYjg2YTNiLmJiNDhlZTA5LTE4ZmMtNGJlOC1hMjYwLTVmMDBjMGY4YmEwYngxNzM3NzU5MDIyNjYyMTU5NjEx
[2025-01-24T22:57:18.007+0000] {connectionpool.py:870} WARNING - Retrying (Retry(total=3, connect=None, read=None, redirect=None, status=None)) after connection broken by 'NameResolutionError("<urllib3.connection.HTTPConnection object at 0x7fe21cfb0ec0>: Failed to resolve 'host.docker.internal' ([Errno -3] Temporary failure in name resolution)")': /raw/full_cpf/Estabelecimentos/2025-01/Estabelecimentos_c4a8ae5149c147d9804f2c945c5196fd.csv?partNumber=757&uploadId=ZTA4ODNjYjYtMmE3OC00N2Q3LThkNmItYWQ5OTczYjg2YTNiLmJiNDhlZTA5LTE4ZmMtNGJlOC1hMjYwLTVmMDBjMGY4YmEwYngxNzM3NzU5MDIyNjYyMTU5NjEx
[2025-01-24T22:57:18.061+0000] {connectionpool.py:870} WARNING - Retrying (Retry(total=3, connect=None, read=None, redirect=None, status=None)) after connection broken by 'NameResolutionError("<urllib3.connection.HTTPConnection object at 0x7fe21cfb1880>: Failed to resolve 'host.docker.internal' ([Errno -3] Temporary failure in name resolution)")': /raw/full_cpf/Estabelecimentos/2025-01/Estabelecimentos_c4a8ae5149c147d9804f2c945c5196fd.csv?partNumber=759&uploadId=ZTA4ODNjYjYtMmE3OC00N2Q3LThkNmItYWQ5OTczYjg2YTNiLmJiNDhlZTA5LTE4ZmMtNGJlOC1hMjYwLTVmMDBjMGY4YmEwYngxNzM3NzU5MDIyNjYyMTU5NjEx
[2025-01-24T22:57:26.810+0000] {connectionpool.py:870} WARNING - Retrying (Retry(total=2, connect=None, read=None, redirect=None, status=None)) after connection broken by 'NameResolutionError("<urllib3.connection.HTTPConnection object at 0x7fe21cfb2060>: Failed to resolve 'host.docker.internal' ([Errno -3] Temporary failure in name resolution)")': /raw/full_cpf/Estabelecimentos/2025-01/Estabelecimentos_c4a8ae5149c147d9804f2c945c5196fd.csv?partNumber=757&uploadId=ZTA4ODNjYjYtMmE3OC00N2Q3LThkNmItYWQ5OTczYjg2YTNiLmJiNDhlZTA5LTE4ZmMtNGJlOC1hMjYwLTVmMDBjMGY4YmEwYngxNzM3NzU5MDIyNjYyMTU5NjEx
[2025-01-24T22:57:26.810+0000] {connectionpool.py:870} WARNING - Retrying (Retry(total=2, connect=None, read=None, redirect=None, status=None)) after connection broken by 'NameResolutionError("<urllib3.connection.HTTPConnection object at 0x7fe21cfb1c10>: Failed to resolve 'host.docker.internal' ([Errno -3] Temporary failure in name resolution)")': /raw/full_cpf/Estabelecimentos/2025-01/Estabelecimentos_c4a8ae5149c147d9804f2c945c5196fd.csv?partNumber=758&uploadId=ZTA4ODNjYjYtMmE3OC00N2Q3LThkNmItYWQ5OTczYjg2YTNiLmJiNDhlZTA5LTE4ZmMtNGJlOC1hMjYwLTVmMDBjMGY4YmEwYngxNzM3NzU5MDIyNjYyMTU5NjEx
[2025-01-24T22:57:26.864+0000] {connectionpool.py:870} WARNING - Retrying (Retry(total=2, connect=None, read=None, redirect=None, status=None)) after connection broken by 'NameResolutionError("<urllib3.connection.HTTPConnection object at 0x7fe21cfb2330>: Failed to resolve 'host.docker.internal' ([Errno -3] Temporary failure in name resolution)")': /raw/full_cpf/Estabelecimentos/2025-01/Estabelecimentos_c4a8ae5149c147d9804f2c945c5196fd.csv?partNumber=759&uploadId=ZTA4ODNjYjYtMmE3OC00N2Q3LThkNmItYWQ5OTczYjg2YTNiLmJiNDhlZTA5LTE4ZmMtNGJlOC1hMjYwLTVmMDBjMGY4YmEwYngxNzM3NzU5MDIyNjYyMTU5NjEx
[2025-01-24T22:57:36.414+0000] {connectionpool.py:870} WARNING - Retrying (Retry(total=1, connect=None, read=None, redirect=None, status=None)) after connection broken by 'NameResolutionError("<urllib3.connection.HTTPConnection object at 0x7fe21cfb2630>: Failed to resolve 'host.docker.internal' ([Errno -3] Temporary failure in name resolution)")': /raw/full_cpf/Estabelecimentos/2025-01/Estabelecimentos_c4a8ae5149c147d9804f2c945c5196fd.csv?partNumber=757&uploadId=ZTA4ODNjYjYtMmE3OC00N2Q3LThkNmItYWQ5OTczYjg2YTNiLmJiNDhlZTA5LTE4ZmMtNGJlOC1hMjYwLTVmMDBjMGY4YmEwYngxNzM3NzU5MDIyNjYyMTU5NjEx
[2025-01-24T22:57:36.414+0000] {connectionpool.py:870} WARNING - Retrying (Retry(total=1, connect=None, read=None, redirect=None, status=None)) after connection broken by 'NameResolutionError("<urllib3.connection.HTTPConnection object at 0x7fe21cfb2b40>: Failed to resolve 'host.docker.internal' ([Errno -3] Temporary failure in name resolution)")': /raw/full_cpf/Estabelecimentos/2025-01/Estabelecimentos_c4a8ae5149c147d9804f2c945c5196fd.csv?partNumber=758&uploadId=ZTA4ODNjYjYtMmE3OC00N2Q3LThkNmItYWQ5OTczYjg2YTNiLmJiNDhlZTA5LTE4ZmMtNGJlOC1hMjYwLTVmMDBjMGY4YmEwYngxNzM3NzU5MDIyNjYyMTU5NjEx
[2025-01-24T22:57:36.467+0000] {connectionpool.py:870} WARNING - Retrying (Retry(total=1, connect=None, read=None, redirect=None, status=None)) after connection broken by 'NameResolutionError("<urllib3.connection.HTTPConnection object at 0x7fe21cfb2f00>: Failed to resolve 'host.docker.internal' ([Errno -3] Temporary failure in name resolution)")': /raw/full_cpf/Estabelecimentos/2025-01/Estabelecimentos_c4a8ae5149c147d9804f2c945c5196fd.csv?partNumber=759&uploadId=ZTA4ODNjYjYtMmE3OC00N2Q3LThkNmItYWQ5OTczYjg2YTNiLmJiNDhlZTA5LTE4ZmMtNGJlOC1hMjYwLTVmMDBjMGY4YmEwYngxNzM3NzU5MDIyNjYyMTU5NjEx
[2025-01-24T22:57:47.617+0000] {connectionpool.py:870} WARNING - Retrying (Retry(total=0, connect=None, read=None, redirect=None, status=None)) after connection broken by 'NameResolutionError("<urllib3.connection.HTTPConnection object at 0x7fe21cfb34a0>: Failed to resolve 'host.docker.internal' ([Errno -3] Temporary failure in name resolution)")': /raw/full_cpf/Estabelecimentos/2025-01/Estabelecimentos_c4a8ae5149c147d9804f2c945c5196fd.csv?partNumber=757&uploadId=ZTA4ODNjYjYtMmE3OC00N2Q3LThkNmItYWQ5OTczYjg2YTNiLmJiNDhlZTA5LTE4ZmMtNGJlOC1hMjYwLTVmMDBjMGY4YmEwYngxNzM3NzU5MDIyNjYyMTU5NjEx
[2025-01-24T22:57:47.618+0000] {connectionpool.py:870} WARNING - Retrying (Retry(total=0, connect=None, read=None, redirect=None, status=None)) after connection broken by 'NameResolutionError("<urllib3.connection.HTTPConnection object at 0x7fe21cfb3650>: Failed to resolve 'host.docker.internal' ([Errno -3] Temporary failure in name resolution)")': /raw/full_cpf/Estabelecimentos/2025-01/Estabelecimentos_c4a8ae5149c147d9804f2c945c5196fd.csv?partNumber=758&uploadId=ZTA4ODNjYjYtMmE3OC00N2Q3LThkNmItYWQ5OTczYjg2YTNiLmJiNDhlZTA5LTE4ZmMtNGJlOC1hMjYwLTVmMDBjMGY4YmEwYngxNzM3NzU5MDIyNjYyMTU5NjEx
[2025-01-24T22:57:47.670+0000] {connectionpool.py:870} WARNING - Retrying (Retry(total=0, connect=None, read=None, redirect=None, status=None)) after connection broken by 'NameResolutionError("<urllib3.connection.HTTPConnection object at 0x7fe21cfb3aa0>: Failed to resolve 'host.docker.internal' ([Errno -3] Temporary failure in name resolution)")': /raw/full_cpf/Estabelecimentos/2025-01/Estabelecimentos_c4a8ae5149c147d9804f2c945c5196fd.csv?partNumber=759&uploadId=ZTA4ODNjYjYtMmE3OC00N2Q3LThkNmItYWQ5OTczYjg2YTNiLmJiNDhlZTA5LTE4ZmMtNGJlOC1hMjYwLTVmMDBjMGY4YmEwYngxNzM3NzU5MDIyNjYyMTU5NjEx
[2025-01-24T22:58:03.798+0000] {connectionpool.py:870} WARNING - Retrying (Retry(total=4, connect=None, read=None, redirect=None, status=None)) after connection broken by 'NameResolutionError("<urllib3.connection.HTTPConnection object at 0x7fe21cff0920>: Failed to resolve 'host.docker.internal' ([Errno -3] Temporary failure in name resolution)")': /raw/full_cpf/Estabelecimentos/2025-01/Estabelecimentos_c4a8ae5149c147d9804f2c945c5196fd.csv?uploadId=ZTA4ODNjYjYtMmE3OC00N2Q3LThkNmItYWQ5OTczYjg2YTNiLmJiNDhlZTA5LTE4ZmMtNGJlOC1hMjYwLTVmMDBjMGY4YmEwYngxNzM3NzU5MDIyNjYyMTU5NjEx
[2025-01-24T22:58:12.202+0000] {connectionpool.py:870} WARNING - Retrying (Retry(total=3, connect=None, read=None, redirect=None, status=None)) after connection broken by 'NameResolutionError("<urllib3.connection.HTTPConnection object at 0x7fe21cff0bf0>: Failed to resolve 'host.docker.internal' ([Errno -3] Temporary failure in name resolution)")': /raw/full_cpf/Estabelecimentos/2025-01/Estabelecimentos_c4a8ae5149c147d9804f2c945c5196fd.csv?uploadId=ZTA4ODNjYjYtMmE3OC00N2Q3LThkNmItYWQ5OTczYjg2YTNiLmJiNDhlZTA5LTE4ZmMtNGJlOC1hMjYwLTVmMDBjMGY4YmEwYngxNzM3NzU5MDIyNjYyMTU5NjEx
[2025-01-24T22:58:21.005+0000] {connectionpool.py:870} WARNING - Retrying (Retry(total=2, connect=None, read=None, redirect=None, status=None)) after connection broken by 'NameResolutionError("<urllib3.connection.HTTPConnection object at 0x7fe21cff0d10>: Failed to resolve 'host.docker.internal' ([Errno -3] Temporary failure in name resolution)")': /raw/full_cpf/Estabelecimentos/2025-01/Estabelecimentos_c4a8ae5149c147d9804f2c945c5196fd.csv?uploadId=ZTA4ODNjYjYtMmE3OC00N2Q3LThkNmItYWQ5OTczYjg2YTNiLmJiNDhlZTA5LTE4ZmMtNGJlOC1hMjYwLTVmMDBjMGY4YmEwYngxNzM3NzU5MDIyNjYyMTU5NjEx
[2025-01-24T22:58:30.608+0000] {connectionpool.py:870} WARNING - Retrying (Retry(total=1, connect=None, read=None, redirect=None, status=None)) after connection broken by 'NameResolutionError("<urllib3.connection.HTTPConnection object at 0x7fe21cff11f0>: Failed to resolve 'host.docker.internal' ([Errno -3] Temporary failure in name resolution)")': /raw/full_cpf/Estabelecimentos/2025-01/Estabelecimentos_c4a8ae5149c147d9804f2c945c5196fd.csv?uploadId=ZTA4ODNjYjYtMmE3OC00N2Q3LThkNmItYWQ5OTczYjg2YTNiLmJiNDhlZTA5LTE4ZmMtNGJlOC1hMjYwLTVmMDBjMGY4YmEwYngxNzM3NzU5MDIyNjYyMTU5NjEx
[2025-01-24T22:58:41.811+0000] {connectionpool.py:870} WARNING - Retrying (Retry(total=0, connect=None, read=None, redirect=None, status=None)) after connection broken by 'NameResolutionError("<urllib3.connection.HTTPConnection object at 0x7fe21cff1400>: Failed to resolve 'host.docker.internal' ([Errno -3] Temporary failure in name resolution)")': /raw/full_cpf/Estabelecimentos/2025-01/Estabelecimentos_c4a8ae5149c147d9804f2c945c5196fd.csv?uploadId=ZTA4ODNjYjYtMmE3OC00N2Q3LThkNmItYWQ5OTczYjg2YTNiLmJiNDhlZTA5LTE4ZmMtNGJlOC1hMjYwLTVmMDBjMGY4YmEwYngxNzM3NzU5MDIyNjYyMTU5NjEx
