[2025-01-18T21:22:26.563+0000] {local_task_job_runner.py:123} INFO - ::group::Pre task execution logs
[2025-01-18T21:22:26.574+0000] {taskinstance.py:2613} INFO - Dependencies all met for dep_context=non-requeueable deps ti=<TaskInstance: coleta_dados_abertos_cnpj.extract scheduled__2022-02-10T00:00:00+00:00 [queued]>
[2025-01-18T21:22:26.580+0000] {taskinstance.py:2613} INFO - Dependencies all met for dep_context=requeueable deps ti=<TaskInstance: coleta_dados_abertos_cnpj.extract scheduled__2022-02-10T00:00:00+00:00 [queued]>
[2025-01-18T21:22:26.581+0000] {taskinstance.py:2866} INFO - Starting attempt 1 of 2
[2025-01-18T21:22:26.616+0000] {taskinstance.py:2889} INFO - Executing <Task(PythonOperator): extract> on 2022-02-10 00:00:00+00:00
[2025-01-18T21:22:26.621+0000] {warnings.py:112} WARNING - /home/***/.local/lib/python3.12/site-packages/***/task/task_runner/standard_task_runner.py:70: DeprecationWarning: This process (pid=258) is multi-threaded, use of fork() may lead to deadlocks in the child.
  pid = os.fork()

[2025-01-18T21:22:26.622+0000] {standard_task_runner.py:72} INFO - Started process 268 to run task
[2025-01-18T21:22:26.622+0000] {standard_task_runner.py:104} INFO - Running: ['***', 'tasks', 'run', 'coleta_dados_abertos_cnpj', 'extract', 'scheduled__2022-02-10T00:00:00+00:00', '--job-id', '96', '--raw', '--subdir', 'DAGS_FOLDER/coleta_dados_abertos_cnpj/dag.py', '--cfg-path', '/tmp/tmpof5j2fdd']
[2025-01-18T21:22:26.624+0000] {standard_task_runner.py:105} INFO - Job 96: Subtask extract
[2025-01-18T21:22:26.655+0000] {task_command.py:467} INFO - Running <TaskInstance: coleta_dados_abertos_cnpj.extract scheduled__2022-02-10T00:00:00+00:00 [running]> on host e9a1739d3128
[2025-01-18T21:22:26.702+0000] {taskinstance.py:3132} INFO - Exporting env vars: AIRFLOW_CTX_DAG_OWNER='Corvaum' AIRFLOW_CTX_DAG_ID='coleta_dados_abertos_cnpj' AIRFLOW_CTX_TASK_ID='extract' AIRFLOW_CTX_EXECUTION_DATE='2022-02-10T00:00:00+00:00' AIRFLOW_CTX_TRY_NUMBER='1' AIRFLOW_CTX_DAG_RUN_ID='scheduled__2022-02-10T00:00:00+00:00'
[2025-01-18T21:22:26.703+0000] {taskinstance.py:731} INFO - ::endgroup::
[2025-01-18T21:22:26.716+0000] {logging_mixin.py:190} INFO - 2022-02
[2025-01-18T21:22:27.906+0000] {logging_mixin.py:190} INFO - Erro ao listar os arquivos: 404 Client Error: Not Found for url: https://arquivos.receitafederal.gov.br/dados/cnpj/dados_abertos_cnpj/2022-02
[2025-01-18T21:22:27.906+0000] {logging_mixin.py:190} INFO - None
[2025-01-18T21:22:27.907+0000] {python.py:240} INFO - Done. Returned value was: None
[2025-01-18T21:22:27.912+0000] {taskinstance.py:340} INFO - ::group::Post task execution logs
[2025-01-18T21:22:27.912+0000] {taskinstance.py:352} INFO - Marking task as SUCCESS. dag_id=coleta_dados_abertos_cnpj, task_id=extract, run_id=scheduled__2022-02-10T00:00:00+00:00, execution_date=20220210T000000, start_date=20250118T212226, end_date=20250118T212227
[2025-01-18T21:22:27.958+0000] {local_task_job_runner.py:266} INFO - Task exited with return code 0
[2025-01-18T21:22:27.967+0000] {taskinstance.py:3895} INFO - 0 downstream tasks scheduled from follow-on schedule check
[2025-01-18T21:22:27.971+0000] {local_task_job_runner.py:245} INFO - ::endgroup::
[2025-01-19T20:06:19.883+0000] {local_task_job_runner.py:123} INFO - ::group::Pre task execution logs
[2025-01-19T20:06:19.893+0000] {taskinstance.py:2613} INFO - Dependencies all met for dep_context=non-requeueable deps ti=<TaskInstance: coleta_dados_abertos_cnpj.extract scheduled__2022-02-10T00:00:00+00:00 [queued]>
[2025-01-19T20:06:19.898+0000] {taskinstance.py:2613} INFO - Dependencies all met for dep_context=requeueable deps ti=<TaskInstance: coleta_dados_abertos_cnpj.extract scheduled__2022-02-10T00:00:00+00:00 [queued]>
[2025-01-19T20:06:19.899+0000] {taskinstance.py:2866} INFO - Starting attempt 1 of 2
[2025-01-19T20:06:19.912+0000] {taskinstance.py:2889} INFO - Executing <Task(PythonOperator): extract> on 2022-02-10 00:00:00+00:00
[2025-01-19T20:06:19.916+0000] {warnings.py:112} WARNING - /home/***/.local/lib/python3.12/site-packages/***/task/task_runner/standard_task_runner.py:70: DeprecationWarning: This process (pid=80) is multi-threaded, use of fork() may lead to deadlocks in the child.
  pid = os.fork()

[2025-01-19T20:06:19.918+0000] {standard_task_runner.py:72} INFO - Started process 89 to run task
[2025-01-19T20:06:19.919+0000] {standard_task_runner.py:104} INFO - Running: ['***', 'tasks', 'run', 'coleta_dados_abertos_cnpj', 'extract', 'scheduled__2022-02-10T00:00:00+00:00', '--job-id', '6', '--raw', '--subdir', 'DAGS_FOLDER/coleta_dados_abertos_cnpj/dag.py', '--cfg-path', '/tmp/tmpmxf0ooee']
[2025-01-19T20:06:19.922+0000] {standard_task_runner.py:105} INFO - Job 6: Subtask extract
[2025-01-19T20:06:19.959+0000] {task_command.py:467} INFO - Running <TaskInstance: coleta_dados_abertos_cnpj.extract scheduled__2022-02-10T00:00:00+00:00 [running]> on host 659dab735c6e
[2025-01-19T20:06:20.013+0000] {taskinstance.py:3132} INFO - Exporting env vars: AIRFLOW_CTX_DAG_OWNER='Corvaum' AIRFLOW_CTX_DAG_ID='coleta_dados_abertos_cnpj' AIRFLOW_CTX_TASK_ID='extract' AIRFLOW_CTX_EXECUTION_DATE='2022-02-10T00:00:00+00:00' AIRFLOW_CTX_TRY_NUMBER='1' AIRFLOW_CTX_DAG_RUN_ID='scheduled__2022-02-10T00:00:00+00:00'
[2025-01-19T20:06:20.014+0000] {taskinstance.py:731} INFO - ::endgroup::
[2025-01-19T20:06:20.030+0000] {logging_mixin.py:190} INFO - 2022-02
[2025-01-19T20:06:20.344+0000] {logging_mixin.py:190} INFO - Erro ao listar os arquivos: HTTPSConnectionPool(host='arquivos.receitafederal.gov.br', port=443): Max retries exceeded with url: /dados/cnpj/dados_abertos_cnpj/2022-02 (Caused by SSLError(SSLEOFError(8, '[SSL: UNEXPECTED_EOF_WHILE_READING] EOF occurred in violation of protocol (_ssl.c:1000)')))
[2025-01-19T20:06:20.345+0000] {logging_mixin.py:190} INFO - -----------------
[2025-01-19T20:06:20.345+0000] {logging_mixin.py:190} INFO - None
[2025-01-19T20:06:20.347+0000] {logging_mixin.py:190} INFO - ['Cnaes']
[2025-01-19T20:06:20.348+0000] {taskinstance.py:3311} ERROR - Task failed with exception
Traceback (most recent call last):
  File "/home/airflow/.local/lib/python3.12/site-packages/airflow/models/taskinstance.py", line 767, in _execute_task
    result = _execute_callable(context=context, **execute_callable_kwargs)
             ^^^^^^^^^^^^^^^^^^^^^^^^^^^^^^^^^^^^^^^^^^^^^^^^^^^^^^^^^^^^^
  File "/home/airflow/.local/lib/python3.12/site-packages/airflow/models/taskinstance.py", line 733, in _execute_callable
    return ExecutionCallableRunner(
           ^^^^^^^^^^^^^^^^^^^^^^^^
  File "/home/airflow/.local/lib/python3.12/site-packages/airflow/utils/operator_helpers.py", line 252, in run
    return self.func(*args, **kwargs)
           ^^^^^^^^^^^^^^^^^^^^^^^^^^
  File "/home/airflow/.local/lib/python3.12/site-packages/airflow/models/baseoperator.py", line 422, in wrapper
    return func(self, *args, **kwargs)
           ^^^^^^^^^^^^^^^^^^^^^^^^^^^
  File "/home/airflow/.local/lib/python3.12/site-packages/airflow/operators/python.py", line 238, in execute
    return_value = self.execute_callable()
                   ^^^^^^^^^^^^^^^^^^^^^^^
  File "/home/airflow/.local/lib/python3.12/site-packages/airflow/operators/python.py", line 256, in execute_callable
    return runner.run(*self.op_args, **self.op_kwargs)
           ^^^^^^^^^^^^^^^^^^^^^^^^^^^^^^^^^^^^^^^^^^^
  File "/home/airflow/.local/lib/python3.12/site-packages/airflow/utils/operator_helpers.py", line 252, in run
    return self.func(*args, **kwargs)
           ^^^^^^^^^^^^^^^^^^^^^^^^^^
  File "/opt/airflow/dags/coleta_dados_abertos_cnpj/jobs/extract.py", line 96, in extract
    for file in files:
                ^^^^^
TypeError: 'NoneType' object is not iterable
[2025-01-19T20:06:20.359+0000] {taskinstance.py:1225} INFO - Marking task as UP_FOR_RETRY. dag_id=coleta_dados_abertos_cnpj, task_id=extract, run_id=scheduled__2022-02-10T00:00:00+00:00, execution_date=20220210T000000, start_date=20250119T200619, end_date=20250119T200620
[2025-01-19T20:06:20.371+0000] {taskinstance.py:340} INFO - ::group::Post task execution logs
[2025-01-19T20:06:20.372+0000] {standard_task_runner.py:124} ERROR - Failed to execute job 6 for task extract ('NoneType' object is not iterable; 89)
Traceback (most recent call last):
  File "/home/airflow/.local/lib/python3.12/site-packages/airflow/task/task_runner/standard_task_runner.py", line 117, in _start_by_fork
    ret = args.func(args, dag=self.dag)
          ^^^^^^^^^^^^^^^^^^^^^^^^^^^^^
  File "/home/airflow/.local/lib/python3.12/site-packages/airflow/cli/cli_config.py", line 49, in command
    return func(*args, **kwargs)
           ^^^^^^^^^^^^^^^^^^^^^
  File "/home/airflow/.local/lib/python3.12/site-packages/airflow/utils/cli.py", line 116, in wrapper
    return f(*args, **kwargs)
           ^^^^^^^^^^^^^^^^^^
  File "/home/airflow/.local/lib/python3.12/site-packages/airflow/cli/commands/task_command.py", line 483, in task_run
    task_return_code = _run_task_by_selected_method(args, _dag, ti)
                       ^^^^^^^^^^^^^^^^^^^^^^^^^^^^^^^^^^^^^^^^^^^^
  File "/home/airflow/.local/lib/python3.12/site-packages/airflow/cli/commands/task_command.py", line 256, in _run_task_by_selected_method
    return _run_raw_task(args, ti)
           ^^^^^^^^^^^^^^^^^^^^^^^
  File "/home/airflow/.local/lib/python3.12/site-packages/airflow/cli/commands/task_command.py", line 341, in _run_raw_task
    return ti._run_raw_task(
           ^^^^^^^^^^^^^^^^^
  File "/home/airflow/.local/lib/python3.12/site-packages/airflow/utils/session.py", line 97, in wrapper
    return func(*args, session=session, **kwargs)
           ^^^^^^^^^^^^^^^^^^^^^^^^^^^^^^^^^^^^^^
  File "/home/airflow/.local/lib/python3.12/site-packages/airflow/models/taskinstance.py", line 3005, in _run_raw_task
    return _run_raw_task(
           ^^^^^^^^^^^^^^
  File "/home/airflow/.local/lib/python3.12/site-packages/airflow/models/taskinstance.py", line 273, in _run_raw_task
    TaskInstance._execute_task_with_callbacks(
  File "/home/airflow/.local/lib/python3.12/site-packages/airflow/models/taskinstance.py", line 3159, in _execute_task_with_callbacks
    result = self._execute_task(context, task_orig)
             ^^^^^^^^^^^^^^^^^^^^^^^^^^^^^^^^^^^^^^
  File "/home/airflow/.local/lib/python3.12/site-packages/airflow/models/taskinstance.py", line 3183, in _execute_task
    return _execute_task(self, context, task_orig)
           ^^^^^^^^^^^^^^^^^^^^^^^^^^^^^^^^^^^^^^^
  File "/home/airflow/.local/lib/python3.12/site-packages/airflow/models/taskinstance.py", line 767, in _execute_task
    result = _execute_callable(context=context, **execute_callable_kwargs)
             ^^^^^^^^^^^^^^^^^^^^^^^^^^^^^^^^^^^^^^^^^^^^^^^^^^^^^^^^^^^^^
  File "/home/airflow/.local/lib/python3.12/site-packages/airflow/models/taskinstance.py", line 733, in _execute_callable
    return ExecutionCallableRunner(
           ^^^^^^^^^^^^^^^^^^^^^^^^
  File "/home/airflow/.local/lib/python3.12/site-packages/airflow/utils/operator_helpers.py", line 252, in run
    return self.func(*args, **kwargs)
           ^^^^^^^^^^^^^^^^^^^^^^^^^^
  File "/home/airflow/.local/lib/python3.12/site-packages/airflow/models/baseoperator.py", line 422, in wrapper
    return func(self, *args, **kwargs)
           ^^^^^^^^^^^^^^^^^^^^^^^^^^^
  File "/home/airflow/.local/lib/python3.12/site-packages/airflow/operators/python.py", line 238, in execute
    return_value = self.execute_callable()
                   ^^^^^^^^^^^^^^^^^^^^^^^
  File "/home/airflow/.local/lib/python3.12/site-packages/airflow/operators/python.py", line 256, in execute_callable
    return runner.run(*self.op_args, **self.op_kwargs)
           ^^^^^^^^^^^^^^^^^^^^^^^^^^^^^^^^^^^^^^^^^^^
  File "/home/airflow/.local/lib/python3.12/site-packages/airflow/utils/operator_helpers.py", line 252, in run
    return self.func(*args, **kwargs)
           ^^^^^^^^^^^^^^^^^^^^^^^^^^
  File "/opt/airflow/dags/coleta_dados_abertos_cnpj/jobs/extract.py", line 96, in extract
    for file in files:
                ^^^^^
TypeError: 'NoneType' object is not iterable
[2025-01-19T20:06:20.414+0000] {local_task_job_runner.py:266} INFO - Task exited with return code 1
[2025-01-19T20:06:20.421+0000] {local_task_job_runner.py:245} INFO - ::endgroup::
[2025-01-19T22:19:12.606+0000] {local_task_job_runner.py:123} INFO - ::group::Pre task execution logs
[2025-01-19T22:19:12.619+0000] {taskinstance.py:2613} INFO - Dependencies all met for dep_context=non-requeueable deps ti=<TaskInstance: coleta_dados_abertos_cnpj.extract scheduled__2022-02-10T00:00:00+00:00 [queued]>
[2025-01-19T22:19:12.624+0000] {taskinstance.py:2613} INFO - Dependencies all met for dep_context=requeueable deps ti=<TaskInstance: coleta_dados_abertos_cnpj.extract scheduled__2022-02-10T00:00:00+00:00 [queued]>
[2025-01-19T22:19:12.624+0000] {taskinstance.py:2866} INFO - Starting attempt 1 of 2
[2025-01-19T22:19:12.653+0000] {taskinstance.py:2889} INFO - Executing <Task(PythonOperator): extract> on 2022-02-10 00:00:00+00:00
[2025-01-19T22:19:12.658+0000] {warnings.py:112} WARNING - /home/***/.local/lib/python3.12/site-packages/***/task/task_runner/standard_task_runner.py:70: DeprecationWarning: This process (pid=405) is multi-threaded, use of fork() may lead to deadlocks in the child.
  pid = os.fork()

[2025-01-19T22:19:12.659+0000] {standard_task_runner.py:72} INFO - Started process 414 to run task
[2025-01-19T22:19:12.659+0000] {standard_task_runner.py:104} INFO - Running: ['***', 'tasks', 'run', 'coleta_dados_abertos_cnpj', 'extract', 'scheduled__2022-02-10T00:00:00+00:00', '--job-id', '125', '--raw', '--subdir', 'DAGS_FOLDER/coleta_dados_abertos_cnpj/dag.py', '--cfg-path', '/tmp/tmpl0uf47i6']
[2025-01-19T22:19:12.661+0000] {standard_task_runner.py:105} INFO - Job 125: Subtask extract
[2025-01-19T22:19:12.700+0000] {task_command.py:467} INFO - Running <TaskInstance: coleta_dados_abertos_cnpj.extract scheduled__2022-02-10T00:00:00+00:00 [running]> on host 659dab735c6e
[2025-01-19T22:19:12.756+0000] {taskinstance.py:3132} INFO - Exporting env vars: AIRFLOW_CTX_DAG_OWNER='Corvaum' AIRFLOW_CTX_DAG_ID='coleta_dados_abertos_cnpj' AIRFLOW_CTX_TASK_ID='extract' AIRFLOW_CTX_EXECUTION_DATE='2022-02-10T00:00:00+00:00' AIRFLOW_CTX_TRY_NUMBER='1' AIRFLOW_CTX_DAG_RUN_ID='scheduled__2022-02-10T00:00:00+00:00'
[2025-01-19T22:19:12.757+0000] {taskinstance.py:731} INFO - ::endgroup::
[2025-01-19T22:19:12.770+0000] {logging_mixin.py:190} INFO - 2022-02
[2025-01-19T22:19:13.958+0000] {logging_mixin.py:190} INFO - Erro ao listar os arquivos: 404 Client Error: Not Found for url: https://arquivos.receitafederal.gov.br/dados/cnpj/dados_abertos_cnpj/2022-02
[2025-01-19T22:19:13.959+0000] {logging_mixin.py:190} INFO - -----------------
[2025-01-19T22:19:13.959+0000] {logging_mixin.py:190} INFO - None
[2025-01-19T22:19:13.959+0000] {logging_mixin.py:190} INFO - ['Cnaes', 'Empresas', 'Estabelecimentos', 'Motivos', 'Municipios', 'Naturezas', 'Paises', 'Qualificacoes', 'Simples', 'Socios']
[2025-01-19T22:19:13.960+0000] {taskinstance.py:3311} ERROR - Task failed with exception
Traceback (most recent call last):
  File "/home/airflow/.local/lib/python3.12/site-packages/airflow/models/taskinstance.py", line 767, in _execute_task
    result = _execute_callable(context=context, **execute_callable_kwargs)
             ^^^^^^^^^^^^^^^^^^^^^^^^^^^^^^^^^^^^^^^^^^^^^^^^^^^^^^^^^^^^^
  File "/home/airflow/.local/lib/python3.12/site-packages/airflow/models/taskinstance.py", line 733, in _execute_callable
    return ExecutionCallableRunner(
           ^^^^^^^^^^^^^^^^^^^^^^^^
  File "/home/airflow/.local/lib/python3.12/site-packages/airflow/utils/operator_helpers.py", line 252, in run
    return self.func(*args, **kwargs)
           ^^^^^^^^^^^^^^^^^^^^^^^^^^
  File "/home/airflow/.local/lib/python3.12/site-packages/airflow/models/baseoperator.py", line 422, in wrapper
    return func(self, *args, **kwargs)
           ^^^^^^^^^^^^^^^^^^^^^^^^^^^
  File "/home/airflow/.local/lib/python3.12/site-packages/airflow/operators/python.py", line 238, in execute
    return_value = self.execute_callable()
                   ^^^^^^^^^^^^^^^^^^^^^^^
  File "/home/airflow/.local/lib/python3.12/site-packages/airflow/operators/python.py", line 256, in execute_callable
    return runner.run(*self.op_args, **self.op_kwargs)
           ^^^^^^^^^^^^^^^^^^^^^^^^^^^^^^^^^^^^^^^^^^^
  File "/home/airflow/.local/lib/python3.12/site-packages/airflow/utils/operator_helpers.py", line 252, in run
    return self.func(*args, **kwargs)
           ^^^^^^^^^^^^^^^^^^^^^^^^^^
  File "/opt/airflow/dags/coleta_dados_abertos_cnpj/jobs/extract.py", line 100, in extract
    for file in files:
                ^^^^^
TypeError: 'NoneType' object is not iterable
[2025-01-19T22:19:13.970+0000] {taskinstance.py:1225} INFO - Marking task as UP_FOR_RETRY. dag_id=coleta_dados_abertos_cnpj, task_id=extract, run_id=scheduled__2022-02-10T00:00:00+00:00, execution_date=20220210T000000, start_date=20250119T221912, end_date=20250119T221913
[2025-01-19T22:19:13.978+0000] {taskinstance.py:340} INFO - ::group::Post task execution logs
[2025-01-19T22:19:13.979+0000] {standard_task_runner.py:124} ERROR - Failed to execute job 125 for task extract ('NoneType' object is not iterable; 414)
Traceback (most recent call last):
  File "/home/airflow/.local/lib/python3.12/site-packages/airflow/task/task_runner/standard_task_runner.py", line 117, in _start_by_fork
    ret = args.func(args, dag=self.dag)
          ^^^^^^^^^^^^^^^^^^^^^^^^^^^^^
  File "/home/airflow/.local/lib/python3.12/site-packages/airflow/cli/cli_config.py", line 49, in command
    return func(*args, **kwargs)
           ^^^^^^^^^^^^^^^^^^^^^
  File "/home/airflow/.local/lib/python3.12/site-packages/airflow/utils/cli.py", line 116, in wrapper
    return f(*args, **kwargs)
           ^^^^^^^^^^^^^^^^^^
  File "/home/airflow/.local/lib/python3.12/site-packages/airflow/cli/commands/task_command.py", line 483, in task_run
    task_return_code = _run_task_by_selected_method(args, _dag, ti)
                       ^^^^^^^^^^^^^^^^^^^^^^^^^^^^^^^^^^^^^^^^^^^^
  File "/home/airflow/.local/lib/python3.12/site-packages/airflow/cli/commands/task_command.py", line 256, in _run_task_by_selected_method
    return _run_raw_task(args, ti)
           ^^^^^^^^^^^^^^^^^^^^^^^
  File "/home/airflow/.local/lib/python3.12/site-packages/airflow/cli/commands/task_command.py", line 341, in _run_raw_task
    return ti._run_raw_task(
           ^^^^^^^^^^^^^^^^^
  File "/home/airflow/.local/lib/python3.12/site-packages/airflow/utils/session.py", line 97, in wrapper
    return func(*args, session=session, **kwargs)
           ^^^^^^^^^^^^^^^^^^^^^^^^^^^^^^^^^^^^^^
  File "/home/airflow/.local/lib/python3.12/site-packages/airflow/models/taskinstance.py", line 3005, in _run_raw_task
    return _run_raw_task(
           ^^^^^^^^^^^^^^
  File "/home/airflow/.local/lib/python3.12/site-packages/airflow/models/taskinstance.py", line 273, in _run_raw_task
    TaskInstance._execute_task_with_callbacks(
  File "/home/airflow/.local/lib/python3.12/site-packages/airflow/models/taskinstance.py", line 3159, in _execute_task_with_callbacks
    result = self._execute_task(context, task_orig)
             ^^^^^^^^^^^^^^^^^^^^^^^^^^^^^^^^^^^^^^
  File "/home/airflow/.local/lib/python3.12/site-packages/airflow/models/taskinstance.py", line 3183, in _execute_task
    return _execute_task(self, context, task_orig)
           ^^^^^^^^^^^^^^^^^^^^^^^^^^^^^^^^^^^^^^^
  File "/home/airflow/.local/lib/python3.12/site-packages/airflow/models/taskinstance.py", line 767, in _execute_task
    result = _execute_callable(context=context, **execute_callable_kwargs)
             ^^^^^^^^^^^^^^^^^^^^^^^^^^^^^^^^^^^^^^^^^^^^^^^^^^^^^^^^^^^^^
  File "/home/airflow/.local/lib/python3.12/site-packages/airflow/models/taskinstance.py", line 733, in _execute_callable
    return ExecutionCallableRunner(
           ^^^^^^^^^^^^^^^^^^^^^^^^
  File "/home/airflow/.local/lib/python3.12/site-packages/airflow/utils/operator_helpers.py", line 252, in run
    return self.func(*args, **kwargs)
           ^^^^^^^^^^^^^^^^^^^^^^^^^^
  File "/home/airflow/.local/lib/python3.12/site-packages/airflow/models/baseoperator.py", line 422, in wrapper
    return func(self, *args, **kwargs)
           ^^^^^^^^^^^^^^^^^^^^^^^^^^^
  File "/home/airflow/.local/lib/python3.12/site-packages/airflow/operators/python.py", line 238, in execute
    return_value = self.execute_callable()
                   ^^^^^^^^^^^^^^^^^^^^^^^
  File "/home/airflow/.local/lib/python3.12/site-packages/airflow/operators/python.py", line 256, in execute_callable
    return runner.run(*self.op_args, **self.op_kwargs)
           ^^^^^^^^^^^^^^^^^^^^^^^^^^^^^^^^^^^^^^^^^^^
  File "/home/airflow/.local/lib/python3.12/site-packages/airflow/utils/operator_helpers.py", line 252, in run
    return self.func(*args, **kwargs)
           ^^^^^^^^^^^^^^^^^^^^^^^^^^
  File "/opt/airflow/dags/coleta_dados_abertos_cnpj/jobs/extract.py", line 100, in extract
    for file in files:
                ^^^^^
TypeError: 'NoneType' object is not iterable
[2025-01-19T22:19:13.996+0000] {local_task_job_runner.py:266} INFO - Task exited with return code 1
[2025-01-19T22:19:14.009+0000] {taskinstance.py:3895} INFO - 0 downstream tasks scheduled from follow-on schedule check
[2025-01-19T22:19:14.011+0000] {local_task_job_runner.py:245} INFO - ::endgroup::
[2025-01-24T19:01:03.838+0000] {local_task_job_runner.py:123} INFO - ::group::Pre task execution logs
[2025-01-24T19:01:03.851+0000] {taskinstance.py:2613} INFO - Dependencies all met for dep_context=non-requeueable deps ti=<TaskInstance: coleta_dados_abertos_cnpj.extract scheduled__2022-02-10T00:00:00+00:00 [queued]>
[2025-01-24T19:01:03.855+0000] {taskinstance.py:2613} INFO - Dependencies all met for dep_context=requeueable deps ti=<TaskInstance: coleta_dados_abertos_cnpj.extract scheduled__2022-02-10T00:00:00+00:00 [queued]>
[2025-01-24T19:01:03.855+0000] {taskinstance.py:2866} INFO - Starting attempt 1 of 2
[2025-01-24T19:01:03.880+0000] {taskinstance.py:2889} INFO - Executing <Task(PythonOperator): extract> on 2022-02-10 00:00:00+00:00
[2025-01-24T19:01:03.884+0000] {warnings.py:112} WARNING - /home/***/.local/lib/python3.12/site-packages/***/task/task_runner/standard_task_runner.py:70: DeprecationWarning: This process (pid=684) is multi-threaded, use of fork() may lead to deadlocks in the child.
  pid = os.fork()

[2025-01-24T19:01:03.885+0000] {standard_task_runner.py:72} INFO - Started process 699 to run task
[2025-01-24T19:01:03.885+0000] {standard_task_runner.py:104} INFO - Running: ['***', 'tasks', 'run', 'coleta_dados_abertos_cnpj', 'extract', 'scheduled__2022-02-10T00:00:00+00:00', '--job-id', '382', '--raw', '--subdir', 'DAGS_FOLDER/coleta_dados_abertos_cnpj/dag.py', '--cfg-path', '/tmp/tmpme1ffog1']
[2025-01-24T19:01:03.886+0000] {standard_task_runner.py:105} INFO - Job 382: Subtask extract
[2025-01-24T19:01:03.915+0000] {task_command.py:467} INFO - Running <TaskInstance: coleta_dados_abertos_cnpj.extract scheduled__2022-02-10T00:00:00+00:00 [running]> on host ee70781c29c7
[2025-01-24T19:01:03.964+0000] {taskinstance.py:3132} INFO - Exporting env vars: AIRFLOW_CTX_DAG_OWNER='Corvaum' AIRFLOW_CTX_DAG_ID='coleta_dados_abertos_cnpj' AIRFLOW_CTX_TASK_ID='extract' AIRFLOW_CTX_EXECUTION_DATE='2022-02-10T00:00:00+00:00' AIRFLOW_CTX_TRY_NUMBER='1' AIRFLOW_CTX_DAG_RUN_ID='scheduled__2022-02-10T00:00:00+00:00'
[2025-01-24T19:01:03.965+0000] {taskinstance.py:731} INFO - ::endgroup::
[2025-01-24T19:01:03.978+0000] {logging_mixin.py:190} INFO - Data formatada: 2022-02
[2025-01-24T19:01:04.106+0000] {logging_mixin.py:190} INFO - Erro ao listar os arquivos: 404 Client Error: Not Found for url: https://arquivos.receitafederal.gov.br/dados/cnpj/dados_abertos_cnpj/2022-02
[2025-01-24T19:01:04.106+0000] {logging_mixin.py:190} INFO - Arquivos encontrados: []
[2025-01-24T19:01:04.107+0000] {python.py:240} INFO - Done. Returned value was: None
[2025-01-24T19:01:04.112+0000] {taskinstance.py:340} INFO - ::group::Post task execution logs
[2025-01-24T19:01:04.113+0000] {taskinstance.py:352} INFO - Marking task as SUCCESS. dag_id=coleta_dados_abertos_cnpj, task_id=extract, run_id=scheduled__2022-02-10T00:00:00+00:00, execution_date=20220210T000000, start_date=20250124T190103, end_date=20250124T190104
[2025-01-24T19:01:04.139+0000] {local_task_job_runner.py:266} INFO - Task exited with return code 0
[2025-01-24T19:01:04.144+0000] {local_task_job_runner.py:245} INFO - ::endgroup::
