[2025-01-18T21:22:35.983+0000] {local_task_job_runner.py:123} INFO - ::group::Pre task execution logs
[2025-01-18T21:22:35.992+0000] {taskinstance.py:2613} INFO - Dependencies all met for dep_context=non-requeueable deps ti=<TaskInstance: coleta_dados_abertos_cnpj.extract scheduled__2024-10-10T00:00:00+00:00 [queued]>
[2025-01-18T21:22:35.997+0000] {taskinstance.py:2613} INFO - Dependencies all met for dep_context=requeueable deps ti=<TaskInstance: coleta_dados_abertos_cnpj.extract scheduled__2024-10-10T00:00:00+00:00 [queued]>
[2025-01-18T21:22:35.997+0000] {taskinstance.py:2866} INFO - Starting attempt 1 of 2
[2025-01-18T21:22:36.026+0000] {taskinstance.py:2889} INFO - Executing <Task(PythonOperator): extract> on 2024-10-10 00:00:00+00:00
[2025-01-18T21:22:36.030+0000] {warnings.py:112} WARNING - /home/***/.local/lib/python3.12/site-packages/***/task/task_runner/standard_task_runner.py:70: DeprecationWarning: This process (pid=345) is multi-threaded, use of fork() may lead to deadlocks in the child.
  pid = os.fork()

[2025-01-18T21:22:36.031+0000] {standard_task_runner.py:72} INFO - Started process 361 to run task
[2025-01-18T21:22:36.031+0000] {standard_task_runner.py:104} INFO - Running: ['***', 'tasks', 'run', 'coleta_dados_abertos_cnpj', 'extract', 'scheduled__2024-10-10T00:00:00+00:00', '--job-id', '128', '--raw', '--subdir', 'DAGS_FOLDER/coleta_dados_abertos_cnpj/dag.py', '--cfg-path', '/tmp/tmpoub1bwhd']
[2025-01-18T21:22:36.033+0000] {standard_task_runner.py:105} INFO - Job 128: Subtask extract
[2025-01-18T21:22:36.059+0000] {task_command.py:467} INFO - Running <TaskInstance: coleta_dados_abertos_cnpj.extract scheduled__2024-10-10T00:00:00+00:00 [running]> on host e9a1739d3128
[2025-01-18T21:22:36.108+0000] {taskinstance.py:3132} INFO - Exporting env vars: AIRFLOW_CTX_DAG_OWNER='Corvaum' AIRFLOW_CTX_DAG_ID='coleta_dados_abertos_cnpj' AIRFLOW_CTX_TASK_ID='extract' AIRFLOW_CTX_EXECUTION_DATE='2024-10-10T00:00:00+00:00' AIRFLOW_CTX_TRY_NUMBER='1' AIRFLOW_CTX_DAG_RUN_ID='scheduled__2024-10-10T00:00:00+00:00'
[2025-01-18T21:22:36.109+0000] {taskinstance.py:731} INFO - ::endgroup::
[2025-01-18T21:22:36.121+0000] {logging_mixin.py:190} INFO - 2024-10
[2025-01-18T21:22:36.297+0000] {logging_mixin.py:190} INFO - Arquivos encontrados no diret√≥rio https://arquivos.receitafederal.gov.br/dados/cnpj/dados_abertos_cnpj/2024-10:
[2025-01-18T21:22:36.298+0000] {logging_mixin.py:190} INFO - ['Cnaes.zip', 'Empresas0.zip', 'Empresas1.zip', 'Empresas2.zip', 'Empresas3.zip', 'Empresas4.zip', 'Empresas5.zip', 'Empresas6.zip', 'Empresas7.zip', 'Empresas8.zip', 'Empresas9.zip', 'Estabelecimentos0.zip', 'Estabelecimentos1.zip', 'Estabelecimentos2.zip', 'Estabelecimentos3.zip', 'Estabelecimentos4.zip', 'Estabelecimentos5.zip', 'Estabelecimentos6.zip', 'Estabelecimentos7.zip', 'Estabelecimentos8.zip', 'Estabelecimentos9.zip', 'Motivos.zip', 'Municipios.zip', 'Naturezas.zip', 'Paises.zip', 'Qualificacoes.zip', 'Simples.zip', 'Socios0.zip', 'Socios1.zip', 'Socios2.zip', 'Socios3.zip', 'Socios4.zip', 'Socios5.zip', 'Socios6.zip', 'Socios7.zip', 'Socios8.zip', 'Socios9.zip']
[2025-01-18T21:22:36.298+0000] {python.py:240} INFO - Done. Returned value was: None
[2025-01-18T21:22:36.303+0000] {taskinstance.py:340} INFO - ::group::Post task execution logs
[2025-01-18T21:22:36.304+0000] {taskinstance.py:352} INFO - Marking task as SUCCESS. dag_id=coleta_dados_abertos_cnpj, task_id=extract, run_id=scheduled__2024-10-10T00:00:00+00:00, execution_date=20241010T000000, start_date=20250118T212235, end_date=20250118T212236
[2025-01-18T21:22:36.325+0000] {local_task_job_runner.py:266} INFO - Task exited with return code 0
[2025-01-18T21:22:36.333+0000] {taskinstance.py:3895} INFO - 0 downstream tasks scheduled from follow-on schedule check
[2025-01-18T21:22:36.335+0000] {local_task_job_runner.py:245} INFO - ::endgroup::
[2025-01-19T20:07:01.091+0000] {local_task_job_runner.py:123} INFO - ::group::Pre task execution logs
[2025-01-19T20:07:01.100+0000] {taskinstance.py:2613} INFO - Dependencies all met for dep_context=non-requeueable deps ti=<TaskInstance: coleta_dados_abertos_cnpj.extract scheduled__2024-10-10T00:00:00+00:00 [queued]>
[2025-01-19T20:07:01.108+0000] {taskinstance.py:2613} INFO - Dependencies all met for dep_context=requeueable deps ti=<TaskInstance: coleta_dados_abertos_cnpj.extract scheduled__2024-10-10T00:00:00+00:00 [queued]>
[2025-01-19T20:07:01.111+0000] {taskinstance.py:2866} INFO - Starting attempt 1 of 2
[2025-01-19T20:07:01.120+0000] {taskinstance.py:2889} INFO - Executing <Task(PythonOperator): extract> on 2024-10-10 00:00:00+00:00
[2025-01-19T20:07:01.124+0000] {warnings.py:112} WARNING - /home/***/.local/lib/python3.12/site-packages/***/task/task_runner/standard_task_runner.py:70: DeprecationWarning: This process (pid=353) is multi-threaded, use of fork() may lead to deadlocks in the child.
  pid = os.fork()

[2025-01-19T20:07:01.125+0000] {standard_task_runner.py:72} INFO - Started process 358 to run task
[2025-01-19T20:07:01.125+0000] {standard_task_runner.py:104} INFO - Running: ['***', 'tasks', 'run', 'coleta_dados_abertos_cnpj', 'extract', 'scheduled__2024-10-10T00:00:00+00:00', '--job-id', '89', '--raw', '--subdir', 'DAGS_FOLDER/coleta_dados_abertos_cnpj/dag.py', '--cfg-path', '/tmp/tmpqb8nryhq']
[2025-01-19T20:07:01.127+0000] {standard_task_runner.py:105} INFO - Job 89: Subtask extract
[2025-01-19T20:07:01.154+0000] {task_command.py:467} INFO - Running <TaskInstance: coleta_dados_abertos_cnpj.extract scheduled__2024-10-10T00:00:00+00:00 [running]> on host 659dab735c6e
[2025-01-19T20:07:01.201+0000] {taskinstance.py:3132} INFO - Exporting env vars: AIRFLOW_CTX_DAG_OWNER='Corvaum' AIRFLOW_CTX_DAG_ID='coleta_dados_abertos_cnpj' AIRFLOW_CTX_TASK_ID='extract' AIRFLOW_CTX_EXECUTION_DATE='2024-10-10T00:00:00+00:00' AIRFLOW_CTX_TRY_NUMBER='1' AIRFLOW_CTX_DAG_RUN_ID='scheduled__2024-10-10T00:00:00+00:00'
[2025-01-19T20:07:01.202+0000] {taskinstance.py:731} INFO - ::endgroup::
[2025-01-19T20:07:01.216+0000] {logging_mixin.py:190} INFO - 2024-10
[2025-01-19T20:07:01.438+0000] {logging_mixin.py:190} INFO - -----------------
[2025-01-19T20:07:01.438+0000] {logging_mixin.py:190} INFO - ['Cnaes.zip']
[2025-01-19T20:07:01.438+0000] {logging_mixin.py:190} INFO - ['Cnaes']
[2025-01-19T20:07:01.611+0000] {logging_mixin.py:190} INFO - Arquivo salvo em: G:/Airlfow/volumes/dados_abertos_cnpj/2024-10/Cnaes/Cnaes.zip
[2025-01-19T20:07:01.611+0000] {logging_mixin.py:190} INFO - None
[2025-01-19T20:07:01.612+0000] {logging_mixin.py:190} INFO - ['Cnaes.zip']
[2025-01-19T20:07:01.612+0000] {python.py:240} INFO - Done. Returned value was: None
[2025-01-19T20:07:01.617+0000] {taskinstance.py:340} INFO - ::group::Post task execution logs
[2025-01-19T20:07:01.618+0000] {taskinstance.py:352} INFO - Marking task as SUCCESS. dag_id=coleta_dados_abertos_cnpj, task_id=extract, run_id=scheduled__2024-10-10T00:00:00+00:00, execution_date=20241010T000000, start_date=20250119T200701, end_date=20250119T200701
[2025-01-19T20:07:01.660+0000] {local_task_job_runner.py:266} INFO - Task exited with return code 0
[2025-01-19T20:07:01.673+0000] {taskinstance.py:3895} INFO - 1 downstream tasks scheduled from follow-on schedule check
[2025-01-19T20:07:01.676+0000] {local_task_job_runner.py:245} INFO - ::endgroup::
[2025-01-23T01:23:08.738+0000] {local_task_job_runner.py:123} INFO - ::group::Pre task execution logs
[2025-01-23T01:23:08.750+0000] {taskinstance.py:2613} INFO - Dependencies all met for dep_context=non-requeueable deps ti=<TaskInstance: coleta_dados_abertos_cnpj.extract scheduled__2024-10-10T00:00:00+00:00 [queued]>
[2025-01-23T01:23:08.756+0000] {taskinstance.py:2613} INFO - Dependencies all met for dep_context=requeueable deps ti=<TaskInstance: coleta_dados_abertos_cnpj.extract scheduled__2024-10-10T00:00:00+00:00 [queued]>
[2025-01-23T01:23:08.756+0000] {taskinstance.py:2866} INFO - Starting attempt 1 of 2
[2025-01-23T01:23:08.770+0000] {taskinstance.py:2889} INFO - Executing <Task(PythonOperator): extract> on 2024-10-10 00:00:00+00:00
[2025-01-23T01:23:08.774+0000] {warnings.py:112} WARNING - /home/***/.local/lib/python3.12/site-packages/***/task/task_runner/standard_task_runner.py:70: DeprecationWarning: This process (pid=112) is multi-threaded, use of fork() may lead to deadlocks in the child.
  pid = os.fork()

[2025-01-23T01:23:08.775+0000] {standard_task_runner.py:72} INFO - Started process 119 to run task
[2025-01-23T01:23:08.775+0000] {standard_task_runner.py:104} INFO - Running: ['***', 'tasks', 'run', 'coleta_dados_abertos_cnpj', 'extract', 'scheduled__2024-10-10T00:00:00+00:00', '--job-id', '197', '--raw', '--subdir', 'DAGS_FOLDER/coleta_dados_abertos_cnpj/dag.py', '--cfg-path', '/tmp/tmpwa3e0o3i']
[2025-01-23T01:23:08.777+0000] {standard_task_runner.py:105} INFO - Job 197: Subtask extract
[2025-01-23T01:23:08.810+0000] {task_command.py:467} INFO - Running <TaskInstance: coleta_dados_abertos_cnpj.extract scheduled__2024-10-10T00:00:00+00:00 [running]> on host 659dab735c6e
[2025-01-23T01:23:08.881+0000] {taskinstance.py:3132} INFO - Exporting env vars: AIRFLOW_CTX_DAG_OWNER='Corvaum' AIRFLOW_CTX_DAG_ID='coleta_dados_abertos_cnpj' AIRFLOW_CTX_TASK_ID='extract' AIRFLOW_CTX_EXECUTION_DATE='2024-10-10T00:00:00+00:00' AIRFLOW_CTX_TRY_NUMBER='1' AIRFLOW_CTX_DAG_RUN_ID='scheduled__2024-10-10T00:00:00+00:00'
[2025-01-23T01:23:08.881+0000] {taskinstance.py:731} INFO - ::endgroup::
[2025-01-23T01:23:08.902+0000] {logging_mixin.py:190} INFO - 2024-10
[2025-01-23T01:23:09.170+0000] {logging_mixin.py:190} INFO - -----------------
[2025-01-23T01:23:09.171+0000] {logging_mixin.py:190} INFO - ['Cnaes.zip', 'Empresas0.zip', 'Empresas1.zip', 'Empresas2.zip', 'Empresas3.zip', 'Empresas4.zip', 'Empresas5.zip', 'Empresas6.zip', 'Empresas7.zip', 'Empresas8.zip', 'Empresas9.zip', 'Estabelecimentos0.zip', 'Estabelecimentos1.zip', 'Estabelecimentos2.zip', 'Estabelecimentos3.zip', 'Estabelecimentos4.zip', 'Estabelecimentos5.zip', 'Estabelecimentos6.zip', 'Estabelecimentos7.zip', 'Estabelecimentos8.zip', 'Estabelecimentos9.zip', 'Motivos.zip', 'Municipios.zip', 'Naturezas.zip', 'Paises.zip', 'Qualificacoes.zip', 'Simples.zip', 'Socios0.zip', 'Socios1.zip', 'Socios2.zip', 'Socios3.zip', 'Socios4.zip', 'Socios5.zip', 'Socios6.zip', 'Socios7.zip', 'Socios8.zip', 'Socios9.zip']
[2025-01-23T01:23:09.171+0000] {logging_mixin.py:190} INFO - ['Cnaes', 'Empresas', 'Estabelecimentos', 'Motivos', 'Municipios', 'Naturezas', 'Paises', 'Qualificacoes', 'Simples', 'Socios']
[2025-01-23T01:23:09.171+0000] {logging_mixin.py:190} INFO - Iniciando o download de: https://arquivos.receitafederal.gov.br/dados/cnpj/dados_abertos_cnpj/2024-10/Cnaes.zip
[2025-01-23T01:23:09.328+0000] {logging_mixin.py:190} INFO - Arquivo salvo em: G:/Airflow/volumes/dados_abertos_cnpj/2024-10/Cnaes/Cnaes.zip
[2025-01-23T01:23:09.329+0000] {logging_mixin.py:190} INFO - Iniciando o download de: https://arquivos.receitafederal.gov.br/dados/cnpj/dados_abertos_cnpj/2024-10/Empresas0.zip
[2025-01-23T01:25:55.341+0000] {taskinstance.py:3311} ERROR - Task failed with exception
Traceback (most recent call last):
  File "/home/airflow/.local/lib/python3.12/site-packages/urllib3/response.py", line 748, in _error_catcher
    yield
  File "/home/airflow/.local/lib/python3.12/site-packages/urllib3/response.py", line 894, in _raw_read
    raise IncompleteRead(self._fp_bytes_read, self.length_remaining)
urllib3.exceptions.IncompleteRead: IncompleteRead(2560289 bytes read, 374456154 more expected)

The above exception was the direct cause of the following exception:

Traceback (most recent call last):
  File "/home/airflow/.local/lib/python3.12/site-packages/requests/models.py", line 820, in generate
    yield from self.raw.stream(chunk_size, decode_content=True)
  File "/home/airflow/.local/lib/python3.12/site-packages/urllib3/response.py", line 1060, in stream
    data = self.read(amt=amt, decode_content=decode_content)
           ^^^^^^^^^^^^^^^^^^^^^^^^^^^^^^^^^^^^^^^^^^^^^^^^^
  File "/home/airflow/.local/lib/python3.12/site-packages/urllib3/response.py", line 977, in read
    data = self._raw_read(amt)
           ^^^^^^^^^^^^^^^^^^^
  File "/home/airflow/.local/lib/python3.12/site-packages/urllib3/response.py", line 872, in _raw_read
    with self._error_catcher():
         ^^^^^^^^^^^^^^^^^^^^^
  File "/usr/local/lib/python3.12/contextlib.py", line 158, in __exit__
    self.gen.throw(value)
  File "/home/airflow/.local/lib/python3.12/site-packages/urllib3/response.py", line 772, in _error_catcher
    raise ProtocolError(arg, e) from e
urllib3.exceptions.ProtocolError: ('Connection broken: IncompleteRead(2560289 bytes read, 374456154 more expected)', IncompleteRead(2560289 bytes read, 374456154 more expected))

During handling of the above exception, another exception occurred:

Traceback (most recent call last):
  File "/home/airflow/.local/lib/python3.12/site-packages/airflow/models/taskinstance.py", line 767, in _execute_task
    result = _execute_callable(context=context, **execute_callable_kwargs)
             ^^^^^^^^^^^^^^^^^^^^^^^^^^^^^^^^^^^^^^^^^^^^^^^^^^^^^^^^^^^^^
  File "/home/airflow/.local/lib/python3.12/site-packages/airflow/models/taskinstance.py", line 733, in _execute_callable
    return ExecutionCallableRunner(
           ^^^^^^^^^^^^^^^^^^^^^^^^
  File "/home/airflow/.local/lib/python3.12/site-packages/airflow/utils/operator_helpers.py", line 252, in run
    return self.func(*args, **kwargs)
           ^^^^^^^^^^^^^^^^^^^^^^^^^^
  File "/home/airflow/.local/lib/python3.12/site-packages/airflow/models/baseoperator.py", line 422, in wrapper
    return func(self, *args, **kwargs)
           ^^^^^^^^^^^^^^^^^^^^^^^^^^^
  File "/home/airflow/.local/lib/python3.12/site-packages/airflow/operators/python.py", line 238, in execute
    return_value = self.execute_callable()
                   ^^^^^^^^^^^^^^^^^^^^^^^
  File "/home/airflow/.local/lib/python3.12/site-packages/airflow/operators/python.py", line 256, in execute_callable
    return runner.run(*self.op_args, **self.op_kwargs)
           ^^^^^^^^^^^^^^^^^^^^^^^^^^^^^^^^^^^^^^^^^^^
  File "/home/airflow/.local/lib/python3.12/site-packages/airflow/utils/operator_helpers.py", line 252, in run
    return self.func(*args, **kwargs)
           ^^^^^^^^^^^^^^^^^^^^^^^^^^
  File "/opt/airflow/dags/coleta_dados_abertos_cnpj/jobs/extract.py", line 105, in extract
    file_path = download_with_requests(
                ^^^^^^^^^^^^^^^^^^^^^^^
  File "/opt/airflow/dags/coleta_dados_abertos_cnpj/jobs/extract.py", line 68, in download_with_requests
    for chunk in r.iter_content(chunk_size=8192):
                 ^^^^^^^^^^^^^^^^^^^^^^^^^^^^^^^
  File "/home/airflow/.local/lib/python3.12/site-packages/requests/models.py", line 822, in generate
    raise ChunkedEncodingError(e)
requests.exceptions.ChunkedEncodingError: ('Connection broken: IncompleteRead(2560289 bytes read, 374456154 more expected)', IncompleteRead(2560289 bytes read, 374456154 more expected))
[2025-01-23T01:25:55.359+0000] {taskinstance.py:1225} INFO - Marking task as UP_FOR_RETRY. dag_id=coleta_dados_abertos_cnpj, task_id=extract, run_id=scheduled__2024-10-10T00:00:00+00:00, execution_date=20241010T000000, start_date=20250123T012308, end_date=20250123T012555
[2025-01-23T01:25:55.371+0000] {taskinstance.py:340} INFO - ::group::Post task execution logs
[2025-01-23T01:25:55.373+0000] {standard_task_runner.py:124} ERROR - Failed to execute job 197 for task extract (('Connection broken: IncompleteRead(2560289 bytes read, 374456154 more expected)', IncompleteRead(2560289 bytes read, 374456154 more expected)); 119)
Traceback (most recent call last):
  File "/home/airflow/.local/lib/python3.12/site-packages/urllib3/response.py", line 748, in _error_catcher
    yield
  File "/home/airflow/.local/lib/python3.12/site-packages/urllib3/response.py", line 894, in _raw_read
    raise IncompleteRead(self._fp_bytes_read, self.length_remaining)
urllib3.exceptions.IncompleteRead: IncompleteRead(2560289 bytes read, 374456154 more expected)

The above exception was the direct cause of the following exception:

Traceback (most recent call last):
  File "/home/airflow/.local/lib/python3.12/site-packages/requests/models.py", line 820, in generate
    yield from self.raw.stream(chunk_size, decode_content=True)
  File "/home/airflow/.local/lib/python3.12/site-packages/urllib3/response.py", line 1060, in stream
    data = self.read(amt=amt, decode_content=decode_content)
           ^^^^^^^^^^^^^^^^^^^^^^^^^^^^^^^^^^^^^^^^^^^^^^^^^
  File "/home/airflow/.local/lib/python3.12/site-packages/urllib3/response.py", line 977, in read
    data = self._raw_read(amt)
           ^^^^^^^^^^^^^^^^^^^
  File "/home/airflow/.local/lib/python3.12/site-packages/urllib3/response.py", line 872, in _raw_read
    with self._error_catcher():
         ^^^^^^^^^^^^^^^^^^^^^
  File "/usr/local/lib/python3.12/contextlib.py", line 158, in __exit__
    self.gen.throw(value)
  File "/home/airflow/.local/lib/python3.12/site-packages/urllib3/response.py", line 772, in _error_catcher
    raise ProtocolError(arg, e) from e
urllib3.exceptions.ProtocolError: ('Connection broken: IncompleteRead(2560289 bytes read, 374456154 more expected)', IncompleteRead(2560289 bytes read, 374456154 more expected))

During handling of the above exception, another exception occurred:

Traceback (most recent call last):
  File "/home/airflow/.local/lib/python3.12/site-packages/airflow/task/task_runner/standard_task_runner.py", line 117, in _start_by_fork
    ret = args.func(args, dag=self.dag)
          ^^^^^^^^^^^^^^^^^^^^^^^^^^^^^
  File "/home/airflow/.local/lib/python3.12/site-packages/airflow/cli/cli_config.py", line 49, in command
    return func(*args, **kwargs)
           ^^^^^^^^^^^^^^^^^^^^^
  File "/home/airflow/.local/lib/python3.12/site-packages/airflow/utils/cli.py", line 116, in wrapper
    return f(*args, **kwargs)
           ^^^^^^^^^^^^^^^^^^
  File "/home/airflow/.local/lib/python3.12/site-packages/airflow/cli/commands/task_command.py", line 483, in task_run
    task_return_code = _run_task_by_selected_method(args, _dag, ti)
                       ^^^^^^^^^^^^^^^^^^^^^^^^^^^^^^^^^^^^^^^^^^^^
  File "/home/airflow/.local/lib/python3.12/site-packages/airflow/cli/commands/task_command.py", line 256, in _run_task_by_selected_method
    return _run_raw_task(args, ti)
           ^^^^^^^^^^^^^^^^^^^^^^^
  File "/home/airflow/.local/lib/python3.12/site-packages/airflow/cli/commands/task_command.py", line 341, in _run_raw_task
    return ti._run_raw_task(
           ^^^^^^^^^^^^^^^^^
  File "/home/airflow/.local/lib/python3.12/site-packages/airflow/utils/session.py", line 97, in wrapper
    return func(*args, session=session, **kwargs)
           ^^^^^^^^^^^^^^^^^^^^^^^^^^^^^^^^^^^^^^
  File "/home/airflow/.local/lib/python3.12/site-packages/airflow/models/taskinstance.py", line 3005, in _run_raw_task
    return _run_raw_task(
           ^^^^^^^^^^^^^^
  File "/home/airflow/.local/lib/python3.12/site-packages/airflow/models/taskinstance.py", line 273, in _run_raw_task
    TaskInstance._execute_task_with_callbacks(
  File "/home/airflow/.local/lib/python3.12/site-packages/airflow/models/taskinstance.py", line 3159, in _execute_task_with_callbacks
    result = self._execute_task(context, task_orig)
             ^^^^^^^^^^^^^^^^^^^^^^^^^^^^^^^^^^^^^^
  File "/home/airflow/.local/lib/python3.12/site-packages/airflow/models/taskinstance.py", line 3183, in _execute_task
    return _execute_task(self, context, task_orig)
           ^^^^^^^^^^^^^^^^^^^^^^^^^^^^^^^^^^^^^^^
  File "/home/airflow/.local/lib/python3.12/site-packages/airflow/models/taskinstance.py", line 767, in _execute_task
    result = _execute_callable(context=context, **execute_callable_kwargs)
             ^^^^^^^^^^^^^^^^^^^^^^^^^^^^^^^^^^^^^^^^^^^^^^^^^^^^^^^^^^^^^
  File "/home/airflow/.local/lib/python3.12/site-packages/airflow/models/taskinstance.py", line 733, in _execute_callable
    return ExecutionCallableRunner(
           ^^^^^^^^^^^^^^^^^^^^^^^^
  File "/home/airflow/.local/lib/python3.12/site-packages/airflow/utils/operator_helpers.py", line 252, in run
    return self.func(*args, **kwargs)
           ^^^^^^^^^^^^^^^^^^^^^^^^^^
  File "/home/airflow/.local/lib/python3.12/site-packages/airflow/models/baseoperator.py", line 422, in wrapper
    return func(self, *args, **kwargs)
           ^^^^^^^^^^^^^^^^^^^^^^^^^^^
  File "/home/airflow/.local/lib/python3.12/site-packages/airflow/operators/python.py", line 238, in execute
    return_value = self.execute_callable()
                   ^^^^^^^^^^^^^^^^^^^^^^^
  File "/home/airflow/.local/lib/python3.12/site-packages/airflow/operators/python.py", line 256, in execute_callable
    return runner.run(*self.op_args, **self.op_kwargs)
           ^^^^^^^^^^^^^^^^^^^^^^^^^^^^^^^^^^^^^^^^^^^
  File "/home/airflow/.local/lib/python3.12/site-packages/airflow/utils/operator_helpers.py", line 252, in run
    return self.func(*args, **kwargs)
           ^^^^^^^^^^^^^^^^^^^^^^^^^^
  File "/opt/airflow/dags/coleta_dados_abertos_cnpj/jobs/extract.py", line 105, in extract
    file_path = download_with_requests(
                ^^^^^^^^^^^^^^^^^^^^^^^
  File "/opt/airflow/dags/coleta_dados_abertos_cnpj/jobs/extract.py", line 68, in download_with_requests
    for chunk in r.iter_content(chunk_size=8192):
                 ^^^^^^^^^^^^^^^^^^^^^^^^^^^^^^^
  File "/home/airflow/.local/lib/python3.12/site-packages/requests/models.py", line 822, in generate
    raise ChunkedEncodingError(e)
requests.exceptions.ChunkedEncodingError: ('Connection broken: IncompleteRead(2560289 bytes read, 374456154 more expected)', IncompleteRead(2560289 bytes read, 374456154 more expected))
[2025-01-23T01:25:55.401+0000] {local_task_job_runner.py:266} INFO - Task exited with return code 1
[2025-01-23T01:25:55.414+0000] {taskinstance.py:3895} INFO - 0 downstream tasks scheduled from follow-on schedule check
[2025-01-23T01:25:55.416+0000] {local_task_job_runner.py:245} INFO - ::endgroup::
[2025-01-24T19:01:51.526+0000] {local_task_job_runner.py:123} INFO - ::group::Pre task execution logs
[2025-01-24T19:01:51.534+0000] {taskinstance.py:2613} INFO - Dependencies all met for dep_context=non-requeueable deps ti=<TaskInstance: coleta_dados_abertos_cnpj.extract scheduled__2024-10-10T00:00:00+00:00 [queued]>
[2025-01-24T19:01:51.538+0000] {taskinstance.py:2613} INFO - Dependencies all met for dep_context=requeueable deps ti=<TaskInstance: coleta_dados_abertos_cnpj.extract scheduled__2024-10-10T00:00:00+00:00 [queued]>
[2025-01-24T19:01:51.538+0000] {taskinstance.py:2866} INFO - Starting attempt 1 of 2
[2025-01-24T19:01:51.547+0000] {taskinstance.py:2889} INFO - Executing <Task(PythonOperator): extract> on 2024-10-10 00:00:00+00:00
[2025-01-24T19:01:51.551+0000] {warnings.py:112} WARNING - /home/***/.local/lib/python3.12/site-packages/***/task/task_runner/standard_task_runner.py:70: DeprecationWarning: This process (pid=1386) is multi-threaded, use of fork() may lead to deadlocks in the child.
  pid = os.fork()

[2025-01-24T19:01:51.553+0000] {standard_task_runner.py:72} INFO - Started process 1391 to run task
[2025-01-24T19:01:51.552+0000] {standard_task_runner.py:104} INFO - Running: ['***', 'tasks', 'run', 'coleta_dados_abertos_cnpj', 'extract', 'scheduled__2024-10-10T00:00:00+00:00', '--job-id', '606', '--raw', '--subdir', 'DAGS_FOLDER/coleta_dados_abertos_cnpj/dag.py', '--cfg-path', '/tmp/tmpxmw0q4__']
[2025-01-24T19:01:51.553+0000] {standard_task_runner.py:105} INFO - Job 606: Subtask extract
[2025-01-24T19:01:51.578+0000] {task_command.py:467} INFO - Running <TaskInstance: coleta_dados_abertos_cnpj.extract scheduled__2024-10-10T00:00:00+00:00 [running]> on host ee70781c29c7
[2025-01-24T19:01:51.623+0000] {taskinstance.py:3132} INFO - Exporting env vars: AIRFLOW_CTX_DAG_OWNER='Corvaum' AIRFLOW_CTX_DAG_ID='coleta_dados_abertos_cnpj' AIRFLOW_CTX_TASK_ID='extract' AIRFLOW_CTX_EXECUTION_DATE='2024-10-10T00:00:00+00:00' AIRFLOW_CTX_TRY_NUMBER='1' AIRFLOW_CTX_DAG_RUN_ID='scheduled__2024-10-10T00:00:00+00:00'
[2025-01-24T19:01:51.624+0000] {taskinstance.py:731} INFO - ::endgroup::
[2025-01-24T19:01:51.635+0000] {logging_mixin.py:190} INFO - Data formatada: 2024-10
[2025-01-24T19:01:51.846+0000] {logging_mixin.py:190} INFO - Arquivos encontrados: ['Cnaes.zip', 'Empresas0.zip', 'Empresas1.zip', 'Empresas2.zip', 'Empresas3.zip', 'Empresas4.zip', 'Empresas5.zip', 'Empresas6.zip', 'Empresas7.zip', 'Empresas8.zip', 'Empresas9.zip', 'Estabelecimentos0.zip', 'Estabelecimentos1.zip', 'Estabelecimentos2.zip', 'Estabelecimentos3.zip', 'Estabelecimentos4.zip', 'Estabelecimentos5.zip', 'Estabelecimentos6.zip', 'Estabelecimentos7.zip', 'Estabelecimentos8.zip', 'Estabelecimentos9.zip', 'Motivos.zip', 'Municipios.zip', 'Naturezas.zip', 'Paises.zip', 'Qualificacoes.zip', 'Simples.zip', 'Socios0.zip', 'Socios1.zip', 'Socios2.zip', 'Socios3.zip', 'Socios4.zip', 'Socios5.zip', 'Socios6.zip', 'Socios7.zip', 'Socios8.zip', 'Socios9.zip']
[2025-01-24T19:01:51.847+0000] {logging_mixin.py:190} INFO - Baixando o arquivo: https://arquivos.receitafederal.gov.br/dados/cnpj/dados_abertos_cnpj/2024-10/Cnaes.zip
[2025-01-24T19:01:52.000+0000] {logging_mixin.py:190} INFO - Download conclu√≠do: https://arquivos.receitafederal.gov.br/dados/cnpj/dados_abertos_cnpj/2024-10/Cnaes.zip
[2025-01-24T19:01:52.003+0000] {logging_mixin.py:190} INFO - Arquivos descompactados: ['/tmp/8079ee411aad46e8aa700fa2f75be2fe_extracted/F.K03200$Z.D41012.CNAECSV']
[2025-01-24T19:01:52.007+0000] {taskinstance.py:3311} ERROR - Task failed with exception
Traceback (most recent call last):
  File "/home/airflow/.local/lib/python3.12/site-packages/airflow/models/taskinstance.py", line 767, in _execute_task
    result = _execute_callable(context=context, **execute_callable_kwargs)
             ^^^^^^^^^^^^^^^^^^^^^^^^^^^^^^^^^^^^^^^^^^^^^^^^^^^^^^^^^^^^^
  File "/home/airflow/.local/lib/python3.12/site-packages/airflow/models/taskinstance.py", line 733, in _execute_callable
    return ExecutionCallableRunner(
           ^^^^^^^^^^^^^^^^^^^^^^^^
  File "/home/airflow/.local/lib/python3.12/site-packages/airflow/utils/operator_helpers.py", line 252, in run
    return self.func(*args, **kwargs)
           ^^^^^^^^^^^^^^^^^^^^^^^^^^
  File "/home/airflow/.local/lib/python3.12/site-packages/airflow/models/baseoperator.py", line 422, in wrapper
    return func(self, *args, **kwargs)
           ^^^^^^^^^^^^^^^^^^^^^^^^^^^
  File "/home/airflow/.local/lib/python3.12/site-packages/airflow/operators/python.py", line 238, in execute
    return_value = self.execute_callable()
                   ^^^^^^^^^^^^^^^^^^^^^^^
  File "/home/airflow/.local/lib/python3.12/site-packages/airflow/operators/python.py", line 256, in execute_callable
    return runner.run(*self.op_args, **self.op_kwargs)
           ^^^^^^^^^^^^^^^^^^^^^^^^^^^^^^^^^^^^^^^^^^^
  File "/home/airflow/.local/lib/python3.12/site-packages/airflow/utils/operator_helpers.py", line 252, in run
    return self.func(*args, **kwargs)
           ^^^^^^^^^^^^^^^^^^^^^^^^^^
  File "/opt/airflow/dags/coleta_dados_abertos_cnpj/jobs/extract.py", line 134, in extract
    upload_to_bucket(
  File "/opt/airflow/dags/coleta_dados_abertos_cnpj/jobs/extract.py", line 100, in upload_to_bucket
    client.put_object(
  File "/home/airflow/.local/lib/python3.12/site-packages/minio/api.py", line 1996, in put_object
    raise exc
  File "/home/airflow/.local/lib/python3.12/site-packages/minio/api.py", line 1942, in put_object
    return self._put_object(
           ^^^^^^^^^^^^^^^^^
  File "/home/airflow/.local/lib/python3.12/site-packages/minio/api.py", line 1781, in _put_object
    response = self._execute(
               ^^^^^^^^^^^^^^
  File "/home/airflow/.local/lib/python3.12/site-packages/minio/api.py", line 438, in _execute
    region = self._get_region(bucket_name)
             ^^^^^^^^^^^^^^^^^^^^^^^^^^^^^
  File "/home/airflow/.local/lib/python3.12/site-packages/minio/api.py", line 495, in _get_region
    response = self._url_open(
               ^^^^^^^^^^^^^^^
  File "/home/airflow/.local/lib/python3.12/site-packages/minio/api.py", line 424, in _url_open
    raise response_error
minio.error.S3Error: S3 operation failed; code: NoSuchBucket, message: The specified bucket does not exist, resource: /raw, request_id: 181DB627803DE2FD, host_id: dd9025bab4ad464b049177c95eb6ebf374d3b3fd1af9251148b658df7ac2e3e8, bucket_name: raw
[2025-01-24T19:01:52.016+0000] {taskinstance.py:1225} INFO - Marking task as UP_FOR_RETRY. dag_id=coleta_dados_abertos_cnpj, task_id=extract, run_id=scheduled__2024-10-10T00:00:00+00:00, execution_date=20241010T000000, start_date=20250124T190151, end_date=20250124T190152
[2025-01-24T19:01:52.024+0000] {taskinstance.py:340} INFO - ::group::Post task execution logs
[2025-01-24T19:01:52.024+0000] {standard_task_runner.py:124} ERROR - Failed to execute job 606 for task extract (S3 operation failed; code: NoSuchBucket, message: The specified bucket does not exist, resource: /raw, request_id: 181DB627803DE2FD, host_id: dd9025bab4ad464b049177c95eb6ebf374d3b3fd1af9251148b658df7ac2e3e8, bucket_name: raw; 1391)
Traceback (most recent call last):
  File "/home/airflow/.local/lib/python3.12/site-packages/airflow/task/task_runner/standard_task_runner.py", line 117, in _start_by_fork
    ret = args.func(args, dag=self.dag)
          ^^^^^^^^^^^^^^^^^^^^^^^^^^^^^
  File "/home/airflow/.local/lib/python3.12/site-packages/airflow/cli/cli_config.py", line 49, in command
    return func(*args, **kwargs)
           ^^^^^^^^^^^^^^^^^^^^^
  File "/home/airflow/.local/lib/python3.12/site-packages/airflow/utils/cli.py", line 116, in wrapper
    return f(*args, **kwargs)
           ^^^^^^^^^^^^^^^^^^
  File "/home/airflow/.local/lib/python3.12/site-packages/airflow/cli/commands/task_command.py", line 483, in task_run
    task_return_code = _run_task_by_selected_method(args, _dag, ti)
                       ^^^^^^^^^^^^^^^^^^^^^^^^^^^^^^^^^^^^^^^^^^^^
  File "/home/airflow/.local/lib/python3.12/site-packages/airflow/cli/commands/task_command.py", line 256, in _run_task_by_selected_method
    return _run_raw_task(args, ti)
           ^^^^^^^^^^^^^^^^^^^^^^^
  File "/home/airflow/.local/lib/python3.12/site-packages/airflow/cli/commands/task_command.py", line 341, in _run_raw_task
    return ti._run_raw_task(
           ^^^^^^^^^^^^^^^^^
  File "/home/airflow/.local/lib/python3.12/site-packages/airflow/utils/session.py", line 97, in wrapper
    return func(*args, session=session, **kwargs)
           ^^^^^^^^^^^^^^^^^^^^^^^^^^^^^^^^^^^^^^
  File "/home/airflow/.local/lib/python3.12/site-packages/airflow/models/taskinstance.py", line 3005, in _run_raw_task
    return _run_raw_task(
           ^^^^^^^^^^^^^^
  File "/home/airflow/.local/lib/python3.12/site-packages/airflow/models/taskinstance.py", line 273, in _run_raw_task
    TaskInstance._execute_task_with_callbacks(
  File "/home/airflow/.local/lib/python3.12/site-packages/airflow/models/taskinstance.py", line 3159, in _execute_task_with_callbacks
    result = self._execute_task(context, task_orig)
             ^^^^^^^^^^^^^^^^^^^^^^^^^^^^^^^^^^^^^^
  File "/home/airflow/.local/lib/python3.12/site-packages/airflow/models/taskinstance.py", line 3183, in _execute_task
    return _execute_task(self, context, task_orig)
           ^^^^^^^^^^^^^^^^^^^^^^^^^^^^^^^^^^^^^^^
  File "/home/airflow/.local/lib/python3.12/site-packages/airflow/models/taskinstance.py", line 767, in _execute_task
    result = _execute_callable(context=context, **execute_callable_kwargs)
             ^^^^^^^^^^^^^^^^^^^^^^^^^^^^^^^^^^^^^^^^^^^^^^^^^^^^^^^^^^^^^
  File "/home/airflow/.local/lib/python3.12/site-packages/airflow/models/taskinstance.py", line 733, in _execute_callable
    return ExecutionCallableRunner(
           ^^^^^^^^^^^^^^^^^^^^^^^^
  File "/home/airflow/.local/lib/python3.12/site-packages/airflow/utils/operator_helpers.py", line 252, in run
    return self.func(*args, **kwargs)
           ^^^^^^^^^^^^^^^^^^^^^^^^^^
  File "/home/airflow/.local/lib/python3.12/site-packages/airflow/models/baseoperator.py", line 422, in wrapper
    return func(self, *args, **kwargs)
           ^^^^^^^^^^^^^^^^^^^^^^^^^^^
  File "/home/airflow/.local/lib/python3.12/site-packages/airflow/operators/python.py", line 238, in execute
    return_value = self.execute_callable()
                   ^^^^^^^^^^^^^^^^^^^^^^^
  File "/home/airflow/.local/lib/python3.12/site-packages/airflow/operators/python.py", line 256, in execute_callable
    return runner.run(*self.op_args, **self.op_kwargs)
           ^^^^^^^^^^^^^^^^^^^^^^^^^^^^^^^^^^^^^^^^^^^
  File "/home/airflow/.local/lib/python3.12/site-packages/airflow/utils/operator_helpers.py", line 252, in run
    return self.func(*args, **kwargs)
           ^^^^^^^^^^^^^^^^^^^^^^^^^^
  File "/opt/airflow/dags/coleta_dados_abertos_cnpj/jobs/extract.py", line 134, in extract
    upload_to_bucket(
  File "/opt/airflow/dags/coleta_dados_abertos_cnpj/jobs/extract.py", line 100, in upload_to_bucket
    client.put_object(
  File "/home/airflow/.local/lib/python3.12/site-packages/minio/api.py", line 1996, in put_object
    raise exc
  File "/home/airflow/.local/lib/python3.12/site-packages/minio/api.py", line 1942, in put_object
    return self._put_object(
           ^^^^^^^^^^^^^^^^^
  File "/home/airflow/.local/lib/python3.12/site-packages/minio/api.py", line 1781, in _put_object
    response = self._execute(
               ^^^^^^^^^^^^^^
  File "/home/airflow/.local/lib/python3.12/site-packages/minio/api.py", line 438, in _execute
    region = self._get_region(bucket_name)
             ^^^^^^^^^^^^^^^^^^^^^^^^^^^^^
  File "/home/airflow/.local/lib/python3.12/site-packages/minio/api.py", line 495, in _get_region
    response = self._url_open(
               ^^^^^^^^^^^^^^^
  File "/home/airflow/.local/lib/python3.12/site-packages/minio/api.py", line 424, in _url_open
    raise response_error
minio.error.S3Error: S3 operation failed; code: NoSuchBucket, message: The specified bucket does not exist, resource: /raw, request_id: 181DB627803DE2FD, host_id: dd9025bab4ad464b049177c95eb6ebf374d3b3fd1af9251148b658df7ac2e3e8, bucket_name: raw
[2025-01-24T19:01:52.047+0000] {local_task_job_runner.py:266} INFO - Task exited with return code 1
[2025-01-24T19:01:52.059+0000] {taskinstance.py:3895} INFO - 0 downstream tasks scheduled from follow-on schedule check
[2025-01-24T19:01:52.061+0000] {local_task_job_runner.py:245} INFO - ::endgroup::
