[2025-01-18T21:22:35.749+0000] {local_task_job_runner.py:123} INFO - ::group::Pre task execution logs
[2025-01-18T21:22:35.759+0000] {taskinstance.py:2613} INFO - Dependencies all met for dep_context=non-requeueable deps ti=<TaskInstance: coleta_dados_abertos_cnpj.extract scheduled__2024-06-10T00:00:00+00:00 [queued]>
[2025-01-18T21:22:35.766+0000] {taskinstance.py:2613} INFO - Dependencies all met for dep_context=requeueable deps ti=<TaskInstance: coleta_dados_abertos_cnpj.extract scheduled__2024-06-10T00:00:00+00:00 [queued]>
[2025-01-18T21:22:35.766+0000] {taskinstance.py:2866} INFO - Starting attempt 1 of 2
[2025-01-18T21:22:35.803+0000] {taskinstance.py:2889} INFO - Executing <Task(PythonOperator): extract> on 2024-06-10 00:00:00+00:00
[2025-01-18T21:22:35.808+0000] {warnings.py:112} WARNING - /home/***/.local/lib/python3.12/site-packages/***/task/task_runner/standard_task_runner.py:70: DeprecationWarning: This process (pid=340) is multi-threaded, use of fork() may lead to deadlocks in the child.
  pid = os.fork()

[2025-01-18T21:22:35.809+0000] {standard_task_runner.py:72} INFO - Started process 353 to run task
[2025-01-18T21:22:35.809+0000] {standard_task_runner.py:104} INFO - Running: ['***', 'tasks', 'run', 'coleta_dados_abertos_cnpj', 'extract', 'scheduled__2024-06-10T00:00:00+00:00', '--job-id', '124', '--raw', '--subdir', 'DAGS_FOLDER/coleta_dados_abertos_cnpj/dag.py', '--cfg-path', '/tmp/tmpqwhkok0h']
[2025-01-18T21:22:35.811+0000] {standard_task_runner.py:105} INFO - Job 124: Subtask extract
[2025-01-18T21:22:35.840+0000] {task_command.py:467} INFO - Running <TaskInstance: coleta_dados_abertos_cnpj.extract scheduled__2024-06-10T00:00:00+00:00 [running]> on host e9a1739d3128
[2025-01-18T21:22:35.891+0000] {taskinstance.py:3132} INFO - Exporting env vars: AIRFLOW_CTX_DAG_OWNER='Corvaum' AIRFLOW_CTX_DAG_ID='coleta_dados_abertos_cnpj' AIRFLOW_CTX_TASK_ID='extract' AIRFLOW_CTX_EXECUTION_DATE='2024-06-10T00:00:00+00:00' AIRFLOW_CTX_TRY_NUMBER='1' AIRFLOW_CTX_DAG_RUN_ID='scheduled__2024-06-10T00:00:00+00:00'
[2025-01-18T21:22:35.892+0000] {taskinstance.py:731} INFO - ::endgroup::
[2025-01-18T21:22:35.904+0000] {logging_mixin.py:190} INFO - 2024-06
[2025-01-18T21:22:36.085+0000] {logging_mixin.py:190} INFO - Arquivos encontrados no diret√≥rio https://arquivos.receitafederal.gov.br/dados/cnpj/dados_abertos_cnpj/2024-06:
[2025-01-18T21:22:36.086+0000] {logging_mixin.py:190} INFO - ['Cnaes.zip', 'Empresas0.zip', 'Empresas1.zip', 'Empresas2.zip', 'Empresas3.zip', 'Empresas4.zip', 'Empresas5.zip', 'Empresas6.zip', 'Empresas7.zip', 'Empresas8.zip', 'Empresas9.zip', 'Estabelecimentos0.zip', 'Estabelecimentos1.zip', 'Estabelecimentos2.zip', 'Estabelecimentos3.zip', 'Estabelecimentos4.zip', 'Estabelecimentos5.zip', 'Estabelecimentos6.zip', 'Estabelecimentos7.zip', 'Estabelecimentos8.zip', 'Estabelecimentos9.zip', 'Motivos.zip', 'Municipios.zip', 'Naturezas.zip', 'Paises.zip', 'Qualificacoes.zip', 'Simples.zip', 'Socios0.zip', 'Socios1.zip', 'Socios2.zip', 'Socios3.zip', 'Socios4.zip', 'Socios5.zip', 'Socios6.zip', 'Socios7.zip', 'Socios8.zip', 'Socios9.zip']
[2025-01-18T21:22:36.086+0000] {python.py:240} INFO - Done. Returned value was: None
[2025-01-18T21:22:36.091+0000] {taskinstance.py:340} INFO - ::group::Post task execution logs
[2025-01-18T21:22:36.091+0000] {taskinstance.py:352} INFO - Marking task as SUCCESS. dag_id=coleta_dados_abertos_cnpj, task_id=extract, run_id=scheduled__2024-06-10T00:00:00+00:00, execution_date=20240610T000000, start_date=20250118T212235, end_date=20250118T212236
[2025-01-18T21:22:36.104+0000] {local_task_job_runner.py:266} INFO - Task exited with return code 0
[2025-01-18T21:22:36.112+0000] {taskinstance.py:3895} INFO - 0 downstream tasks scheduled from follow-on schedule check
[2025-01-18T21:22:36.114+0000] {local_task_job_runner.py:245} INFO - ::endgroup::
[2025-01-19T20:06:53.449+0000] {local_task_job_runner.py:123} INFO - ::group::Pre task execution logs
[2025-01-19T20:06:53.459+0000] {taskinstance.py:2613} INFO - Dependencies all met for dep_context=non-requeueable deps ti=<TaskInstance: coleta_dados_abertos_cnpj.extract scheduled__2024-06-10T00:00:00+00:00 [queued]>
[2025-01-19T20:06:53.465+0000] {taskinstance.py:2613} INFO - Dependencies all met for dep_context=requeueable deps ti=<TaskInstance: coleta_dados_abertos_cnpj.extract scheduled__2024-06-10T00:00:00+00:00 [queued]>
[2025-01-19T20:06:53.465+0000] {taskinstance.py:2866} INFO - Starting attempt 1 of 2
[2025-01-19T20:06:53.474+0000] {taskinstance.py:2889} INFO - Executing <Task(PythonOperator): extract> on 2024-06-10 00:00:00+00:00
[2025-01-19T20:06:53.478+0000] {warnings.py:112} WARNING - /home/***/.local/lib/python3.12/site-packages/***/task/task_runner/standard_task_runner.py:70: DeprecationWarning: This process (pid=221) is multi-threaded, use of fork() may lead to deadlocks in the child.
  pid = os.fork()

[2025-01-19T20:06:53.479+0000] {standard_task_runner.py:72} INFO - Started process 232 to run task
[2025-01-19T20:06:53.480+0000] {standard_task_runner.py:104} INFO - Running: ['***', 'tasks', 'run', 'coleta_dados_abertos_cnpj', 'extract', 'scheduled__2024-06-10T00:00:00+00:00', '--job-id', '53', '--raw', '--subdir', 'DAGS_FOLDER/coleta_dados_abertos_cnpj/dag.py', '--cfg-path', '/tmp/tmpaaggpvkv']
[2025-01-19T20:06:53.481+0000] {standard_task_runner.py:105} INFO - Job 53: Subtask extract
[2025-01-19T20:06:53.513+0000] {task_command.py:467} INFO - Running <TaskInstance: coleta_dados_abertos_cnpj.extract scheduled__2024-06-10T00:00:00+00:00 [running]> on host 659dab735c6e
[2025-01-19T20:06:53.561+0000] {taskinstance.py:3132} INFO - Exporting env vars: AIRFLOW_CTX_DAG_OWNER='Corvaum' AIRFLOW_CTX_DAG_ID='coleta_dados_abertos_cnpj' AIRFLOW_CTX_TASK_ID='extract' AIRFLOW_CTX_EXECUTION_DATE='2024-06-10T00:00:00+00:00' AIRFLOW_CTX_TRY_NUMBER='1' AIRFLOW_CTX_DAG_RUN_ID='scheduled__2024-06-10T00:00:00+00:00'
[2025-01-19T20:06:53.562+0000] {taskinstance.py:731} INFO - ::endgroup::
[2025-01-19T20:06:53.574+0000] {logging_mixin.py:190} INFO - 2024-06
[2025-01-19T20:06:53.741+0000] {logging_mixin.py:190} INFO - -----------------
[2025-01-19T20:06:53.741+0000] {logging_mixin.py:190} INFO - ['Cnaes.zip']
[2025-01-19T20:06:53.742+0000] {logging_mixin.py:190} INFO - ['Cnaes']
[2025-01-19T20:06:53.896+0000] {logging_mixin.py:190} INFO - Arquivo salvo em: G:/Airlfow/volumes/dados_abertos_cnpj/2024-06/Cnaes/Cnaes.zip
[2025-01-19T20:06:53.897+0000] {logging_mixin.py:190} INFO - None
[2025-01-19T20:06:53.897+0000] {logging_mixin.py:190} INFO - ['Cnaes.zip']
[2025-01-19T20:06:53.898+0000] {python.py:240} INFO - Done. Returned value was: None
[2025-01-19T20:06:53.903+0000] {taskinstance.py:340} INFO - ::group::Post task execution logs
[2025-01-19T20:06:53.904+0000] {taskinstance.py:352} INFO - Marking task as SUCCESS. dag_id=coleta_dados_abertos_cnpj, task_id=extract, run_id=scheduled__2024-06-10T00:00:00+00:00, execution_date=20240610T000000, start_date=20250119T200653, end_date=20250119T200653
[2025-01-19T20:06:53.934+0000] {local_task_job_runner.py:266} INFO - Task exited with return code 0
[2025-01-19T20:06:53.957+0000] {taskinstance.py:3895} INFO - 1 downstream tasks scheduled from follow-on schedule check
[2025-01-19T20:06:53.959+0000] {local_task_job_runner.py:245} INFO - ::endgroup::
[2025-01-19T22:19:35.240+0000] {local_task_job_runner.py:123} INFO - ::group::Pre task execution logs
[2025-01-19T22:19:35.250+0000] {taskinstance.py:2613} INFO - Dependencies all met for dep_context=non-requeueable deps ti=<TaskInstance: coleta_dados_abertos_cnpj.extract scheduled__2024-06-10T00:00:00+00:00 [queued]>
[2025-01-19T22:19:35.255+0000] {taskinstance.py:2613} INFO - Dependencies all met for dep_context=requeueable deps ti=<TaskInstance: coleta_dados_abertos_cnpj.extract scheduled__2024-06-10T00:00:00+00:00 [queued]>
[2025-01-19T22:19:35.255+0000] {taskinstance.py:2866} INFO - Starting attempt 1 of 2
[2025-01-19T22:19:35.263+0000] {taskinstance.py:2889} INFO - Executing <Task(PythonOperator): extract> on 2024-06-10 00:00:00+00:00
[2025-01-19T22:19:35.268+0000] {warnings.py:112} WARNING - /home/***/.local/lib/python3.12/site-packages/***/task/task_runner/standard_task_runner.py:70: DeprecationWarning: This process (pid=534) is multi-threaded, use of fork() may lead to deadlocks in the child.
  pid = os.fork()

[2025-01-19T22:19:35.272+0000] {standard_task_runner.py:72} INFO - Started process 539 to run task
[2025-01-19T22:19:35.272+0000] {standard_task_runner.py:104} INFO - Running: ['***', 'tasks', 'run', 'coleta_dados_abertos_cnpj', 'extract', 'scheduled__2024-06-10T00:00:00+00:00', '--job-id', '168', '--raw', '--subdir', 'DAGS_FOLDER/coleta_dados_abertos_cnpj/dag.py', '--cfg-path', '/tmp/tmpkf84plma']
[2025-01-19T22:19:35.274+0000] {standard_task_runner.py:105} INFO - Job 168: Subtask extract
[2025-01-19T22:19:35.306+0000] {task_command.py:467} INFO - Running <TaskInstance: coleta_dados_abertos_cnpj.extract scheduled__2024-06-10T00:00:00+00:00 [running]> on host 659dab735c6e
[2025-01-19T22:19:35.355+0000] {taskinstance.py:3132} INFO - Exporting env vars: AIRFLOW_CTX_DAG_OWNER='Corvaum' AIRFLOW_CTX_DAG_ID='coleta_dados_abertos_cnpj' AIRFLOW_CTX_TASK_ID='extract' AIRFLOW_CTX_EXECUTION_DATE='2024-06-10T00:00:00+00:00' AIRFLOW_CTX_TRY_NUMBER='1' AIRFLOW_CTX_DAG_RUN_ID='scheduled__2024-06-10T00:00:00+00:00'
[2025-01-19T22:19:35.356+0000] {taskinstance.py:731} INFO - ::endgroup::
[2025-01-19T22:19:35.368+0000] {logging_mixin.py:190} INFO - 2024-06
[2025-01-19T22:19:35.541+0000] {logging_mixin.py:190} INFO - -----------------
[2025-01-19T22:19:35.541+0000] {logging_mixin.py:190} INFO - ['Cnaes.zip', 'Empresas0.zip', 'Empresas1.zip', 'Empresas2.zip', 'Empresas3.zip', 'Empresas4.zip', 'Empresas5.zip', 'Empresas6.zip', 'Empresas7.zip', 'Empresas8.zip', 'Empresas9.zip', 'Estabelecimentos0.zip', 'Estabelecimentos1.zip', 'Estabelecimentos2.zip', 'Estabelecimentos3.zip', 'Estabelecimentos4.zip', 'Estabelecimentos5.zip', 'Estabelecimentos6.zip', 'Estabelecimentos7.zip', 'Estabelecimentos8.zip', 'Estabelecimentos9.zip', 'Motivos.zip', 'Municipios.zip', 'Naturezas.zip', 'Paises.zip', 'Qualificacoes.zip', 'Simples.zip', 'Socios0.zip', 'Socios1.zip', 'Socios2.zip', 'Socios3.zip', 'Socios4.zip', 'Socios5.zip', 'Socios6.zip', 'Socios7.zip', 'Socios8.zip', 'Socios9.zip']
[2025-01-19T22:19:35.541+0000] {logging_mixin.py:190} INFO - ['Cnaes', 'Empresas', 'Estabelecimentos', 'Motivos', 'Municipios', 'Naturezas', 'Paises', 'Qualificacoes', 'Simples', 'Socios']
[2025-01-19T22:19:35.541+0000] {logging_mixin.py:190} INFO - Iniciando o download de: https://arquivos.receitafederal.gov.br/dados/cnpj/dados_abertos_cnpj/2024-06/Cnaes.zip
[2025-01-19T22:19:54.777+0000] {taskinstance.py:3311} ERROR - Task failed with exception
Traceback (most recent call last):
  File "/home/airflow/.local/lib/python3.12/site-packages/urllib3/connectionpool.py", line 466, in _make_request
    self._validate_conn(conn)
  File "/home/airflow/.local/lib/python3.12/site-packages/urllib3/connectionpool.py", line 1095, in _validate_conn
    conn.connect()
  File "/home/airflow/.local/lib/python3.12/site-packages/urllib3/connection.py", line 730, in connect
    sock_and_verified = _ssl_wrap_socket_and_match_hostname(
                        ^^^^^^^^^^^^^^^^^^^^^^^^^^^^^^^^^^^^
  File "/home/airflow/.local/lib/python3.12/site-packages/urllib3/connection.py", line 909, in _ssl_wrap_socket_and_match_hostname
    ssl_sock = ssl_wrap_socket(
               ^^^^^^^^^^^^^^^^
  File "/home/airflow/.local/lib/python3.12/site-packages/urllib3/util/ssl_.py", line 469, in ssl_wrap_socket
    ssl_sock = _ssl_wrap_socket_impl(sock, context, tls_in_tls, server_hostname)
               ^^^^^^^^^^^^^^^^^^^^^^^^^^^^^^^^^^^^^^^^^^^^^^^^^^^^^^^^^^^^^^^^^
  File "/home/airflow/.local/lib/python3.12/site-packages/urllib3/util/ssl_.py", line 513, in _ssl_wrap_socket_impl
    return ssl_context.wrap_socket(sock, server_hostname=server_hostname)
           ^^^^^^^^^^^^^^^^^^^^^^^^^^^^^^^^^^^^^^^^^^^^^^^^^^^^^^^^^^^^^^
  File "/usr/local/lib/python3.12/ssl.py", line 455, in wrap_socket
    return self.sslsocket_class._create(
           ^^^^^^^^^^^^^^^^^^^^^^^^^^^^^
  File "/usr/local/lib/python3.12/ssl.py", line 1041, in _create
    self.do_handshake()
  File "/usr/local/lib/python3.12/ssl.py", line 1319, in do_handshake
    self._sslobj.do_handshake()
ssl.SSLEOFError: [SSL: UNEXPECTED_EOF_WHILE_READING] EOF occurred in violation of protocol (_ssl.c:1000)

During handling of the above exception, another exception occurred:

Traceback (most recent call last):
  File "/home/airflow/.local/lib/python3.12/site-packages/urllib3/connectionpool.py", line 789, in urlopen
    response = self._make_request(
               ^^^^^^^^^^^^^^^^^^^
  File "/home/airflow/.local/lib/python3.12/site-packages/urllib3/connectionpool.py", line 490, in _make_request
    raise new_e
urllib3.exceptions.SSLError: [SSL: UNEXPECTED_EOF_WHILE_READING] EOF occurred in violation of protocol (_ssl.c:1000)

The above exception was the direct cause of the following exception:

Traceback (most recent call last):
  File "/home/airflow/.local/lib/python3.12/site-packages/requests/adapters.py", line 667, in send
    resp = conn.urlopen(
           ^^^^^^^^^^^^^
  File "/home/airflow/.local/lib/python3.12/site-packages/urllib3/connectionpool.py", line 843, in urlopen
    retries = retries.increment(
              ^^^^^^^^^^^^^^^^^^
  File "/home/airflow/.local/lib/python3.12/site-packages/urllib3/util/retry.py", line 519, in increment
    raise MaxRetryError(_pool, url, reason) from reason  # type: ignore[arg-type]
    ^^^^^^^^^^^^^^^^^^^^^^^^^^^^^^^^^^^^^^^^^^^^^^^^^^^
urllib3.exceptions.MaxRetryError: HTTPSConnectionPool(host='arquivos.receitafederal.gov.br', port=443): Max retries exceeded with url: /dados/cnpj/dados_abertos_cnpj/2024-06/Cnaes.zip (Caused by SSLError(SSLEOFError(8, '[SSL: UNEXPECTED_EOF_WHILE_READING] EOF occurred in violation of protocol (_ssl.c:1000)')))

During handling of the above exception, another exception occurred:

Traceback (most recent call last):
  File "/home/airflow/.local/lib/python3.12/site-packages/airflow/models/taskinstance.py", line 767, in _execute_task
    result = _execute_callable(context=context, **execute_callable_kwargs)
             ^^^^^^^^^^^^^^^^^^^^^^^^^^^^^^^^^^^^^^^^^^^^^^^^^^^^^^^^^^^^^
  File "/home/airflow/.local/lib/python3.12/site-packages/airflow/models/taskinstance.py", line 733, in _execute_callable
    return ExecutionCallableRunner(
           ^^^^^^^^^^^^^^^^^^^^^^^^
  File "/home/airflow/.local/lib/python3.12/site-packages/airflow/utils/operator_helpers.py", line 252, in run
    return self.func(*args, **kwargs)
           ^^^^^^^^^^^^^^^^^^^^^^^^^^
  File "/home/airflow/.local/lib/python3.12/site-packages/airflow/models/baseoperator.py", line 422, in wrapper
    return func(self, *args, **kwargs)
           ^^^^^^^^^^^^^^^^^^^^^^^^^^^
  File "/home/airflow/.local/lib/python3.12/site-packages/airflow/operators/python.py", line 238, in execute
    return_value = self.execute_callable()
                   ^^^^^^^^^^^^^^^^^^^^^^^
  File "/home/airflow/.local/lib/python3.12/site-packages/airflow/operators/python.py", line 256, in execute_callable
    return runner.run(*self.op_args, **self.op_kwargs)
           ^^^^^^^^^^^^^^^^^^^^^^^^^^^^^^^^^^^^^^^^^^^
  File "/home/airflow/.local/lib/python3.12/site-packages/airflow/utils/operator_helpers.py", line 252, in run
    return self.func(*args, **kwargs)
           ^^^^^^^^^^^^^^^^^^^^^^^^^^
  File "/opt/airflow/dags/coleta_dados_abertos_cnpj/jobs/extract.py", line 105, in extract
    file_path = download_with_requests(
                ^^^^^^^^^^^^^^^^^^^^^^^
  File "/opt/airflow/dags/coleta_dados_abertos_cnpj/jobs/extract.py", line 65, in download_with_requests
    with requests.get(download_file_url, stream=True) as r:
         ^^^^^^^^^^^^^^^^^^^^^^^^^^^^^^^^^^^^^^^^^^^^
  File "/home/airflow/.local/lib/python3.12/site-packages/requests/api.py", line 73, in get
    return request("get", url, params=params, **kwargs)
           ^^^^^^^^^^^^^^^^^^^^^^^^^^^^^^^^^^^^^^^^^^^^
  File "/home/airflow/.local/lib/python3.12/site-packages/requests/api.py", line 59, in request
    return session.request(method=method, url=url, **kwargs)
           ^^^^^^^^^^^^^^^^^^^^^^^^^^^^^^^^^^^^^^^^^^^^^^^^^
  File "/home/airflow/.local/lib/python3.12/site-packages/requests/sessions.py", line 589, in request
    resp = self.send(prep, **send_kwargs)
           ^^^^^^^^^^^^^^^^^^^^^^^^^^^^^^
  File "/home/airflow/.local/lib/python3.12/site-packages/requests/sessions.py", line 703, in send
    r = adapter.send(request, **kwargs)
        ^^^^^^^^^^^^^^^^^^^^^^^^^^^^^^^
  File "/home/airflow/.local/lib/python3.12/site-packages/requests/adapters.py", line 698, in send
    raise SSLError(e, request=request)
requests.exceptions.SSLError: HTTPSConnectionPool(host='arquivos.receitafederal.gov.br', port=443): Max retries exceeded with url: /dados/cnpj/dados_abertos_cnpj/2024-06/Cnaes.zip (Caused by SSLError(SSLEOFError(8, '[SSL: UNEXPECTED_EOF_WHILE_READING] EOF occurred in violation of protocol (_ssl.c:1000)')))
[2025-01-19T22:19:54.794+0000] {taskinstance.py:1225} INFO - Marking task as UP_FOR_RETRY. dag_id=coleta_dados_abertos_cnpj, task_id=extract, run_id=scheduled__2024-06-10T00:00:00+00:00, execution_date=20240610T000000, start_date=20250119T221935, end_date=20250119T221954
[2025-01-19T22:19:54.904+0000] {taskinstance.py:340} INFO - ::group::Post task execution logs
[2025-01-19T22:19:54.905+0000] {standard_task_runner.py:124} ERROR - Failed to execute job 168 for task extract (HTTPSConnectionPool(host='arquivos.receitafederal.gov.br', port=443): Max retries exceeded with url: /dados/cnpj/dados_abertos_cnpj/2024-06/Cnaes.zip (Caused by SSLError(SSLEOFError(8, '[SSL: UNEXPECTED_EOF_WHILE_READING] EOF occurred in violation of protocol (_ssl.c:1000)'))); 539)
Traceback (most recent call last):
  File "/home/airflow/.local/lib/python3.12/site-packages/urllib3/connectionpool.py", line 466, in _make_request
    self._validate_conn(conn)
  File "/home/airflow/.local/lib/python3.12/site-packages/urllib3/connectionpool.py", line 1095, in _validate_conn
    conn.connect()
  File "/home/airflow/.local/lib/python3.12/site-packages/urllib3/connection.py", line 730, in connect
    sock_and_verified = _ssl_wrap_socket_and_match_hostname(
                        ^^^^^^^^^^^^^^^^^^^^^^^^^^^^^^^^^^^^
  File "/home/airflow/.local/lib/python3.12/site-packages/urllib3/connection.py", line 909, in _ssl_wrap_socket_and_match_hostname
    ssl_sock = ssl_wrap_socket(
               ^^^^^^^^^^^^^^^^
  File "/home/airflow/.local/lib/python3.12/site-packages/urllib3/util/ssl_.py", line 469, in ssl_wrap_socket
    ssl_sock = _ssl_wrap_socket_impl(sock, context, tls_in_tls, server_hostname)
               ^^^^^^^^^^^^^^^^^^^^^^^^^^^^^^^^^^^^^^^^^^^^^^^^^^^^^^^^^^^^^^^^^
  File "/home/airflow/.local/lib/python3.12/site-packages/urllib3/util/ssl_.py", line 513, in _ssl_wrap_socket_impl
    return ssl_context.wrap_socket(sock, server_hostname=server_hostname)
           ^^^^^^^^^^^^^^^^^^^^^^^^^^^^^^^^^^^^^^^^^^^^^^^^^^^^^^^^^^^^^^
  File "/usr/local/lib/python3.12/ssl.py", line 455, in wrap_socket
    return self.sslsocket_class._create(
           ^^^^^^^^^^^^^^^^^^^^^^^^^^^^^
  File "/usr/local/lib/python3.12/ssl.py", line 1041, in _create
    self.do_handshake()
  File "/usr/local/lib/python3.12/ssl.py", line 1319, in do_handshake
    self._sslobj.do_handshake()
ssl.SSLEOFError: [SSL: UNEXPECTED_EOF_WHILE_READING] EOF occurred in violation of protocol (_ssl.c:1000)

During handling of the above exception, another exception occurred:

Traceback (most recent call last):
  File "/home/airflow/.local/lib/python3.12/site-packages/urllib3/connectionpool.py", line 789, in urlopen
    response = self._make_request(
               ^^^^^^^^^^^^^^^^^^^
  File "/home/airflow/.local/lib/python3.12/site-packages/urllib3/connectionpool.py", line 490, in _make_request
    raise new_e
urllib3.exceptions.SSLError: [SSL: UNEXPECTED_EOF_WHILE_READING] EOF occurred in violation of protocol (_ssl.c:1000)

The above exception was the direct cause of the following exception:

Traceback (most recent call last):
  File "/home/airflow/.local/lib/python3.12/site-packages/requests/adapters.py", line 667, in send
    resp = conn.urlopen(
           ^^^^^^^^^^^^^
  File "/home/airflow/.local/lib/python3.12/site-packages/urllib3/connectionpool.py", line 843, in urlopen
    retries = retries.increment(
              ^^^^^^^^^^^^^^^^^^
  File "/home/airflow/.local/lib/python3.12/site-packages/urllib3/util/retry.py", line 519, in increment
    raise MaxRetryError(_pool, url, reason) from reason  # type: ignore[arg-type]
    ^^^^^^^^^^^^^^^^^^^^^^^^^^^^^^^^^^^^^^^^^^^^^^^^^^^
urllib3.exceptions.MaxRetryError: HTTPSConnectionPool(host='arquivos.receitafederal.gov.br', port=443): Max retries exceeded with url: /dados/cnpj/dados_abertos_cnpj/2024-06/Cnaes.zip (Caused by SSLError(SSLEOFError(8, '[SSL: UNEXPECTED_EOF_WHILE_READING] EOF occurred in violation of protocol (_ssl.c:1000)')))

During handling of the above exception, another exception occurred:

Traceback (most recent call last):
  File "/home/airflow/.local/lib/python3.12/site-packages/airflow/task/task_runner/standard_task_runner.py", line 117, in _start_by_fork
    ret = args.func(args, dag=self.dag)
          ^^^^^^^^^^^^^^^^^^^^^^^^^^^^^
  File "/home/airflow/.local/lib/python3.12/site-packages/airflow/cli/cli_config.py", line 49, in command
    return func(*args, **kwargs)
           ^^^^^^^^^^^^^^^^^^^^^
  File "/home/airflow/.local/lib/python3.12/site-packages/airflow/utils/cli.py", line 116, in wrapper
    return f(*args, **kwargs)
           ^^^^^^^^^^^^^^^^^^
  File "/home/airflow/.local/lib/python3.12/site-packages/airflow/cli/commands/task_command.py", line 483, in task_run
    task_return_code = _run_task_by_selected_method(args, _dag, ti)
                       ^^^^^^^^^^^^^^^^^^^^^^^^^^^^^^^^^^^^^^^^^^^^
  File "/home/airflow/.local/lib/python3.12/site-packages/airflow/cli/commands/task_command.py", line 256, in _run_task_by_selected_method
    return _run_raw_task(args, ti)
           ^^^^^^^^^^^^^^^^^^^^^^^
  File "/home/airflow/.local/lib/python3.12/site-packages/airflow/cli/commands/task_command.py", line 341, in _run_raw_task
    return ti._run_raw_task(
           ^^^^^^^^^^^^^^^^^
  File "/home/airflow/.local/lib/python3.12/site-packages/airflow/utils/session.py", line 97, in wrapper
    return func(*args, session=session, **kwargs)
           ^^^^^^^^^^^^^^^^^^^^^^^^^^^^^^^^^^^^^^
  File "/home/airflow/.local/lib/python3.12/site-packages/airflow/models/taskinstance.py", line 3005, in _run_raw_task
    return _run_raw_task(
           ^^^^^^^^^^^^^^
  File "/home/airflow/.local/lib/python3.12/site-packages/airflow/models/taskinstance.py", line 273, in _run_raw_task
    TaskInstance._execute_task_with_callbacks(
  File "/home/airflow/.local/lib/python3.12/site-packages/airflow/models/taskinstance.py", line 3159, in _execute_task_with_callbacks
    result = self._execute_task(context, task_orig)
             ^^^^^^^^^^^^^^^^^^^^^^^^^^^^^^^^^^^^^^
  File "/home/airflow/.local/lib/python3.12/site-packages/airflow/models/taskinstance.py", line 3183, in _execute_task
    return _execute_task(self, context, task_orig)
           ^^^^^^^^^^^^^^^^^^^^^^^^^^^^^^^^^^^^^^^
  File "/home/airflow/.local/lib/python3.12/site-packages/airflow/models/taskinstance.py", line 767, in _execute_task
    result = _execute_callable(context=context, **execute_callable_kwargs)
             ^^^^^^^^^^^^^^^^^^^^^^^^^^^^^^^^^^^^^^^^^^^^^^^^^^^^^^^^^^^^^
  File "/home/airflow/.local/lib/python3.12/site-packages/airflow/models/taskinstance.py", line 733, in _execute_callable
    return ExecutionCallableRunner(
           ^^^^^^^^^^^^^^^^^^^^^^^^
  File "/home/airflow/.local/lib/python3.12/site-packages/airflow/utils/operator_helpers.py", line 252, in run
    return self.func(*args, **kwargs)
           ^^^^^^^^^^^^^^^^^^^^^^^^^^
  File "/home/airflow/.local/lib/python3.12/site-packages/airflow/models/baseoperator.py", line 422, in wrapper
    return func(self, *args, **kwargs)
           ^^^^^^^^^^^^^^^^^^^^^^^^^^^
  File "/home/airflow/.local/lib/python3.12/site-packages/airflow/operators/python.py", line 238, in execute
    return_value = self.execute_callable()
                   ^^^^^^^^^^^^^^^^^^^^^^^
  File "/home/airflow/.local/lib/python3.12/site-packages/airflow/operators/python.py", line 256, in execute_callable
    return runner.run(*self.op_args, **self.op_kwargs)
           ^^^^^^^^^^^^^^^^^^^^^^^^^^^^^^^^^^^^^^^^^^^
  File "/home/airflow/.local/lib/python3.12/site-packages/airflow/utils/operator_helpers.py", line 252, in run
    return self.func(*args, **kwargs)
           ^^^^^^^^^^^^^^^^^^^^^^^^^^
  File "/opt/airflow/dags/coleta_dados_abertos_cnpj/jobs/extract.py", line 105, in extract
    file_path = download_with_requests(
                ^^^^^^^^^^^^^^^^^^^^^^^
  File "/opt/airflow/dags/coleta_dados_abertos_cnpj/jobs/extract.py", line 65, in download_with_requests
    with requests.get(download_file_url, stream=True) as r:
         ^^^^^^^^^^^^^^^^^^^^^^^^^^^^^^^^^^^^^^^^^^^^
  File "/home/airflow/.local/lib/python3.12/site-packages/requests/api.py", line 73, in get
    return request("get", url, params=params, **kwargs)
           ^^^^^^^^^^^^^^^^^^^^^^^^^^^^^^^^^^^^^^^^^^^^
  File "/home/airflow/.local/lib/python3.12/site-packages/requests/api.py", line 59, in request
    return session.request(method=method, url=url, **kwargs)
           ^^^^^^^^^^^^^^^^^^^^^^^^^^^^^^^^^^^^^^^^^^^^^^^^^
  File "/home/airflow/.local/lib/python3.12/site-packages/requests/sessions.py", line 589, in request
    resp = self.send(prep, **send_kwargs)
           ^^^^^^^^^^^^^^^^^^^^^^^^^^^^^^
  File "/home/airflow/.local/lib/python3.12/site-packages/requests/sessions.py", line 703, in send
    r = adapter.send(request, **kwargs)
        ^^^^^^^^^^^^^^^^^^^^^^^^^^^^^^^
  File "/home/airflow/.local/lib/python3.12/site-packages/requests/adapters.py", line 698, in send
    raise SSLError(e, request=request)
requests.exceptions.SSLError: HTTPSConnectionPool(host='arquivos.receitafederal.gov.br', port=443): Max retries exceeded with url: /dados/cnpj/dados_abertos_cnpj/2024-06/Cnaes.zip (Caused by SSLError(SSLEOFError(8, '[SSL: UNEXPECTED_EOF_WHILE_READING] EOF occurred in violation of protocol (_ssl.c:1000)')))
[2025-01-19T22:19:54.927+0000] {local_task_job_runner.py:266} INFO - Task exited with return code 1
[2025-01-19T22:19:54.940+0000] {taskinstance.py:3895} INFO - 0 downstream tasks scheduled from follow-on schedule check
[2025-01-19T22:19:54.943+0000] {local_task_job_runner.py:245} INFO - ::endgroup::
[2025-01-24T19:01:30.676+0000] {local_task_job_runner.py:123} INFO - ::group::Pre task execution logs
[2025-01-24T19:01:30.685+0000] {taskinstance.py:2613} INFO - Dependencies all met for dep_context=non-requeueable deps ti=<TaskInstance: coleta_dados_abertos_cnpj.extract scheduled__2024-06-10T00:00:00+00:00 [queued]>
[2025-01-24T19:01:30.691+0000] {taskinstance.py:2613} INFO - Dependencies all met for dep_context=requeueable deps ti=<TaskInstance: coleta_dados_abertos_cnpj.extract scheduled__2024-06-10T00:00:00+00:00 [queued]>
[2025-01-24T19:01:30.691+0000] {taskinstance.py:2866} INFO - Starting attempt 1 of 2
[2025-01-24T19:01:30.707+0000] {taskinstance.py:2889} INFO - Executing <Task(PythonOperator): extract> on 2024-06-10 00:00:00+00:00
[2025-01-24T19:01:30.711+0000] {warnings.py:112} WARNING - /home/***/.local/lib/python3.12/site-packages/***/task/task_runner/standard_task_runner.py:70: DeprecationWarning: This process (pid=1315) is multi-threaded, use of fork() may lead to deadlocks in the child.
  pid = os.fork()

[2025-01-24T19:01:30.712+0000] {standard_task_runner.py:72} INFO - Started process 1324 to run task
[2025-01-24T19:01:30.712+0000] {standard_task_runner.py:104} INFO - Running: ['***', 'tasks', 'run', 'coleta_dados_abertos_cnpj', 'extract', 'scheduled__2024-06-10T00:00:00+00:00', '--job-id', '586', '--raw', '--subdir', 'DAGS_FOLDER/coleta_dados_abertos_cnpj/dag.py', '--cfg-path', '/tmp/tmpbkr59fwr']
[2025-01-24T19:01:30.713+0000] {standard_task_runner.py:105} INFO - Job 586: Subtask extract
[2025-01-24T19:01:30.738+0000] {task_command.py:467} INFO - Running <TaskInstance: coleta_dados_abertos_cnpj.extract scheduled__2024-06-10T00:00:00+00:00 [running]> on host ee70781c29c7
[2025-01-24T19:01:30.790+0000] {taskinstance.py:3132} INFO - Exporting env vars: AIRFLOW_CTX_DAG_OWNER='Corvaum' AIRFLOW_CTX_DAG_ID='coleta_dados_abertos_cnpj' AIRFLOW_CTX_TASK_ID='extract' AIRFLOW_CTX_EXECUTION_DATE='2024-06-10T00:00:00+00:00' AIRFLOW_CTX_TRY_NUMBER='1' AIRFLOW_CTX_DAG_RUN_ID='scheduled__2024-06-10T00:00:00+00:00'
[2025-01-24T19:01:30.791+0000] {taskinstance.py:731} INFO - ::endgroup::
[2025-01-24T19:01:30.802+0000] {logging_mixin.py:190} INFO - Data formatada: 2024-06
[2025-01-24T19:01:30.968+0000] {logging_mixin.py:190} INFO - Arquivos encontrados: ['Cnaes.zip', 'Empresas0.zip', 'Empresas1.zip', 'Empresas2.zip', 'Empresas3.zip', 'Empresas4.zip', 'Empresas5.zip', 'Empresas6.zip', 'Empresas7.zip', 'Empresas8.zip', 'Empresas9.zip', 'Estabelecimentos0.zip', 'Estabelecimentos1.zip', 'Estabelecimentos2.zip', 'Estabelecimentos3.zip', 'Estabelecimentos4.zip', 'Estabelecimentos5.zip', 'Estabelecimentos6.zip', 'Estabelecimentos7.zip', 'Estabelecimentos8.zip', 'Estabelecimentos9.zip', 'Motivos.zip', 'Municipios.zip', 'Naturezas.zip', 'Paises.zip', 'Qualificacoes.zip', 'Simples.zip', 'Socios0.zip', 'Socios1.zip', 'Socios2.zip', 'Socios3.zip', 'Socios4.zip', 'Socios5.zip', 'Socios6.zip', 'Socios7.zip', 'Socios8.zip', 'Socios9.zip']
[2025-01-24T19:01:30.968+0000] {logging_mixin.py:190} INFO - Baixando o arquivo: https://arquivos.receitafederal.gov.br/dados/cnpj/dados_abertos_cnpj/2024-06/Cnaes.zip
[2025-01-24T19:01:31.136+0000] {logging_mixin.py:190} INFO - Download conclu√≠do: https://arquivos.receitafederal.gov.br/dados/cnpj/dados_abertos_cnpj/2024-06/Cnaes.zip
[2025-01-24T19:01:31.139+0000] {logging_mixin.py:190} INFO - Arquivos descompactados: ['/tmp/d41ac49940f7464c861de8ca115d226c_extracted/F.K03200$Z.D40608.CNAECSV']
[2025-01-24T19:01:31.143+0000] {taskinstance.py:3311} ERROR - Task failed with exception
Traceback (most recent call last):
  File "/home/airflow/.local/lib/python3.12/site-packages/airflow/models/taskinstance.py", line 767, in _execute_task
    result = _execute_callable(context=context, **execute_callable_kwargs)
             ^^^^^^^^^^^^^^^^^^^^^^^^^^^^^^^^^^^^^^^^^^^^^^^^^^^^^^^^^^^^^
  File "/home/airflow/.local/lib/python3.12/site-packages/airflow/models/taskinstance.py", line 733, in _execute_callable
    return ExecutionCallableRunner(
           ^^^^^^^^^^^^^^^^^^^^^^^^
  File "/home/airflow/.local/lib/python3.12/site-packages/airflow/utils/operator_helpers.py", line 252, in run
    return self.func(*args, **kwargs)
           ^^^^^^^^^^^^^^^^^^^^^^^^^^
  File "/home/airflow/.local/lib/python3.12/site-packages/airflow/models/baseoperator.py", line 422, in wrapper
    return func(self, *args, **kwargs)
           ^^^^^^^^^^^^^^^^^^^^^^^^^^^
  File "/home/airflow/.local/lib/python3.12/site-packages/airflow/operators/python.py", line 238, in execute
    return_value = self.execute_callable()
                   ^^^^^^^^^^^^^^^^^^^^^^^
  File "/home/airflow/.local/lib/python3.12/site-packages/airflow/operators/python.py", line 256, in execute_callable
    return runner.run(*self.op_args, **self.op_kwargs)
           ^^^^^^^^^^^^^^^^^^^^^^^^^^^^^^^^^^^^^^^^^^^
  File "/home/airflow/.local/lib/python3.12/site-packages/airflow/utils/operator_helpers.py", line 252, in run
    return self.func(*args, **kwargs)
           ^^^^^^^^^^^^^^^^^^^^^^^^^^
  File "/opt/airflow/dags/coleta_dados_abertos_cnpj/jobs/extract.py", line 134, in extract
    upload_to_bucket(
  File "/opt/airflow/dags/coleta_dados_abertos_cnpj/jobs/extract.py", line 100, in upload_to_bucket
    client.put_object(
  File "/home/airflow/.local/lib/python3.12/site-packages/minio/api.py", line 1996, in put_object
    raise exc
  File "/home/airflow/.local/lib/python3.12/site-packages/minio/api.py", line 1942, in put_object
    return self._put_object(
           ^^^^^^^^^^^^^^^^^
  File "/home/airflow/.local/lib/python3.12/site-packages/minio/api.py", line 1781, in _put_object
    response = self._execute(
               ^^^^^^^^^^^^^^
  File "/home/airflow/.local/lib/python3.12/site-packages/minio/api.py", line 438, in _execute
    region = self._get_region(bucket_name)
             ^^^^^^^^^^^^^^^^^^^^^^^^^^^^^
  File "/home/airflow/.local/lib/python3.12/site-packages/minio/api.py", line 495, in _get_region
    response = self._url_open(
               ^^^^^^^^^^^^^^^
  File "/home/airflow/.local/lib/python3.12/site-packages/minio/api.py", line 424, in _url_open
    raise response_error
minio.error.S3Error: S3 operation failed; code: NoSuchBucket, message: The specified bucket does not exist, resource: /raw, request_id: 181DB622A4AF11B3, host_id: dd9025bab4ad464b049177c95eb6ebf374d3b3fd1af9251148b658df7ac2e3e8, bucket_name: raw
[2025-01-24T19:01:31.154+0000] {taskinstance.py:1225} INFO - Marking task as UP_FOR_RETRY. dag_id=coleta_dados_abertos_cnpj, task_id=extract, run_id=scheduled__2024-06-10T00:00:00+00:00, execution_date=20240610T000000, start_date=20250124T190130, end_date=20250124T190131
[2025-01-24T19:01:31.162+0000] {taskinstance.py:340} INFO - ::group::Post task execution logs
[2025-01-24T19:01:31.162+0000] {standard_task_runner.py:124} ERROR - Failed to execute job 586 for task extract (S3 operation failed; code: NoSuchBucket, message: The specified bucket does not exist, resource: /raw, request_id: 181DB622A4AF11B3, host_id: dd9025bab4ad464b049177c95eb6ebf374d3b3fd1af9251148b658df7ac2e3e8, bucket_name: raw; 1324)
Traceback (most recent call last):
  File "/home/airflow/.local/lib/python3.12/site-packages/airflow/task/task_runner/standard_task_runner.py", line 117, in _start_by_fork
    ret = args.func(args, dag=self.dag)
          ^^^^^^^^^^^^^^^^^^^^^^^^^^^^^
  File "/home/airflow/.local/lib/python3.12/site-packages/airflow/cli/cli_config.py", line 49, in command
    return func(*args, **kwargs)
           ^^^^^^^^^^^^^^^^^^^^^
  File "/home/airflow/.local/lib/python3.12/site-packages/airflow/utils/cli.py", line 116, in wrapper
    return f(*args, **kwargs)
           ^^^^^^^^^^^^^^^^^^
  File "/home/airflow/.local/lib/python3.12/site-packages/airflow/cli/commands/task_command.py", line 483, in task_run
    task_return_code = _run_task_by_selected_method(args, _dag, ti)
                       ^^^^^^^^^^^^^^^^^^^^^^^^^^^^^^^^^^^^^^^^^^^^
  File "/home/airflow/.local/lib/python3.12/site-packages/airflow/cli/commands/task_command.py", line 256, in _run_task_by_selected_method
    return _run_raw_task(args, ti)
           ^^^^^^^^^^^^^^^^^^^^^^^
  File "/home/airflow/.local/lib/python3.12/site-packages/airflow/cli/commands/task_command.py", line 341, in _run_raw_task
    return ti._run_raw_task(
           ^^^^^^^^^^^^^^^^^
  File "/home/airflow/.local/lib/python3.12/site-packages/airflow/utils/session.py", line 97, in wrapper
    return func(*args, session=session, **kwargs)
           ^^^^^^^^^^^^^^^^^^^^^^^^^^^^^^^^^^^^^^
  File "/home/airflow/.local/lib/python3.12/site-packages/airflow/models/taskinstance.py", line 3005, in _run_raw_task
    return _run_raw_task(
           ^^^^^^^^^^^^^^
  File "/home/airflow/.local/lib/python3.12/site-packages/airflow/models/taskinstance.py", line 273, in _run_raw_task
    TaskInstance._execute_task_with_callbacks(
  File "/home/airflow/.local/lib/python3.12/site-packages/airflow/models/taskinstance.py", line 3159, in _execute_task_with_callbacks
    result = self._execute_task(context, task_orig)
             ^^^^^^^^^^^^^^^^^^^^^^^^^^^^^^^^^^^^^^
  File "/home/airflow/.local/lib/python3.12/site-packages/airflow/models/taskinstance.py", line 3183, in _execute_task
    return _execute_task(self, context, task_orig)
           ^^^^^^^^^^^^^^^^^^^^^^^^^^^^^^^^^^^^^^^
  File "/home/airflow/.local/lib/python3.12/site-packages/airflow/models/taskinstance.py", line 767, in _execute_task
    result = _execute_callable(context=context, **execute_callable_kwargs)
             ^^^^^^^^^^^^^^^^^^^^^^^^^^^^^^^^^^^^^^^^^^^^^^^^^^^^^^^^^^^^^
  File "/home/airflow/.local/lib/python3.12/site-packages/airflow/models/taskinstance.py", line 733, in _execute_callable
    return ExecutionCallableRunner(
           ^^^^^^^^^^^^^^^^^^^^^^^^
  File "/home/airflow/.local/lib/python3.12/site-packages/airflow/utils/operator_helpers.py", line 252, in run
    return self.func(*args, **kwargs)
           ^^^^^^^^^^^^^^^^^^^^^^^^^^
  File "/home/airflow/.local/lib/python3.12/site-packages/airflow/models/baseoperator.py", line 422, in wrapper
    return func(self, *args, **kwargs)
           ^^^^^^^^^^^^^^^^^^^^^^^^^^^
  File "/home/airflow/.local/lib/python3.12/site-packages/airflow/operators/python.py", line 238, in execute
    return_value = self.execute_callable()
                   ^^^^^^^^^^^^^^^^^^^^^^^
  File "/home/airflow/.local/lib/python3.12/site-packages/airflow/operators/python.py", line 256, in execute_callable
    return runner.run(*self.op_args, **self.op_kwargs)
           ^^^^^^^^^^^^^^^^^^^^^^^^^^^^^^^^^^^^^^^^^^^
  File "/home/airflow/.local/lib/python3.12/site-packages/airflow/utils/operator_helpers.py", line 252, in run
    return self.func(*args, **kwargs)
           ^^^^^^^^^^^^^^^^^^^^^^^^^^
  File "/opt/airflow/dags/coleta_dados_abertos_cnpj/jobs/extract.py", line 134, in extract
    upload_to_bucket(
  File "/opt/airflow/dags/coleta_dados_abertos_cnpj/jobs/extract.py", line 100, in upload_to_bucket
    client.put_object(
  File "/home/airflow/.local/lib/python3.12/site-packages/minio/api.py", line 1996, in put_object
    raise exc
  File "/home/airflow/.local/lib/python3.12/site-packages/minio/api.py", line 1942, in put_object
    return self._put_object(
           ^^^^^^^^^^^^^^^^^
  File "/home/airflow/.local/lib/python3.12/site-packages/minio/api.py", line 1781, in _put_object
    response = self._execute(
               ^^^^^^^^^^^^^^
  File "/home/airflow/.local/lib/python3.12/site-packages/minio/api.py", line 438, in _execute
    region = self._get_region(bucket_name)
             ^^^^^^^^^^^^^^^^^^^^^^^^^^^^^
  File "/home/airflow/.local/lib/python3.12/site-packages/minio/api.py", line 495, in _get_region
    response = self._url_open(
               ^^^^^^^^^^^^^^^
  File "/home/airflow/.local/lib/python3.12/site-packages/minio/api.py", line 424, in _url_open
    raise response_error
minio.error.S3Error: S3 operation failed; code: NoSuchBucket, message: The specified bucket does not exist, resource: /raw, request_id: 181DB622A4AF11B3, host_id: dd9025bab4ad464b049177c95eb6ebf374d3b3fd1af9251148b658df7ac2e3e8, bucket_name: raw
[2025-01-24T19:01:31.287+0000] {local_task_job_runner.py:266} INFO - Task exited with return code 1
[2025-01-24T19:01:31.298+0000] {taskinstance.py:3895} INFO - 0 downstream tasks scheduled from follow-on schedule check
[2025-01-24T19:01:31.396+0000] {local_task_job_runner.py:245} INFO - ::endgroup::
