[2025-01-24T05:27:47.545+0000] {local_task_job_runner.py:123} INFO - ::group::Pre task execution logs
[2025-01-24T05:27:47.651+0000] {taskinstance.py:2613} INFO - Dependencies all met for dep_context=non-requeueable deps ti=<TaskInstance: TESTANDO.test manual__2025-01-24T02:57:44.023751+00:00 [queued]>
[2025-01-24T05:27:47.655+0000] {taskinstance.py:2613} INFO - Dependencies all met for dep_context=requeueable deps ti=<TaskInstance: TESTANDO.test manual__2025-01-24T02:57:44.023751+00:00 [queued]>
[2025-01-24T05:27:47.655+0000] {taskinstance.py:2866} INFO - Starting attempt 13 of 14
[2025-01-24T05:27:47.663+0000] {taskinstance.py:2889} INFO - Executing <Task(PythonOperator): test> on 2025-01-24 02:57:44.023751+00:00
[2025-01-24T05:27:47.700+0000] {warnings.py:112} WARNING - /home/***/.local/lib/python3.12/site-packages/***/task/task_runner/standard_task_runner.py:70: DeprecationWarning: This process (pid=200) is multi-threaded, use of fork() may lead to deadlocks in the child.
  pid = os.fork()

[2025-01-24T05:27:47.700+0000] {standard_task_runner.py:72} INFO - Started process 202 to run task
[2025-01-24T05:27:47.701+0000] {standard_task_runner.py:104} INFO - Running: ['***', 'tasks', 'run', 'TESTANDO', 'test', 'manual__2025-01-24T02:57:44.023751+00:00', '--job-id', '283', '--raw', '--subdir', 'DAGS_FOLDER/testdag.py', '--cfg-path', '/tmp/tmpjdb5mlz0']
[2025-01-24T05:27:47.715+0000] {standard_task_runner.py:105} INFO - Job 283: Subtask test
[2025-01-24T05:27:47.805+0000] {task_command.py:467} INFO - Running <TaskInstance: TESTANDO.test manual__2025-01-24T02:57:44.023751+00:00 [running]> on host ee70781c29c7
[2025-01-24T05:27:47.849+0000] {taskinstance.py:3132} INFO - Exporting env vars: AIRFLOW_CTX_DAG_OWNER='Corvaum' AIRFLOW_CTX_DAG_ID='TESTANDO' AIRFLOW_CTX_TASK_ID='test' AIRFLOW_CTX_EXECUTION_DATE='2025-01-24T02:57:44.023751+00:00' AIRFLOW_CTX_TRY_NUMBER='13' AIRFLOW_CTX_DAG_RUN_ID='manual__2025-01-24T02:57:44.023751+00:00'
[2025-01-24T05:27:47.850+0000] {taskinstance.py:731} INFO - ::endgroup::
[2025-01-24T05:27:47.861+0000] {logging_mixin.py:190} INFO -              CNPJ Razão Social  Atividade
0  12345678000195    Empresa A   Comércio
1  98765432000100    Empresa B   Serviços
2  45678901000123    Empresa C  Indústria
[2025-01-24T05:27:47.912+0000] {logging_mixin.py:190} INFO - Bucket coleta-dados-abertos-cnpj já existe.
[2025-01-24T05:27:47.912+0000] {taskinstance.py:3311} ERROR - Task failed with exception
Traceback (most recent call last):
  File "/home/airflow/.local/lib/python3.12/site-packages/airflow/models/taskinstance.py", line 767, in _execute_task
    result = _execute_callable(context=context, **execute_callable_kwargs)
             ^^^^^^^^^^^^^^^^^^^^^^^^^^^^^^^^^^^^^^^^^^^^^^^^^^^^^^^^^^^^^
  File "/home/airflow/.local/lib/python3.12/site-packages/airflow/models/taskinstance.py", line 733, in _execute_callable
    return ExecutionCallableRunner(
           ^^^^^^^^^^^^^^^^^^^^^^^^
  File "/home/airflow/.local/lib/python3.12/site-packages/airflow/utils/operator_helpers.py", line 252, in run
    return self.func(*args, **kwargs)
           ^^^^^^^^^^^^^^^^^^^^^^^^^^
  File "/home/airflow/.local/lib/python3.12/site-packages/airflow/models/baseoperator.py", line 422, in wrapper
    return func(self, *args, **kwargs)
           ^^^^^^^^^^^^^^^^^^^^^^^^^^^
  File "/home/airflow/.local/lib/python3.12/site-packages/airflow/operators/python.py", line 238, in execute
    return_value = self.execute_callable()
                   ^^^^^^^^^^^^^^^^^^^^^^^
  File "/home/airflow/.local/lib/python3.12/site-packages/airflow/operators/python.py", line 256, in execute_callable
    return runner.run(*self.op_args, **self.op_kwargs)
           ^^^^^^^^^^^^^^^^^^^^^^^^^^^^^^^^^^^^^^^^^^^
  File "/home/airflow/.local/lib/python3.12/site-packages/airflow/utils/operator_helpers.py", line 252, in run
    return self.func(*args, **kwargs)
           ^^^^^^^^^^^^^^^^^^^^^^^^^^
  File "/opt/airflow/dags/testdag.py", line 48, in test
    client.fput_object(bucket_name, destination_file, source_file)
  File "/home/airflow/.local/lib/python3.12/site-packages/minio/api.py", line 1049, in fput_object
    file_size = os.stat(file_path).st_size
                ^^^^^^^^^^^^^^^^^^
FileNotFoundError: [Errno 2] No such file or directory: 'dadaos.csv'
[2025-01-24T05:27:47.920+0000] {taskinstance.py:1225} INFO - Marking task as UP_FOR_RETRY. dag_id=TESTANDO, task_id=test, run_id=manual__2025-01-24T02:57:44.023751+00:00, execution_date=20250124T025744, start_date=20250124T052747, end_date=20250124T052747
[2025-01-24T05:27:47.928+0000] {taskinstance.py:340} INFO - ::group::Post task execution logs
[2025-01-24T05:27:47.929+0000] {standard_task_runner.py:124} ERROR - Failed to execute job 283 for task test ([Errno 2] No such file or directory: 'dadaos.csv'; 202)
Traceback (most recent call last):
  File "/home/airflow/.local/lib/python3.12/site-packages/airflow/task/task_runner/standard_task_runner.py", line 117, in _start_by_fork
    ret = args.func(args, dag=self.dag)
          ^^^^^^^^^^^^^^^^^^^^^^^^^^^^^
  File "/home/airflow/.local/lib/python3.12/site-packages/airflow/cli/cli_config.py", line 49, in command
    return func(*args, **kwargs)
           ^^^^^^^^^^^^^^^^^^^^^
  File "/home/airflow/.local/lib/python3.12/site-packages/airflow/utils/cli.py", line 116, in wrapper
    return f(*args, **kwargs)
           ^^^^^^^^^^^^^^^^^^
  File "/home/airflow/.local/lib/python3.12/site-packages/airflow/cli/commands/task_command.py", line 483, in task_run
    task_return_code = _run_task_by_selected_method(args, _dag, ti)
                       ^^^^^^^^^^^^^^^^^^^^^^^^^^^^^^^^^^^^^^^^^^^^
  File "/home/airflow/.local/lib/python3.12/site-packages/airflow/cli/commands/task_command.py", line 256, in _run_task_by_selected_method
    return _run_raw_task(args, ti)
           ^^^^^^^^^^^^^^^^^^^^^^^
  File "/home/airflow/.local/lib/python3.12/site-packages/airflow/cli/commands/task_command.py", line 341, in _run_raw_task
    return ti._run_raw_task(
           ^^^^^^^^^^^^^^^^^
  File "/home/airflow/.local/lib/python3.12/site-packages/airflow/utils/session.py", line 97, in wrapper
    return func(*args, session=session, **kwargs)
           ^^^^^^^^^^^^^^^^^^^^^^^^^^^^^^^^^^^^^^
  File "/home/airflow/.local/lib/python3.12/site-packages/airflow/models/taskinstance.py", line 3005, in _run_raw_task
    return _run_raw_task(
           ^^^^^^^^^^^^^^
  File "/home/airflow/.local/lib/python3.12/site-packages/airflow/models/taskinstance.py", line 273, in _run_raw_task
    TaskInstance._execute_task_with_callbacks(
  File "/home/airflow/.local/lib/python3.12/site-packages/airflow/models/taskinstance.py", line 3159, in _execute_task_with_callbacks
    result = self._execute_task(context, task_orig)
             ^^^^^^^^^^^^^^^^^^^^^^^^^^^^^^^^^^^^^^
  File "/home/airflow/.local/lib/python3.12/site-packages/airflow/models/taskinstance.py", line 3183, in _execute_task
    return _execute_task(self, context, task_orig)
           ^^^^^^^^^^^^^^^^^^^^^^^^^^^^^^^^^^^^^^^
  File "/home/airflow/.local/lib/python3.12/site-packages/airflow/models/taskinstance.py", line 767, in _execute_task
    result = _execute_callable(context=context, **execute_callable_kwargs)
             ^^^^^^^^^^^^^^^^^^^^^^^^^^^^^^^^^^^^^^^^^^^^^^^^^^^^^^^^^^^^^
  File "/home/airflow/.local/lib/python3.12/site-packages/airflow/models/taskinstance.py", line 733, in _execute_callable
    return ExecutionCallableRunner(
           ^^^^^^^^^^^^^^^^^^^^^^^^
  File "/home/airflow/.local/lib/python3.12/site-packages/airflow/utils/operator_helpers.py", line 252, in run
    return self.func(*args, **kwargs)
           ^^^^^^^^^^^^^^^^^^^^^^^^^^
  File "/home/airflow/.local/lib/python3.12/site-packages/airflow/models/baseoperator.py", line 422, in wrapper
    return func(self, *args, **kwargs)
           ^^^^^^^^^^^^^^^^^^^^^^^^^^^
  File "/home/airflow/.local/lib/python3.12/site-packages/airflow/operators/python.py", line 238, in execute
    return_value = self.execute_callable()
                   ^^^^^^^^^^^^^^^^^^^^^^^
  File "/home/airflow/.local/lib/python3.12/site-packages/airflow/operators/python.py", line 256, in execute_callable
    return runner.run(*self.op_args, **self.op_kwargs)
           ^^^^^^^^^^^^^^^^^^^^^^^^^^^^^^^^^^^^^^^^^^^
  File "/home/airflow/.local/lib/python3.12/site-packages/airflow/utils/operator_helpers.py", line 252, in run
    return self.func(*args, **kwargs)
           ^^^^^^^^^^^^^^^^^^^^^^^^^^
  File "/opt/airflow/dags/testdag.py", line 48, in test
    client.fput_object(bucket_name, destination_file, source_file)
  File "/home/airflow/.local/lib/python3.12/site-packages/minio/api.py", line 1049, in fput_object
    file_size = os.stat(file_path).st_size
                ^^^^^^^^^^^^^^^^^^
FileNotFoundError: [Errno 2] No such file or directory: 'dadaos.csv'
[2025-01-24T05:27:47.954+0000] {local_task_job_runner.py:266} INFO - Task exited with return code 1
[2025-01-24T05:27:47.965+0000] {taskinstance.py:3895} INFO - 0 downstream tasks scheduled from follow-on schedule check
[2025-01-24T05:27:47.967+0000] {local_task_job_runner.py:245} INFO - ::endgroup::
